Workbook

Sheet README
A1: India data centres: data register
A2: Everything gathered across the 12-report research series and the atlas, with verification status, intended use and what to derive. Built 8 Oct 2026.
A4: What is in this file
A5: Register | B5: One row per dataset (128 datasets): contents and key values, source, verification status, how to use it, what to derive from it, where it is used in the atlas, and the next step to verify or improve it.
A6: Summary | B6: Counts of datasets by report and verification status (live formulas).
A7: Verified figures | B7: Every individual figure confirmed against its source document during the research, with the link. Where it confirms or corrects a figure from an earlier report, that is noted.
A8: Conflicts | B8: Places where two of our sources disagree, which value to use now, and how to resolve it.
A9: Data gaps | B9: What is still missing, why it matters, and who to ask.
A10: Sources | B10: Source documents, with links where the research captured them.
A12: Verification status
A13: Verified | B13: Confirmed against the primary or authoritative document during the research run (Report 12 recorded this figure by figure). Every value in the row is confirmed unless the note says otherwise.
A14: Verified (secondary source) | B14: Confirmed through a secondary summary of the primary document (for example a news report of a tariff order). Good enough for analysis; check the primary before investment decisions.
A15: Partly verified | B15: Some values in the row are verified (named in the note), the rest are reported, estimated or modelled.
A16: Reported, not verified | B16: Taken from a named published source as cited in Reports 1–11, but not checked against the original document. Most of Reports 1–11 is in this category because those reports recorded sources without a verification step.
A17: Estimate / proxy | B17: Analyst estimate, engineering range, proxy or series judgement (for example rubric scores, design temperatures, substation distances).
A18: Model output | B18: Calculated by our own formulas from the inputs above (for example worked examples, forecasts, rankings). Only as good as its inputs.
A19: Unpublished / gap | B19: No public data exists; the value has to be requested from the owner.
A21: Important
A22: What "Verified" means here | B22: Verification was done during the research runs (mainly Report 12, which checked figures against source documents and labelled each one). Nothing was re-checked when this register was compiled. Where Report 12 later verified a figure first used in an earlier report, the earlier row says so and is marked Partly verified.
A23: Reports 1–9 | B23: The original nine reports are not stored as files in this workspace; their data is catalogued from the atlas, which carries each figure with its source and an evidence tag (reported / estimate / model).
A24: Columns to filter | B24: Use the filter on the Register header. "Verified?" is a formula (Yes / Partly / No) driven by the status column; change a status and it updates.
A26: Counts (live)
A27: Verified | B27: =COUNTIF(Register!$K$5:$K$132,A27) -> 4
A28: Verified (secondary source) | B28: =COUNTIF(Register!$K$5:$K$132,A28) -> 0
A29: Partly verified | B29: =COUNTIF(Register!$K$5:$K$132,A29) -> 31
A30: Reported, not verified | B30: =COUNTIF(Register!$K$5:$K$132,A30) -> 44
A31: Estimate / proxy | B31: =COUNTIF(Register!$K$5:$K$132,A31) -> 18
A32: Model output | B32: =COUNTIF(Register!$K$5:$K$132,A32) -> 30
A33: Unpublished / gap | B33: =COUNTIF(Register!$K$5:$K$132,A33) -> 1
A34: Total datasets | B34: =COUNTA(Register!$A$5:$A$132) -> 128
A35: Individually verified figures | B35: =COUNTA('Verified figures'!$B$5:$B$62) -> 58

Sheet Summary
A1: Summary by report and status
A2: Live counts from the Register.
A4: Report | B4: Verified | C4: Verified (secondary source) | D4: Partly verified | E4: Reported, not verified | F4: Estimate / proxy | G4: Model output | H4: Unpublished / gap | I4: Total | J4: Verified or partly
A5: R1 Types | B5: =COUNTIFS(Register!$B$5:$B$132,$A5,Register!$K$5:$K$132,B$4) -> 0 | C5: =COUNTIFS(Register!$B$5:$B$132,$A5,Register!$K$5:$K$132,C$4) -> 0 | D5: =COUNTIFS(Register!$B$5:$B$132,$A5,Register!$K$5:$K$132,D$4) -> 1 | E5: =COUNTIFS(Register!$B$5:$B$132,$A5,Register!$K$5:$K$132,E$4) -> 6 | F5: =COUNTIFS(Register!$B$5:$B$132,$A5,Register!$K$5:$K$132,F$4) -> 0 | G5: =COUNTIFS(Register!$B$5:$B$132,$A5,Register!$K$5:$K$132,G$4) -> 0 | H5: =COUNTIFS(Register!$B$5:$B$132,$A5,Register!$K$5:$K$132,H$4) -> 0 | I5: =SUM(B5:H5) -> 7 | J5: =SUM(B5:D5) -> 1
A6: R2 AI vs conventional | B6: =COUNTIFS(Register!$B$5:$B$132,$A6,Register!$K$5:$K$132,B$4) -> 0 | C6: =COUNTIFS(Register!$B$5:$B$132,$A6,Register!$K$5:$K$132,C$4) -> 0 | D6: =COUNTIFS(Register!$B$5:$B$132,$A6,Register!$K$5:$K$132,D$4) -> 4 | E6: =COUNTIFS(Register!$B$5:$B$132,$A6,Register!$K$5:$K$132,E$4) -> 4 | F6: =COUNTIFS(Register!$B$5:$B$132,$A6,Register!$K$5:$K$132,F$4) -> 1 | G6: =COUNTIFS(Register!$B$5:$B$132,$A6,Register!$K$5:$K$132,G$4) -> 0 | H6: =COUNTIFS(Register!$B$5:$B$132,$A6,Register!$K$5:$K$132,H$4) -> 0 | I6: =SUM(B6:H6) -> 9 | J6: =SUM(B6:D6) -> 4
A7: R3 Cooling | B7: =COUNTIFS(Register!$B$5:$B$132,$A7,Register!$K$5:$K$132,B$4) -> 0 | C7: =COUNTIFS(Register!$B$5:$B$132,$A7,Register!$K$5:$K$132,C$4) -> 0 | D7: =COUNTIFS(Register!$B$5:$B$132,$A7,Register!$K$5:$K$132,D$4) -> 1 | E7: =COUNTIFS(Register!$B$5:$B$132,$A7,Register!$K$5:$K$132,E$4) -> 5 | F7: =COUNTIFS(Register!$B$5:$B$132,$A7,Register!$K$5:$K$132,F$4) -> 3 | G7: =COUNTIFS(Register!$B$5:$B$132,$A7,Register!$K$5:$K$132,G$4) -> 0 | H7: =COUNTIFS(Register!$B$5:$B$132,$A7,Register!$K$5:$K$132,H$4) -> 0 | I7: =SUM(B7:H7) -> 9 | J7: =SUM(B7:D7) -> 1
A8: R4 Bengaluru | B8: =COUNTIFS(Register!$B$5:$B$132,$A8,Register!$K$5:$K$132,B$4) -> 0 | C8: =COUNTIFS(Register!$B$5:$B$132,$A8,Register!$K$5:$K$132,C$4) -> 0 | D8: =COUNTIFS(Register!$B$5:$B$132,$A8,Register!$K$5:$K$132,D$4) -> 0 | E8: =COUNTIFS(Register!$B$5:$B$132,$A8,Register!$K$5:$K$132,E$4) -> 7 | F8: =COUNTIFS(Register!$B$5:$B$132,$A8,Register!$K$5:$K$132,F$4) -> 0 | G8: =COUNTIFS(Register!$B$5:$B$132,$A8,Register!$K$5:$K$132,G$4) -> 1 | H8: =COUNTIFS(Register!$B$5:$B$132,$A8,Register!$K$5:$K$132,H$4) -> 0 | I8: =SUM(B8:H8) -> 8 | J8: =SUM(B8:D8) -> 0
A9: R5 Carbon | B9: =COUNTIFS(Register!$B$5:$B$132,$A9,Register!$K$5:$K$132,B$4) -> 0 | C9: =COUNTIFS(Register!$B$5:$B$132,$A9,Register!$K$5:$K$132,C$4) -> 0 | D9: =COUNTIFS(Register!$B$5:$B$132,$A9,Register!$K$5:$K$132,D$4) -> 3 | E9: =COUNTIFS(Register!$B$5:$B$132,$A9,Register!$K$5:$K$132,E$4) -> 4 | F9: =COUNTIFS(Register!$B$5:$B$132,$A9,Register!$K$5:$K$132,F$4) -> 1 | G9: =COUNTIFS(Register!$B$5:$B$132,$A9,Register!$K$5:$K$132,G$4) -> 3 | H9: =COUNTIFS(Register!$B$5:$B$132,$A9,Register!$K$5:$K$132,H$4) -> 0 | I9: =SUM(B9:H9) -> 11 | J9: =SUM(B9:D9) -> 3
A10: R6 Water impact | B10: =COUNTIFS(Register!$B$5:$B$132,$A10,Register!$K$5:$K$132,B$4) -> 0 | C10: =COUNTIFS(Register!$B$5:$B$132,$A10,Register!$K$5:$K$132,C$4) -> 0 | D10: =COUNTIFS(Register!$B$5:$B$132,$A10,Register!$K$5:$K$132,D$4) -> 2 | E10: =COUNTIFS(Register!$B$5:$B$132,$A10,Register!$K$5:$K$132,E$4) -> 1 | F10: =COUNTIFS(Register!$B$5:$B$132,$A10,Register!$K$5:$K$132,F$4) -> 0 | G10: =COUNTIFS(Register!$B$5:$B$132,$A10,Register!$K$5:$K$132,G$4) -> 5 | H10: =COUNTIFS(Register!$B$5:$B$132,$A10,Register!$K$5:$K$132,H$4) -> 0 | I10: =SUM(B10:H10) -> 8 | J10: =SUM(B10:D10) -> 2
A11: R7 Unit economics | B11: =COUNTIFS(Register!$B$5:$B$132,$A11,Register!$K$5:$K$132,B$4) -> 0 | C11: =COUNTIFS(Register!$B$5:$B$132,$A11,Register!$K$5:$K$132,C$4) -> 0 | D11: =COUNTIFS(Register!$B$5:$B$132,$A11,Register!$K$5:$K$132,D$4) -> 2 | E11: =COUNTIFS(Register!$B$5:$B$132,$A11,Register!$K$5:$K$132,E$4) -> 4 | F11: =COUNTIFS(Register!$B$5:$B$132,$A11,Register!$K$5:$K$132,F$4) -> 0 | G11: =COUNTIFS(Register!$B$5:$B$132,$A11,Register!$K$5:$K$132,G$4) -> 5 | H11: =COUNTIFS(Register!$B$5:$B$132,$A11,Register!$K$5:$K$132,H$4) -> 0 | I11: =SUM(B11:H11) -> 11 | J11: =SUM(B11:D11) -> 2
A12: R8 Green | B12: =COUNTIFS(Register!$B$5:$B$132,$A12,Register!$K$5:$K$132,B$4) -> 0 | C12: =COUNTIFS(Register!$B$5:$B$132,$A12,Register!$K$5:$K$132,C$4) -> 0 | D12: =COUNTIFS(Register!$B$5:$B$132,$A12,Register!$K$5:$K$132,D$4) -> 2 | E12: =COUNTIFS(Register!$B$5:$B$132,$A12,Register!$K$5:$K$132,E$4) -> 1 | F12: =COUNTIFS(Register!$B$5:$B$132,$A12,Register!$K$5:$K$132,F$4) -> 1 | G12: =COUNTIFS(Register!$B$5:$B$132,$A12,Register!$K$5:$K$132,G$4) -> 3 | H12: =COUNTIFS(Register!$B$5:$B$132,$A12,Register!$K$5:$K$132,H$4) -> 0 | I12: =SUM(B12:H12) -> 7 | J12: =SUM(B12:D12) -> 2
A13: R9 State policies | B13: =COUNTIFS(Register!$B$5:$B$132,$A13,Register!$K$5:$K$132,B$4) -> 0 | C13: =COUNTIFS(Register!$B$5:$B$132,$A13,Register!$K$5:$K$132,C$4) -> 0 | D13: =COUNTIFS(Register!$B$5:$B$132,$A13,Register!$K$5:$K$132,D$4) -> 1 | E13: =COUNTIFS(Register!$B$5:$B$132,$A13,Register!$K$5:$K$132,E$4) -> 4 | F13: =COUNTIFS(Register!$B$5:$B$132,$A13,Register!$K$5:$K$132,F$4) -> 1 | G13: =COUNTIFS(Register!$B$5:$B$132,$A13,Register!$K$5:$K$132,G$4) -> 0 | H13: =COUNTIFS(Register!$B$5:$B$132,$A13,Register!$K$5:$K$132,H$4) -> 0 | I13: =SUM(B13:H13) -> 6 | J13: =SUM(B13:D13) -> 1
A14: Simulator (R1–R9 synthesis) | B14: =COUNTIFS(Register!$B$5:$B$132,$A14,Register!$K$5:$K$132,B$4) -> 0 | C14: =COUNTIFS(Register!$B$5:$B$132,$A14,Register!$K$5:$K$132,C$4) -> 0 | D14: =COUNTIFS(Register!$B$5:$B$132,$A14,Register!$K$5:$K$132,D$4) -> 1 | E14: =COUNTIFS(Register!$B$5:$B$132,$A14,Register!$K$5:$K$132,E$4) -> 0 | F14: =COUNTIFS(Register!$B$5:$B$132,$A14,Register!$K$5:$K$132,F$4) -> 0 | G14: =COUNTIFS(Register!$B$5:$B$132,$A14,Register!$K$5:$K$132,G$4) -> 1 | H14: =COUNTIFS(Register!$B$5:$B$132,$A14,Register!$K$5:$K$132,H$4) -> 0 | I14: =SUM(B14:H14) -> 2 | J14: =SUM(B14:D14) -> 1
A15: R10 Where to build | B15: =COUNTIFS(Register!$B$5:$B$132,$A15,Register!$K$5:$K$132,B$4) -> 0 | C15: =COUNTIFS(Register!$B$5:$B$132,$A15,Register!$K$5:$K$132,C$4) -> 0 | D15: =COUNTIFS(Register!$B$5:$B$132,$A15,Register!$K$5:$K$132,D$4) -> 4 | E15: =COUNTIFS(Register!$B$5:$B$132,$A15,Register!$K$5:$K$132,E$4) -> 4 | F15: =COUNTIFS(Register!$B$5:$B$132,$A15,Register!$K$5:$K$132,F$4) -> 1 | G15: =COUNTIFS(Register!$B$5:$B$132,$A15,Register!$K$5:$K$132,G$4) -> 2 | H15: =COUNTIFS(Register!$B$5:$B$132,$A15,Register!$K$5:$K$132,H$4) -> 1 | I15: =SUM(B15:H15) -> 12 | J15: =SUM(B15:D15) -> 4
A16: R11 Forecast | B16: =COUNTIFS(Register!$B$5:$B$132,$A16,Register!$K$5:$K$132,B$4) -> 0 | C16: =COUNTIFS(Register!$B$5:$B$132,$A16,Register!$K$5:$K$132,C$4) -> 0 | D16: =COUNTIFS(Register!$B$5:$B$132,$A16,Register!$K$5:$K$132,D$4) -> 4 | E16: =COUNTIFS(Register!$B$5:$B$132,$A16,Register!$K$5:$K$132,E$4) -> 4 | F16: =COUNTIFS(Register!$B$5:$B$132,$A16,Register!$K$5:$K$132,F$4) -> 5 | G16: =COUNTIFS(Register!$B$5:$B$132,$A16,Register!$K$5:$K$132,G$4) -> 5 | H16: =COUNTIFS(Register!$B$5:$B$132,$A16,Register!$K$5:$K$132,H$4) -> 0 | I16: =SUM(B16:H16) -> 18 | J16: =SUM(B16:D16) -> 4
A17: R12 Water & energy | B17: =COUNTIFS(Register!$B$5:$B$132,$A17,Register!$K$5:$K$132,B$4) -> 4 | C17: =COUNTIFS(Register!$B$5:$B$132,$A17,Register!$K$5:$K$132,C$4) -> 0 | D17: =COUNTIFS(Register!$B$5:$B$132,$A17,Register!$K$5:$K$132,D$4) -> 6 | E17: =COUNTIFS(Register!$B$5:$B$132,$A17,Register!$K$5:$K$132,E$4) -> 0 | F17: =COUNTIFS(Register!$B$5:$B$132,$A17,Register!$K$5:$K$132,F$4) -> 5 | G17: =COUNTIFS(Register!$B$5:$B$132,$A17,Register!$K$5:$K$132,G$4) -> 5 | H17: =COUNTIFS(Register!$B$5:$B$132,$A17,Register!$K$5:$K$132,H$4) -> 0 | I17: =SUM(B17:H17) -> 20 | J17: =SUM(B17:D17) -> 10
A18: Total | B18: =SUM(B5:B17) -> 4 | C18: =SUM(C5:C17) -> 0 | D18: =SUM(D5:D17) -> 31 | E18: =SUM(E5:E17) -> 44 | F18: =SUM(F5:F17) -> 18 | G18: =SUM(G5:G17) -> 30 | H18: =SUM(H5:H17) -> 1 | I18: =SUM(I5:I17) -> 128 | J18: =SUM(J5:J17) -> 35
A20: Reading it
A21: Report 12 is the only report that verified figures one by one. Earlier reports cited named sources without a verification step, so their rows are "Reported" unless Report 12 later confirmed the same figure. Model outputs and estimates are expected: they are our calculations and judgements, labelled as such.

Sheet Register
A1: Dataset register
A2: One row per dataset. Status colours follow the README legend. Filter on any column.
A4: ID | B4: Report | C4: Theme | D4: Dataset | E4: What it contains (key values) | F4: Unit | G4: Geography | H4: As of | I4: Source(s) | J4: Link | K4: Verification status | L4: Verified? | M4: Verification note | N4: How to use it | O4: What to derive from it | P4: Used in (atlas) | Q4: Next step to verify or improve
A5: R1-01 | B5: R1 Types | C5: Market size | D5: Global data-centre capacity | E5: ~103 GW (2025) → ~200 GW (2030), ~14% CAGR | F5: GW (IT) | G5: Global | H5: Jan 2026 | I5: JLL global outlook, Jan 2026 | K5: Reported, not verified | L5: =IF(K5="Partly verified","Partly",IF(LEFT(K5,8)="Verified","Yes","No")) -> No | M5: Cited by name in Report 1; not checked against the JLL document. | N5: Global benchmark for India's scale and growth rate. | O5: India's share of global capacity (1.79 GW ÷ ~103 GW ≈ 1.7%); compare India's ~25% growth with the global 14%. | P5: Ch 1 headline; Key numbers | Q5: Check against JLL report text.
A6: R1-02 | B6: R1 Types | C6: Market structure | D6: Ownership mix of global capacity | E6: Hyperscale 41% (2024), 44% (2025), 48% (2026), ~67% (2031 proj.); colocation 22/22/20/14%; enterprise on-prem 37/34/32/19%; enterprise 56% in 2018. 20 metros hold 60% of hyperscale; N. Virginia 11%. | F6: % of capacity | G6: Global | H6: Apr 2026 | I6: Synergy Research Group | K6: Reported, not verified | L6: =IF(K6="Partly verified","Partly",IF(LEFT(K6,8)="Verified","Yes","No")) -> No | M6: 2031 is a Synergy projection. | N6: Shows where demand is moving (hyperscale and wholesale colo, away from enterprise rooms). | O6: Expected Indian demand mix by business model; justify wholesale/hyperscale campuses as the build priority. | P6: Ch 1 "Who owns the world's capacity" chart | Q6: Confirm against Synergy release.
A7: R1-03 | B7: R1 Types | C7: Business models | D7: Six data-centre business models | E7: Enterprise <1–20 MW; retail colo 1 rack–1 MW; wholesale/BTS 10–100+ MW; hyperscale 30 MW–1 GW+; AI factory 50 MW–5 GW; edge 50 kW–5 MW. Self-build ~13–27% cheaper than leasing in India; >20 MW sites PUE ~1.44. | F7: MW bands | G7: Global / India | H7: 2026 | I7: Report 1 synthesis (industry sources); PUE 1.44 for >20 MW from Uptime 2025 | K7: Partly verified | L7: =IF(K7="Partly verified","Partly",IF(LEFT(K7,8)="Verified","Yes","No")) -> Partly | M7: PUE 1.44 for >20 MW sites verified in Report 12 (Uptime 2025); size bands and self-build saving are series estimates. | N7: Classify any project; feeds the Type finder. | O7: Which model fits a given size/workload; expected PUE and cost band per type. | P7: Ch 1 Type explorer and Type finder | Q7: Source the 13–27% self-build saving.
A8: R1-04 | B8: R1 Types | C8: Reliability | D8: Uptime Tier availability targets | E8: Tier I 99.671%, Tier II 99.741%, Tier III 99.982% (1.6 h/yr), Tier IV 99.995%; ANSI/TIA-942 Rated 1–4. | F8: % availability | G8: Global standard | H8: Current | I8: Uptime Institute Tier Standard | K8: Reported, not verified | L8: =IF(K8="Partly verified","Partly",IF(LEFT(K8,8)="Verified","Yes","No")) -> No | M8: Standard design targets; not re-checked. | N8: Set reliability level per workload. | O8: Allowed downtime = (1 − availability) × 8,760 h; Tier III is the Indian commercial norm. | P8: Ch 1 Tier clock | Q8: —
A9: R1-05 | B9: R1 Types | C9: India market | D9: India operational and pipeline capacity by city | E9: Operational / upcoming MW: Mumbai 890/1,726; Chennai 214/368; Delhi NCR 183/387; Bengaluru 162/100; Hyderabad 151/710; Pune 133/258; Kolkata 22/84. Total 1,789 MW operational; pipeline 3,860 MW (509 under construction, 3,351 planned); 147 facilities, 33 providers; vacancy 14.9%. | F9: MW (IT) | G9: India, 7 markets | H9: H1 2026 (press release 16 Sep 2026) | I9: Cushman & Wakefield India Data Centre H1 2026 Update | K9: Reported, not verified | L9: =IF(K9="Partly verified","Partly",IF(LEFT(K9,8)="Verified","Yes","No")) -> No | M9: Press release figures cited in Reports 1, 10 and 11; city sum (3,633 MW) is 227 MW short of the 3,860 MW total, unexplained. | N9: Anchor for every capacity number in the atlas: market share, pipeline and the forecast starting point. | O9: City shares (Mumbai 49.7%); pipeline-to-stock ratios (Hyderabad 4.7×); forecast base C₀ = 1,789 − 178 = 1,611 MW for end-2025. | P9: Ch 1 city chart; Ch 9 map; Ch 10 demand scores; Ch 11 forecast | Q9: Obtain the full C&W report; reconcile the 227 MW gap.
A10: R1-06 | B10: R1 Types | C10: Connectivity | D10: Subsea cable landings and bandwidth concentration | E10: 17–18 international cables at 14–15 landing stations in 5 cities (Mumbai, Chennai, Kochi, Thoothukudi, Thiruvananthapuram); 15 of 17 land within ~6 km of Versova; ~95% of international bandwidth via Mumbai; Chennai 8 cables (JLL); new: SEA-ME-WE 6 Chennai, Google Vizag gateway (3 paths), Meta Waterworth, Jio Digha (unconfirmed). | F10: Count / % | G10: India | H10: 2026 | I10: Report 1 and Report 10 (TeleGeography-style sources, JLL, Google, Meta announcements) | K10: Reported, not verified | L10: =IF(K10="Partly verified","Partly",IF(LEFT(K10,8)="Verified","Yes","No")) -> No | M10: The 95% bandwidth share is a series figure without a primary citation. | N10: Connectivity factor in site ranking; concentration-risk argument. | O10: Connectivity scores per city; case for east-coast landings; latency to cable heads. | P10: Ch 1; Ch 10 connectivity scores | Q10: Confirm counts on TeleGeography Submarine Cable Map.
A11: R1-07 | B11: R1 Types | C11: Investment | D11: Announced hyperscale and AI investments in India | E11: Google ≈US$15 bn (1 GW AI hub, Vizag); Microsoft US$17.5 bn; Amazon US$35 bn+ by 2030; Reliance up to 3 GW Jamnagar; Adani ≈US$100 bn by 2035; TCS HyperVault 1 GW+. | F11: US$ bn / GW | G11: India | H11: 2025–26 | I11: Company announcements (Report 1) | K11: Reported, not verified | L11: =IF(K11="Partly verified","Partly",IF(LEFT(K11,8)="Verified","Yes","No")) -> No | M11: Announcements, not built capacity. | N11: Upside scenarios and pipeline outside C&W's 7 markets. | O11: Apply 0.2–0.5 conversion to announced capacity (Report 11) to get expected MW. | P11: Ch 1 callout; Ch 11 extra-campus slider | Q11: Track commissioning, not announcements.
A12: R2-01 | B12: R2 AI vs conventional | C12: Energy | D12: Global data-centre electricity | E12: 415 TWh (2024) → 945 TWh (2030) base; >1,260 TWh high case; ~1,200 TWh (2035). IEA 2026 update: 485 → 950 TWh. US and China ~80% of growth. | F12: TWh/yr | G12: Global | H12: Apr 2025 / 2026 update | I12: IEA, Energy and AI (Apr 2025) and 2026 update | K12: Reported, not verified | L12: =IF(K12="Partly verified","Partly",IF(LEFT(K12,8)="Verified","Yes","No")) -> No | M12: Two IEA vintages differ for 2024 (415 vs 485 TWh). | N12: Global context for India's electricity path. | O12: India's share of global DC electricity (base 2030: 35 TWh ÷ 945 ≈ 3.7%). | P12: Ch 2 chart; Ch 11 context; Key numbers | Q12: Use the 2026 update consistently.
A13: R2-02 | B13: R2 AI vs conventional | C13: Energy | D13: AI share of server electricity | E13: AI servers 24% of server electricity (2024); AI growing ~30%/yr vs ~9% for conventional servers. | F13: % / %/yr | G13: Global | H13: 2025 | I13: IEA, Energy and AI | K13: Reported, not verified | L13: =IF(K13="Partly verified","Partly",IF(LEFT(K13,8)="Verified","Yes","No")) -> No | N13: Explains why AI dominates new demand. | O13: AI share of new Indian capacity assumptions (40% → 70% of new builds in Report 11). | P13: Ch 2 headline | Q13: —
A14: R2-03 | B14: R2 AI vs conventional | C14: Energy per workload | D14: Energy per query and per training run | E14: Gemini median text prompt 0.24 Wh and 0.26 mL water (May 2025); ChatGPT avg ~0.34 Wh (Jun 2025); Google search ~0.3 Wh (2009); GPT-4o 500 tokens ~0.3 Wh; 10k/100k-token inputs 2.5/40 Wh; Llama 3.1 405B ≤21.6 GWh (30.84 M H100-hours); GPT-4 training ~50–62 GWh (unofficial). | F14: Wh / GWh | G14: Global | H14: 2009–2025 | I14: Google (arXiv 2508.15734), OpenAI (Altman), Epoch AI, Meta | J14: Open source | K14: Partly verified | L14: =IF(K14="Partly verified","Partly",IF(LEFT(K14,8)="Verified","Yes","No")) -> Partly | M14: Gemini figures verified (Report 12, GOOG25); ChatGPT 0.34 Wh verified via secondary source; others reported or unofficial estimates. | N14: Per-query footprint comparisons and explainer. | O14: Water per prompt in India = Wh × (site WUE + grid water); daily load of a service (1 bn messages ≈ 12.5 MW). | P14: Ch 2 table; Ch 6 and Ch 12 prompt charts | Q14: —
A15: R2-04 | B15: R2 AI vs conventional | C15: Hardware | D15: Rack density and GPU system power | E15: Enterprise modal ~7–9 kW; air practical ~20 kW; active RDHx ~60 kW; GB200/GB300 NVL72 120–142 kW (HPE 132 kW nominal); Vera Rubin ~190–230 kW (industry estimate); Kyber ~600 kW (2027). DGX H100 10.2 kW; DGX B200 14.3 kW max. | F15: kW per rack / system | G15: Global | H15: 2025–27 | I15: Nvidia specifications and GTC roadmap; LBNL 2024; NVIDIA DGX B200 guide | J15: Open source | K15: Partly verified | L15: =IF(K15="Partly verified","Partly",IF(LEFT(K15,8)="Verified","Yes","No")) -> Partly | M15: DGX B200 14.3 kW and DGX H100 10.2 kW verified (Report 12); NVL72 ~120 kW verified via secondary source; Rubin figures are estimates. | N15: Design density for cooling and power chain. | O15: Racks per MW (1,000 ÷ kW); GPUs per MW; per-GPU energy (NVL72: 18.2 MWh/yr at PUE 1.25). | P15: Ch 2 rack inspector; Ch 12 energy | Q15: Confirm Rubin specs when published.
A16: R2-05 | B16: R2 AI vs conventional | C16: Energy split | D16: Facility electricity split by class | E16: IT / cooling / power losses / other (%): legacy PUE~1.9 52/35/10/3; enterprise-colo ~1.55 64/27/7/2; hyperscale ~1.15 88/7.5/3.5/1; AI liquid ~1.2 84/11/4.5/0.5. | F16: % of facility energy | G16: Generic | H16: 2025 | I16: Series synthesis from PUE ranges and IEA component shares | K16: Estimate / proxy | L16: =IF(K16="Partly verified","Partly",IF(LEFT(K16,8)="Verified","Yes","No")) -> No | M16: Indicative. | N16: Explain where non-IT energy goes. | O16: Cooling energy per MW; savings from cooling upgrades. | P16: Ch 2 chart; simulator overhead split | Q16: —
A17: R2-06 | B17: R2 AI vs conventional | C17: Power chain | D17: Power-chain conversion losses | E17: Transformer 1–2%; UPS 2–8%; PDU/busway 1–3%; server PSU 4–10%. UPS efficiency: edge 77–85%, colo 80–94%, hyperscale/AI 90–99%. 800 VDC (Kyber, 2027) removes stages. | F17: % loss | G17: Generic | H17: 2024–26 | I17: Industry ranges; LBNL 2024 for UPS efficiency | J17: Open source | K17: Partly verified | L17: =IF(K17="Partly verified","Partly",IF(LEFT(K17,8)="Verified","Yes","No")) -> Partly | M17: UPS efficiency ranges verified (Report 12, LBNL); stage losses are typical ranges. | N17: PUE build-up and electrical design. | O17: Loss share of PUE; benefit of high-efficiency UPS / DC distribution. | P17: Ch 2 power chain; simulator losses | Q17: —
A18: R2-07 | B18: R2 AI vs conventional | C18: Grid reliability | D18: AI load swings and grid events | E18: NERC: 10 Jul 2024, ~1,500 MW of DC load disconnected (60 load points, 25 substations); ~1,800 MW load loss Feb 2025; ~1,260 MW did not return for hours; one site 450 → 40 MW in 36 s; NERC Level 3 alert 4 May 2026. | F18: MW | G18: USA (Virginia) | H18: 2024–26 | I18: NERC/FERC large-loads presentation; POWER; Keentel; NERC alert | J18: Open source | K18: Partly verified | L18: =IF(K18="Partly verified","Partly",IF(LEFT(K18,8)="Verified","Yes","No")) -> Partly | M18: 1,500 MW and 1,800 MW events verified (Report 12); 1,260 MW and 450→40 MW via secondary sources; Level 3 alert reported. | N18: Argue for ride-through and ramp-rate clauses in Indian connection agreements. | O18: Required BESS/UPS ride-through for >100 MW AI loads. | P18: Ch 2 load profiles; Ch 12 Example C | Q18: —
A19: R2-08 | B19: R2 AI vs conventional | C19: India AI compute | D19: IndiaAI Mission and Indian AI build-out | E19: IndiaAI Mission ₹10,372 cr; 38,231 GPUs onboarded across 14 providers (Mar 2026), avg ≈₹65/GPU-hr subsidised; ~20,000 more announced. Yotta NM1 52 MW, 8,192 H100; Reliance Jamnagar up to 3 GW, 120 MW+ H2 2026, Meta lease ~168 MW; Sify DGX-Ready 130 kW/rack, then 200 kW/rack. | F19: ₹ cr / GPUs / MW | G19: India | H19: Mar 2026 | I19: PIB (Mar 2026); company announcements | K19: Reported, not verified | L19: =IF(K19="Partly verified","Partly",IF(LEFT(K19,8)="Verified","Yes","No")) -> No | N19: Size of public AI compute; anchor-tenant evidence. | O19: IndiaAI GPUs ≈ 40–55 MW of IT (≈3% of national capacity) at 1.0–1.4 kW/GPU. | P19: Ch 2 India build-out; Ch 7 GPU prices; Ch 11 | Q19: Track PIB updates.
A20: R2-09 | B20: R2 AI vs conventional | C20: Design comparison | D20: Conventional vs AI data-centre attributes | E20: Density 5–15 vs 120–142 → 600 kW; capex JLL shell ≈US$11.3 m/MW + up to US$25 m/MW AI fit-out; India ₹50–55 vs up to ₹75 cr/MW; training sites 300 MW–5 GW, inference 10–200 MW; GPU economic life 3–6 years (contested). | F20: mixed | G20: Global / India | H20: 2025–26 | I20: JLL, SBI (Apr 2026), Report 2 synthesis | K20: Reported, not verified | L20: =IF(K20="Partly verified","Partly",IF(LEFT(K20,8)="Verified","Yes","No")) -> No | M20: GPU life and some ranges contested. | N20: Planning differences between AI and cloud campuses. | O20: Siting rule: train near power, serve inference near users. | P20: Ch 2 tables | Q20: —
A21: R3-01 | B21: R3 Cooling | C21: Physics | D21: Heat-carrying capacity of coolants | E21: kJ/m³·K: air 1.2; dielectric oil 1,750; two-phase (sensible) 1,850; PG25 4,000; water 4,180. 100 kW at 10 K rise needs ~8 m³/s air vs 2.4 L/s water. | F21: kJ/m³·K | G21: Physics | H21: — | I21: Standard physical properties | K21: Reported, not verified | L21: =IF(K21="Partly verified","Partly",IF(LEFT(K21,8)="Verified","Yes","No")) -> No | M21: Textbook values. | N21: Explain why liquid cooling wins at high density. | O21: Flow rates for a given heat load (Q = ρ·cp·V·ΔT). | P21: Ch 3 chart | Q21: —
A22: R3-02 | B22: R3 Cooling | C22: Design limits | D22: Practical rack-density limits by cooling method | E22: Perimeter air 15 kW; air + containment 30; active RDHx 70; direct-to-chip and immersion ~250 kW per rack; air stops being practical at 20–40 kW. | F22: kW per rack | G22: Generic | H22: 2026 | I22: Report 3 synthesis (vendor and ASHRAE guidance) | K22: Estimate / proxy | L22: =IF(K22="Partly verified","Partly",IF(LEFT(K22,8)="Verified","Yes","No")) -> No | N22: Choose in-room cooling for a target density. | O22: Which halls are stranded by a density jump; retrofit needs. | P22: Ch 3 cooling selector | Q22: —
A23: R3-03 | B23: R3 Cooling | C23: Heat rejection | D23: Heat-rejection options: water and energy | E23: WUE L/kWh: open tower + water-cooled chiller 1.4–2.5; adiabatic 0.1–0.5; hybrid/thermosyphon 0.5–0.7; dry + air-cooled chiller ~0 (+5–15% energy); DLC at W40–W45 + dry 0–0.1; seawater ~0 freshwater. | F23: L/kWh IT | G23: Generic, India fit | H23: 2026 | I23: Report 3 synthesis; consistent with Report 12 table and LBNL ranking | K23: Estimate / proxy | L23: =IF(K23="Partly verified","Partly",IF(LEFT(K23,8)="Verified","Yes","No")) -> No | M23: Ranges consistent with Report 12 (proxy) and NTT evaporative 1.42–2.93 (verified). | N23: Pick heat rejection by water stress and climate. | O23: Site WUE for calculators; water cut from switching designs. | P23: Ch 3 table; simulator WUE functions | Q23: Replace with metered operator data when disclosed.
A24: R3-04 | B24: R3 Cooling | C24: Liquid cooling | D24: Liquid-cooling technologies compared | E24: 1-phase DLC 50–250 kW+, 70–98% heat to liquid, PUE 1.05–1.20; 2-phase DLC 100–300 kW, PUE 1.04–1.15; 1-phase immersion 100–250 kW/tank, PUE 1.03–1.08; 2-phase immersion 200 kW+, PUE 1.01–1.05 (PFAS risk; 3M exited end-2025). | F24: kW / PUE | G24: Global | H24: 2026 | I24: Vendor and industry reports (Report 3) | K24: Reported, not verified | L24: =IF(K24="Partly verified","Partly",IF(LEFT(K24,8)="Verified","Yes","No")) -> No | M24: Reported PUEs are vendor claims. | N24: Technology choice for AI halls. | O24: PUE and WUE inputs for liquid-cooled cases. | P24: Ch 3 table | Q24: —
A25: R3-05 | B25: R3 Cooling | C25: Market | D25: Liquid-cooling market size | E25: Manufacturer revenue US$1.5 bn (2024) → ~3 bn (2025) → ~7 bn (2029); DLC US$1.1 bn (2024) → 5.8 bn (2029), +156% YoY Q2 2025; India US$113 m (2026) → 790 m (2031). 26–50% of projects use liquid for AI (Turner & Townsend). | F25: US$ | G25: Global / India | H25: Jan 2026 | I25: Dell'Oro Group; MarketsandMarkets; Turner & Townsend | K25: Reported, not verified | L25: =IF(K25="Partly verified","Partly",IF(LEFT(K25,8)="Verified","Yes","No")) -> No | N25: Evidence for fast adoption of liquid cooling. | O25: Bass diffusion parameters (q ≫ p) for the liquid/dry share in Report 11. | P25: Ch 3 chart; Ch 11 water model | Q25: —
A26: R3-06 | B26: R3 Cooling | C26: Market | D26: Cooling-sector M&A 2024–26 | E26: Eaton–Boyd Thermal US$9.5 bn; Ecolab–CoolIT US$4.75 bn; Vertiv–PurgeRite ~US$1 bn; Schneider–Motivair US$0.85 bn; Trane–LiquidStack (undisclosed). ~US$16 bn total. | F26: US$ bn | G26: Global | H26: 2024–26 | I26: Company announcements | K26: Reported, not verified | L26: =IF(K26="Partly verified","Partly",IF(LEFT(K26,8)="Verified","Yes","No")) -> No | N26: Supply-chain and lock-in risk argument. | O26: Procurement advice: insist on open interfaces (OCP UQD, CDU controls). | P26: Ch 3 | Q26: —
A27: R3-07 | B27: R3 Cooling | C27: Regulation | D27: India HFC phase-down under Kigali Amendment | E27: Baseline 2024–26; freeze 1 Jan 2028; −10% 2032; −20% 2037; −30% 2042; −85% 2047. | F27: Dates / % cut | G27: India | H27: 2016 amendment | I27: Kigali Amendment to the Montreal Protocol (India: Group 2) | K27: Reported, not verified | L27: =IF(K27="Partly verified","Partly",IF(LEFT(K27,8)="Verified","Yes","No")) -> No | N27: Refrigerant choice for chillers bought now. | O27: Specify low-GWP refrigerants (R-1234ze, R-513A, R-32) or chiller-free designs. | P27: Ch 3; Key numbers | Q27: —
A28: R3-08 | B28: R3 Cooling | C28: Climate | D28: City design temperatures (cooling chapter and simulator) | E28: Design dry-bulb / wet-bulb °C: Bengaluru 35/23; Hyderabad 41/26; Pune 39/25; Mumbai 35/28; Chennai 38/29; Visakhapatnam 36/28; Delhi NCR 45/29. | F28: °C | G28: 7 Indian cities | H28: 2026 | I28: Indicative 0.4% summer conditions (series estimate) | K28: Estimate / proxy | L28: =IF(K28="Partly verified","Partly",IF(LEFT(K28,8)="Verified","Yes","No")) -> No | M28: Not station data. Report 10 has a separate DB/WB list for 50 cities (also estimates). | N28: Decide which heat-rejection option can meet a facility water temperature. | O28: Free-cooling hours, chiller need at peak, PUE by city. | P28: Ch 3 warm-water explorer; simulator; Ch 4 day model | Q28: Replace with ISHRAE/ASHRAE station design data.
A29: R3-09 | B29: R3 Cooling | C29: Operator practice | D29: Hyperscaler and Indian cooling deployments | E29: Microsoft: zero-water-evaporation designs since Aug 2024, avoiding >125 million L/yr per site; Google Vizag hub air-cooled heat rejection; Meta air-assisted liquid; AWS in-row HX (Jul 2025). India: NTT NAV1 4.8 MW immersion; Sify 130–200 kW/rack; Yotta RDHx 50–60 kW, DLC 80 kW; leading operators PUE 1.4–1.5; MeitY tenders PUE <1.35; Schneider/Motivair factory Bengaluru, Vertiv Pune. | F29: mixed | G29: Global / India | H29: 2024–26 | I29: Company statements; Microsoft blog (Dec 2024) | J29: Open source | K29: Partly verified | L29: =IF(K29="Partly verified","Partly",IF(LEFT(K29,8)="Verified","Yes","No")) -> Partly | M29: Microsoft 125 million L/yr verified (Report 12); others reported. | N29: Benchmarks for what is achievable now. | O29: Target PUE/WUE for new Indian builds. | P29: Ch 3 | Q29: —
A30: R4-01 | B30: R4 Bengaluru | C30: City water | D30: Bengaluru water supply (BWSSB) | E30: ~1,935 MLD delivered of 2,225 MLD capacity; Cauvery Stage V ~485 of 775 MLD; industrial tariff ₹99/kL; STP capacity ~1,348.5 MLD, only ~30 MLD reused commercially at ₹10–20/kL. | F30: MLD, ₹/kL | G30: Bengaluru | H30: Aug 2026 | I30: Karnataka Legislative Council reply (Aug 2026); BWSSB tariff | K30: Reported, not verified | L30: =IF(K30="Partly verified","Partly",IF(LEFT(K30,8)="Verified","Yes","No")) -> No | N30: Denominator for data-centre water shares; water price in calculators. | O30: DC share of city supply (50 MW evaporative ≈ 0.09%); treated-water opportunity. | P30: Ch 4, Ch 6, simulator, Ch 11 city water | Q30: —
A31: R4-02 | B31: R4 Bengaluru | C31: Groundwater | D31: Bengaluru groundwater extraction | E31: Bengaluru Urban extraction 1,457 MLD (2024) from ~600 MLD (2020); every taluk over-exploited; Bangalore East ~305% (2024 assessment), Devanahalli 169%; Bangalore East sustainable groundwater ~45 MLD (series estimate). | F31: % stage of extraction; MLD | G31: Bengaluru taluks | H31: 2024 | I31: Karnataka dynamic groundwater assessment 2024 | K31: Reported, not verified | L31: =IF(K31="Partly verified","Partly",IF(LEFT(K31,8)="Verified","Yes","No")) -> No | M31: Conflicts with Report 10 (Bangalore East 395% in IN-GRES 2025-26, secondary compilation). See Conflicts tab. | N31: Water hard filter and scarcity weighting. | O31: Share of local sustainable groundwater a site would take (50 MW evaporative ≈ 4%). | P31: Ch 4, Ch 6, Ch 10 filter | Q31: Verify on IN-GRES portal.
A32: R4-03 | B32: R4 Bengaluru | C32: DC water use | D32: Bengaluru data-centre water use today | E32: Estimates (MLD): DTE permitted volumes ~2.2; Karnataka IT dept (32 DCs) ~4; series model mixed cooling 4–5; all-evaporative ~8.8; WELL Labs heuristic ~20. BWSSB billing 129,000 L/month for five centres on shared meters; KSPCB cannot quantify. | F32: MLD | G32: Bengaluru | H32: 2025–26 | I32: Down To Earth; Karnataka IT department; WELL Labs; series model | K32: Reported, not verified | L32: =IF(K32="Partly verified","Partly",IF(LEFT(K32,8)="Verified","Yes","No")) -> No | M32: Fivefold spread; nobody meters it. | N32: Shows the disclosure gap. | O32: Range for sector water; case for mandatory metering. | P32: Ch 4 chart | Q32: Request metered data from BWSSB/KSPCB.
A33: R4-04 | B33: R4 Bengaluru | C33: Water stress event | D33: March 2024 borewell failure | E33: 6,997 of 14,781 public borewells failed (47%) after a weak 2023 monsoon; BWSSB banned non-essential potable use; tanker prices capped. | F33: count / % | G33: Bengaluru | H33: Mar 2024 | I33: BWSSB / press reports | K33: Reported, not verified | L33: =IF(K33="Partly verified","Partly",IF(LEFT(K33,8)="Verified","Yes","No")) -> No | N33: Summer stress test for water supply. | O33: Tanker trips and storage days needed in a 2024-style summer. | P33: Ch 6 "Water you can picture" stress test | Q33: —
A34: R4-05 | B34: R4 Bengaluru | C34: Power | D34: Karnataka electricity denominators | E34: Karnataka demand ~93,000 MU/yr; household use ~16,089 MU/yr; a Bengaluru home ~1,800 kWh/yr. | F34: MU | G34: Karnataka | H34: FY25 | I34: Report 4 (state energy statistics) | K34: Reported, not verified | L34: =IF(K34="Partly verified","Partly",IF(LEFT(K34,8)="Verified","Yes","No")) -> No | N34: Express campus energy as share of state demand and homes. | O34: 100 MW AI campus ≈ 841 MU ≈ 5% of household use. | P34: Ch 4 calculator; simulator | Q34: Confirm with KERC/CEA state data.
A35: R4-06 | B35: R4 Bengaluru | C35: Grid connection | D35: KERC supply voltage by contract demand | E35: ≤20 MVA 66 kV; ≤35 MVA (55 MVA since June 2025 if feasible) 110 kV; >20 MVA 220 kV dual circuit; 300 MW+ campuses 400 kV. | F35: MVA / kV | G35: Karnataka | H35: 2025 | I35: KERC conditions of supply (as reported) | K35: Reported, not verified | L35: =IF(K35="Partly verified","Partly",IF(LEFT(K35,8)="Verified","Yes","No")) -> No | N35: Size the grid connection. | O35: Contract MVA = MW × (PUE + 0.12) ÷ 0.95; voltage class. | P35: Ch 4; simulator grid connection | Q35: Check KERC supply code text.
A36: R4-07 | B36: R4 Bengaluru | C36: Comparators | D36: Other water users in Karnataka | E36: MLD: JSW Vijayanagar 330 (allocation); Raichur TPS ~130; 10 m sq ft IT campus ~6; Toyota Bidadi 4.7; brewery 1.7; 1,000-flat apartments 0.61; 500-bed hospital 0.23. | F36: MLD | G36: Karnataka | H36: 2025–26 | I36: Report 4 (company and allocation data; some estimates) | K36: Reported, not verified | L36: =IF(K36="Partly verified","Partly",IF(LEFT(K36,8)="Verified","Yes","No")) -> No | M36: Mix of allocations and estimates. | N36: Put data-centre water in context. | O36: Rank DC water among industrial users. | P36: Ch 4 comparison chart | Q36: —
A37: R4-08 | B37: R4 Bengaluru | C37: Model | D37: Bengaluru campus central cases | E37: 20 MW colo ~178 MU/yr, ~33 MVA, 0.60 MLD on site; 50 MW hyperscale evaporative ~1.47 MLD; 100 MW AI ~841 MU/yr, ~140 MVA, 0.13 MLD; 1 GW target all-evaporative ~32 MLD (~1% of supply). | F37: MU, MVA, MLD | G37: Bengaluru | H37: 2026 | I37: Report 4 calculations | K37: Model output | L37: =IF(K37="Partly verified","Partly",IF(LEFT(K37,8)="Verified","Yes","No")) -> No | N37: Default cases in calculators. | O37: Energy, connection and water per campus size. | P37: Ch 4 calculator; Key numbers | Q37: —
A38: R5-01 | B38: R5 Carbon | C38: Grid carbon | D38: India grid emission factor (CEA) | E38: Weighted average incl. RE, tCO₂/MWh: FY14 0.774; FY21 0.703; FY23 0.716; FY24 0.727; FY25 0.710 (1,234.19 Mt ÷ 1,739.06 BU). | F38: tCO₂/MWh | G38: India | H38: Nov 2025 (v21) | I38: CEA CO₂ Baseline Database User Guide v21 | K38: Partly verified | L38: =IF(K38="Partly verified","Partly",IF(LEFT(K38,8)="Verified","Yes","No")) -> Partly | M38: FY14 and FY25 verified in Report 12; intermediate years reported in Report 11. | N38: Carbon for every calculator. | O38: CO₂ = facility MWh × EF × (1 − clean share); CUE = PUE × EF; ~0.77 at the meter with ~8% losses. | P38: All calculators; Ch 5; Ch 11 carbon | Q38: —
A39: R5-02 | B39: R5 Carbon | C39: Grid carbon | D39: Carbon of 1 TWh by supply type | E39: Mt CO₂ per TWh: India grid avg incl. losses 0.77; Karnataka mix 0.54; marginal coal evening 1.09; 24/7 RE + battery (90% CFE) 0.11; gas CCGT 0.49; France 0.045; Norway 0.025; nuclear 0.009. | F39: Mt/TWh | G39: Various | H39: 2026 | I39: Report 5 comparison across CEA, Ember, IPCC | K39: Model output | L39: =IF(K39="Partly verified","Partly",IF(LEFT(K39,8)="Verified","Yes","No")) -> No | N39: Show that where/when/what you buy matters more than efficiency. | O39: Carbon range for procurement choices. | P39: Ch 5 chart | Q39: —
A40: R5-03 | B40: R5 Carbon | C40: Grid profile | D40: Indian grid hourly fossil profile | E40: Fossil generation ~174 GW at 7 pm vs ~125 GW at 1 pm (H1 2026); Ember India average 670 g/kWh (2025). | F40: GW; g/kWh | G40: India | H40: H1 2026 | I40: Ember (Global Electricity Review 2026, India data) | K40: Reported, not verified | L40: =IF(K40="Partly verified","Partly",IF(LEFT(K40,8)="Verified","Yes","No")) -> No | N40: Case for shifting load to solar hours. | O40: Evening vs solar-hour intensity gap. | P40: Ch 5 headline | Q40: —
A41: R5-04 | B41: R5 Carbon | C41: Grid profile | D41: Karnataka hourly carbon curve (illustrative) | E41: Average intensity by hour 215–610 gCO₂/kWh (low at 13:00, high at 20:00); marginal unit coal 980 (1,080 at 18–22 h). Third-party dashboard 90-day range ~210–603 g. | F41: gCO₂/kWh | G41: Karnataka | H41: 2026 | I41: Modelled third-party dashboard (Report 5) | K41: Model output | L41: =IF(K41="Partly verified","Partly",IF(LEFT(K41,8)="Verified","Yes","No")) -> No | M41: No official hourly or marginal factor exists for India. | N41: Hourly carbon in the 24-hour Bengaluru day and load-shift calculator. | O41: CO₂ saved per MWh shifted (~0.30 t/MWh evening → solar). | P41: Ch 4 day model; Ch 5 load shift | Q41: Ask CEA to publish hourly/marginal factors.
...

Sheet Verified figures
A1: Individually verified figures
A2: Confirmed against the source document during the research (Report 12). Secondary = confirmed via a summary of the primary.
A4: # | B4: Figure | C4: Value | D4: As of | E4: Source | F4: Link | G4: Status | H4: Register ID | I4: Confirms or corrects
A5: 1 | B5: Microsoft fleet WUE / PUE | C5: 0.30 L/kWh / 1.16 (FY24); 0.27 / 1.17 (FY25) | D5: FY24–25 | E5: Microsoft datacenter efficiency page | F5: Open source | G5: Verified | H5: R12-03 | I5: Confirms Report 3 "fleet WUE 0.30"
A6: 2 | B6: Microsoft Asia-Pacific WUE / PUE | C6: 0.03 / 1.25 (FY24); 0.25 / 1.28 (FY25) | D6: FY24–25 | E6: Microsoft datacenter efficiency page | F6: Open source | G6: Verified | H6: R12-03
A7: 3 | B7: Microsoft zero-water cooling design | C7: Avoids >125 million L/yr per datacenter; all new designs from Aug 2024 | D7: Dec 2024 | E7: Microsoft Cloud blog | F7: Open source | G7: Verified | H7: R3-09 | I7: Confirms Report 3
A8: 4 | B8: Google fleet PUE | C8: 1.09 | D8: 2025 | E8: Google data centre efficiency | F8: Open source | G8: Verified | H8: R12-03 | I8: Confirms Key numbers
A9: 5 | B9: Gemini median text prompt | C9: 0.24 Wh; 0.26 mL water (0.15 mL narrow); 0.03 gCO₂e | D9: May 2025 | E9: Elsworth et al. (Google), arXiv 2508.15734 | F9: Open source | G9: Verified | H9: R2-03 | I9: Confirms Reports 2 and 6
A10: 6 | B10: US data-centre average site WUE | C10: ~0.36 L/kWh through 2023; 0.45–0.48 after | D10: 2024 | E10: LBNL US Data Center Energy Usage Report | F10: Open source | G10: Verified | H10: R12-03
A11: 7 | B11: US data-centre water | C11: 66 bn L direct (2023); ~800 bn L at power plants (4.52 L/kWh) on ~176 TWh | D11: 2024 | E11: LBNL 2024 | F11: Open source | G11: Verified | H11: R12-08
A12: 8 | B12: US hyperscale median WUE | C12: 0.32 L/kWh (0.40 if adiabatic at 0.2); adiabatic self-reported 0.1–0.3 | D12: 2024 | E12: LBNL 2024 | F12: Open source | G12: Verified | H12: R12-03
A13: 9 | B13: US average PUE (LBNL) | C13: 1.6 (2014), 1.4 (2023), 1.15–1.35 (2028) | D13: 2024 | E13: LBNL 2024 | F13: Open source | G13: Verified | H13: R12-03
A14: 10 | B14: UPS efficiency by class | C14: Edge 77–85%; colo 80–94%; hyperscale/AI 90–99% | D14: 2024 | E14: LBNL 2024 | F14: Open source | G14: Verified | H14: R2-06
A15: 11 | B15: Server utilisation and AI load factors | C15: Colo 21% (2014) → 35% (2027); hyperscale 45% → 50%; AI training 80% of time at ~70% rated; inference 40% | D15: 2024 | E15: LBNL 2024 | F15: Open source | G15: Verified | H15: R12-13
A16: 12 | B16: DGX H100 rated power | C16: 10.2 kW (8 GPU); saturated node 7.9 kW | D16: 2024 | E16: LBNL 2024 | F16: Open source | G16: Verified | H16: R2-04 | I16: Confirms Report 2
A17: 13 | B17: DGX B200 maximum power | C17: 14.3 kW | D17: 2025 | E17: NVIDIA DGX B200 user guide | F17: Open source | G17: Verified | H17: R2-04
A18: 14 | B18: NTT DATA WUE and PUE | C18: Portfolio WUE 1.01 / 0.65 / 0.72; evaporative sites 2.93 / 2.77 / 1.42; PUE 1.40 / 1.38 / 1.38 | D18: FY22–24 | E18: NTT DATA ESG environment data | F18: Open source | G18: Verified | H18: R12-03
A19: 15 | B19: Global average PUE (Uptime) | C19: 1.54 (2025); 1.56 (2024); 1.58 (2023); facilities since ~2020 1.48; >20 MW 1.44 | D19: 2025 | E19: Uptime Institute Global Data Center Survey 2025 | F19: Open source | G19: Verified | H19: R12-03 | I19: Confirms Key numbers and Report 1 (1.44 for >20 MW)
A20: 16 | B20: Asia-Pacific average PUE (excl. China) | C20: 1.52 (n = 79) vs global 1.54 | D20: 2025 | E20: Uptime Field Report 183 | F20: Open source | G20: Verified | H20: R11-06
A21: 17 | B21: GPT-3 request served from India (Li et al.) | C21: 19.7 mL (0 on-site + 19.7 off-site); PUE 1.430; EWIF 3.445 L/kWh; Microsoft India on-site WUE 0.000 | D21: 2023/2025 | E21: Li, Yang, Islam & Ren, ACM | F21: Open source | G21: Verified | H21: R6-05 | I21: Confirms Report 6
A22: 18 | B22: CEEW India sector data | C22: DCs ≈ 0.5% of national electricity (2025); ~271 DCs (Jan 2026); 100 MW hyperscale ~2 million L/day | D22: Feb 2026 | E22: CEEW & Systemiq, Scaling India's Data Centre Ecosystem | F22: Open source | G22: Verified | H22: R12-04 | I22: Confirms Report 11 calibration
A23: 19 | B23: Indian operator water disclosure | C23: Nxtra and CtrlS publish no WUE; CtrlS 409,037 kL (2023-24) vs 468,330 kL (2022-23); Yotta gives no number | D23: 2025 | E23: Down To Earth | F23: Open source | G23: Verified | H23: R6-07 | I23: Confirms Report 6 disclosure gap
A24: 20 | B24: Karnataka Sustainable DC Policy 2026–31 | C24: Plant-wise PUE and WUE reporting required; water-charge reimbursement for WUE 0.7–1.3 L/kWh | D24: 2026 | E24: The News Minute (policy summary) | F24: Open source | G24: Verified | H24: R9-01 | I24: Confirms Report 4 critique of the WUE band
A25: 21 | B25: Thermal plant water norms | C25: ≤3.5 m³/MWh for existing cooling-tower plants (by 7 Dec 2017); 2.5 m³/MWh for post-2017 plants, relaxed to 3.0 (Jun 2018) | D25: 2015/2018 | E25: MoEFCC S.O. 3305(E) (CPCB); PowerLine | F25: Open source | G25: Verified | H25: R12-05 | I25: Confirms Report 5 "3.5/3.0 norms"
A26: 22 | B26: Indian coal plant water consumption | C26: 2.8–3.4 m³/MWh (≈2× world 1.2–1.5); air-cooled condenser 0.45–0.65 | D26: 2023 | E26: Energy journal (SD23) vulnerability assessment | F26: Open source | G26: Verified | H26: R12-05 | I26: Confirms Report 5 (~3,400 L/MWh)
A27: 23 | B27: Coal plant withdrawal and FGD | C27: Once-through 70–200 m³/MWh; average withdrawal ~4 m³/MWh; FGD adds ~0.3 m³/MWh | D27: Sep 2026 | E27: CSE via PowerLine | F27: Open source | G27: Verified | H27: R12-05
A28: 24 | B28: Nuclear and thermal water factors (NREL) | C28: Nuclear tower 672 gal/MWh = 2.54 L/kWh; tower thermal upper ~1,000 gal/MWh ≈ 3.8 L/kWh; wind ~0 | D28: 2011 | E28: Macknick et al., NREL | F28: Open source | G28: Verified | H28: R12-05 | I28: Confirms Report 5 nuclear ~2,600 L/MWh
A29: 25 | B29: Thermal plants in water-stressed areas | C29: 40% now; 70% by 2030; 14 of 20 utilities had shutdowns 2013–16 costing US$1.4 bn | D29: Jan 2018 | E29: WRI | F29: Open source | G29: Verified | H29: R12-06
A30: 26 | B30: India FY25 generation | C30: 1,824 BU total; thermal 1,363 BU (74.7%) | D30: FY2024-25 | E30: CREA via Deccan Herald | F30: Open source | G30: Verified | H30: R12-07
A31: 27 | B31: India and Karnataka renewable share | C31: RE 403.64 BU (22.13% of generation); Karnataka RE 48.10% of state generation | D31: FY2024-25 | E31: MNRE Renewable Energy Statistics 2024-25 | F31: Open source | G31: Verified | H31: R12-07
A32: 28 | B32: India grid emission factor | C32: 0.710 tCO₂/MWh FY25 (1,234.19 Mt ÷ 1,739.06 BU); 0.774 FY2013-14 | D32: Nov 2025 | E32: CEA CO₂ Baseline Database User Guide v21 | F32: (not captured) | G32: Verified | H32: R5-01 | I32: Confirms Reports 5, 7, 8, 11 and simulator
A33: 29 | B33: EU water reporting | C33: Sites ≥500 kW IT report total and potable water input (m³); first returns 15 Sep 2024, then 15 May yearly | D33: 2024 | E33: Delegated Regulation (EU) 2024/1364 | F33: Open source | G33: Verified | H33: R12-01 | I33: Confirms Report 8
A34: 30 | B34: NERC large-load events | C34: ~1,500 MW DC load disconnected 10 Jul 2024 (60 load points, 25 substations); 1,800 MW loss Feb 2025 | D34: 2025 | E34: NERC / FERC presentation | F34: Open source | G34: Verified | H34: R2-07 | I34: Confirms Report 2
A35: 31 | B35: IEX prices | C35: DAM Jan 2026 ₹3.86, Feb ₹3.58; G-DAM FY25 ₹4.01, Jan 2026 ₹4.06, Feb ₹3.43 | D35: 2026 | E35: IEX via SaurEnergy and Business Standard | F35: Open source | G35: Verified | H35: R12-16
A36: 32 | B36: SECI firm renewable tenders | C36: FDRE-RTC ₹5.25/kWh; 4-hour assured peak ₹5.99/kWh; RTC-IV ₹5.06–5.07; SJVN FDRE-3 ₹4.82–4.91 | D36: Aug 2026 | E36: pv-magazine; SaurEnergy | F36: Open source | G36: Verified | H36: R12-16 | I36: Confirms Reports 7 and 8 (₹5.25)
A37: 33 | B37: ISTS charge waiver phase-out | C37: ISTS charges at 25% for COD Jul 2025–Jun 2026, then 50%, 75%, 100% after 1 Jul 2028 | D37: 2025 | E37: Ministry of Power via T&D India | F37: Open source | G37: Verified | H37: R12-16
A38: 34 | B38: Green Energy Open Access Rules 2022 | C38: CSS may not rise >50% over 12 years; additional surcharge not applicable if fixed charges paid; banking ≥30% monthly | D38: Jun 2022 | E38: GEOA Rules gazette | F38: Open source | G38: Verified | H38: R12-16 | I38: Confirms Report 9
A39: 35 | B39: FOR model GEOA regulations | C39: Cross-subsidy surcharge not to exceed 20% of tariff or ABR | D39: — | E39: Forum of Regulators | F39: Open source | G39: Verified | H39: R12-16
A40: 36 | B40: MSEDCL HT tariffs (MERC MYT) | C40: HT-I(A) ₹7.48/kVAh FY26 → 7.27 → 7.11; ₹555/560/565 per kVA-month; HT-II commercial ₹9.26 + ₹0.62; 10% wheeling discount for DCs on OA/green tariff | D40: Mar 2025 | E40: MERC press note, MSEDCL MYT order | F40: Open source | G40: Verified | H40: R12-15 | I40: Differs from Reports 7/10 (₹7.27 / ₹7.11–7.27) — see Conflicts
A41: 37 | B41: Tata Power-D HT tariffs | C41: HT-II / EHV commercial ₹5.89 + ₹0.69 wheeling / ₹5.89; ₹300/kVA-month; green tariff ₹0.25/kWh | D41: Mar 2025 | E41: MERC press note, TPC-D MYT order | F41: Open source | G41: Verified | H41: R12-15
...

Sheet Conflicts
A1: Where our sources disagree
A2: Use the "Use now" column until the conflict is resolved.
A4: # | B4: Topic | C4: Value A (source) | D4: Value B (source) | E4: Likely reason | F4: Use now | G4: How to resolve
A5: 1 | B5: MSEDCL HT-I(A) energy charge | C5: ₹7.48/kVAh FY26 → 7.27 → 7.11 (MERC press note; verified in Report 12) | D5: ₹7.11–7.27 (Report 10, MERC documents); ₹7.27 (Report 7 and simulator); ₹8.68 after a Mar 2026 review (blog, unverified) | E5: Different tariff years and documents; blog figure unconfirmed | F5: Use ₹7.48 for FY26 and ₹7.27 for FY27 per MERC; ignore ₹8.68 until an order is found | G5: Pull MERC Case 217/2024 schedule and any 2026 review order
A6: 2 | B6: Karnataka HT-2(a) energy charge | C6: 660 paise/kWh FY26–27, ₹345/kVA (KERC schedule; verified in Report 12) | D6: ~700 paise + ~₹355/kVA (Report 10, unconfirmed row); ₹6.70 + ₹365 (Report 7 and simulator) | E6: Report 10 subagent could not confirm the row; Report 7 used an older figure | F6: Use 660 paise + ₹345 (+36 paise P&G, +56 paise BESCOM true-up where applicable) | G6: Update Report 10 effective tariff (≈₹7.61) and simulator
A7: 3 | B7: Bangalore East groundwater stage | C7: ~305% (2024 assessment; Report 4) | D7: 395% (IN-GRES 2025-26, secondary compilation; Report 10) | E7: Different assessment years and sources | F7: Both say severely over-exploited; cite as "305–395%" until verified | G7: Check IN-GRES 2025-26 directly
A8: 4 | B8: India operational capacity | C8: 1,789 MW (C&W, H1 2026) | D8: 1,637 MW (JLL, Jun 2026); 1.57 GW (PIB, Aug 2026); ~1.7 GW end-2025 (CBRE) | E8: Coverage (7 markets vs national), IT vs gross MW, timing | F8: Use C&W for city splits; quote 1.6–1.8 GW range | G8: Rebase every six months
A9: 5 | B9: Colocation vacancy | C9: 14.9% (C&W) | D9: 2.8% (JLL) | E9: Different definitions of vacancy | F9: Avoid using vacancy as a model input without stating the source | G9: —
A10: 6 | B10: Global DC electricity 2024 | C10: 415 TWh (IEA Apr 2025) | D10: 485 TWh (IEA 2026 update) | E10: Revised baseline | F10: Use the 2026 update for new work; atlas still shows 415 | G10: Update atlas Ch 2 chart
A11: 7 | B11: Power-station water, non-Karnataka states | C11: 2.2 L/kWh (simulator, Reports 4–6) | D11: 2.8–3.4 L/kWh (Report 12 proxies for MH, TG, UP); 3.0 national default | E11: Report 12 recomputed from the FY25 generation mix | F11: Use Report 12 values | G11: Update simulator input
A12: 8 | B12: Karnataka power-station water | C12: ~1.5 L/kWh (Reports 4–6) | D12: 1.5–2.2 L/kWh (Report 12 proxy); 1.8 used in Example C | E12: Report 12 range based on 48% RE share | F12: Use 1.8 as central value | G12: —
A13: 9 | B13: Group-captive renewable landed cost | C13: ₹5.5–7/kWh (Report 8) | D13: ₹6.5–7.5/kWh landed incl. wheeling, losses, banking and demand (Report 12) | E13: Report 12 adds delivery charges and demand charge | F13: Use Report 12 build-up | G13: —
A14: 10 | B14: Third-party open access landed cost | C14: ₹6.5–8/kWh (Report 8) | D14: ₹8.5–10/kWh once CSS, AS and residual demand are added (Report 12) | E14: Report 12 includes state surcharges | F14: Use Report 12 build-up | G14: —
A15: 11 | B15: Hyderabad adiabatic annual WUE | C15: 0.45 L/kWh (Report 12 planning value) | D15: 0.31 L/kWh (atlas Ch 12 hourly model on average temperatures) | E15: Average temperatures miss heatwaves; report adds margin | F15: Plan with 0.45 | G15: Calibrate with ISHRAE TMY
A16: 12 | B16: Peak-hour reduction from "dry at noon" | C16: Halves peak hour with an 11:00–16:00 window (Report 12 text) | D16: Only 67 → 63 kL/h with 11:00–16:00 on Report 12's own profile; 67 → 47 kL/h with 10:00–18:00 | E16: 16:00–17:00 hours stay hot | F16: Use a window to ~18:00 | G16: —
... A21: 17 | B21: Tamil Nadu policy status | C21: Lapsed 31 Mar 2026 (Report 9) | D21: — | E21: — | F21: Treat incentives as unavailable until a successor is notified | G21: Track TN notifications

Sheet Data gaps
A1: Data gaps and how to close them
A2: Sorted by priority.
A4: # | B4: Gap | C4: Why it matters | D4: Who to ask / where | E4: Instrument | F4: Affects (Register IDs, chapters) | G4: Priority
A5: 1 | B5: Substation spare capacity (MVA headroom) | C5: Binding constraint for every site; power scores rest on tariff and judgement | D5: MSETCL, TANTRANSCO, KPTCL, TGTRANSCO, APTRANSCO, UPPTCL, HVPNL, DTL, GETCO, WBSETCL, KSEB-T, OPTCL, RVPN, MPPTCL, CSPTCL; CTUIL (ISTS GNA margins); Grid-India ATC/TTC | E5: Load-flow / connectivity study request | F5: R10-02, R10-12; Ch 10 | G5: High
A6: 2 | B6: EHV node names and distances | C6: All 50 site distances are estimates | D6: STU single-line diagrams; CEA/CTUIL transmission maps | E6: Map check | F6: R10-02; Ch 10 filter | G6: High
A7: 3 | B7: Block-level groundwater categories | C7: Only Bengaluru, Chennai, Haryana and national figures are reported | D7: IN-GRES (ingres.iith.ac.in), CGWB 2025 assessment | E7: Portal download | F7: R4-02, R10-06; Ch 10 water filter | G7: High
A8: 4 | B8: Operator WUE / PUE (metered) | C8: No national dataset; most Indian operators publish neither | D8: Nxtra, CtrlS, Yotta, Sify, STT GDC, AdaniConneX, NTT India; Karnataka plant-wise filings | E8: ESG/BRSR requests; Karnataka disclosures | F8: R6-07, R12-03, R11-06 | G8: High
A9: 5 | B9: Hourly climate (typical-year files) | C9: Wet-mode hours, free-cooling hours, design temperatures are approximations | D9: ISHRAE / ASHRAE TMY for 8+ cities | E9: Licence | F9: R3-08, R10-02, R12-11, R12-14 | G9: High
A10: 6 | B10: Tariff conflicts and missing orders | C10: MSEDCL, KERC differ across reports; DERC, APERC energy, Gujarat demand slabs, WB energy, Rajasthan, MP mapping, Kerala demand unverified | D10: MERC Case 217/2024 and 2026 orders; KERC; DERC; APERC; GERC; WBERC; RERC; MPERC; KSERC | E10: Regulator PDFs | F10: R7-11, R10-04, R10-05, R12-15 | G10: High
A11: 7 | B11: CSS, additional surcharge and wheeling for MH and KA | C11: Needed for open-access landed cost | D11: MERC tables 446–447; KERC OA orders | E11: Regulator PDFs | F11: R12-16 | G11: Medium
A12: 8 | B12: Water permits and allocations for named DC projects | C12: No verified Indian figures found (Navi Mumbai, Chennai, Hyderabad, Vizag, Greater Noida, Hoskote) | D12: State PCBs (CTE/CTO), MIDC, CMWSSB, HMWSSB, BWSSB, GVMC; MoEFCC PARIVESH | E12: RTI; portal downloads | F12: R12-12; Ch 12 | G12: Medium
A13: 9 | B13: Hourly and marginal grid emission factors | C13: No official hourly or marginal factor for India | D13: CEA; Grid-India; SLDCs | E13: Policy request | F13: R5-04 | G13: Medium
A14: 10 | B14: Hourly DC load data | C14: All hourly profiles are modelled | D14: Grid-India / SLDCs; DISCOM AMR data | E14: Data-sharing MoU | F14: R12-14, R4 day model | G14: Medium
A15: 11 | B15: Plant-level power-station water | C15: Grid water intensity is modelled from norms and studies | D15: CEA; plant CTO returns; WRI India | E15: RTI; WRI satellite method | F15: R12-08 | G15: Medium
A16: 12 | B16: State electricity requirement tables | C16: State DC shares use extrapolated denominators | D16: 20th EPS mid-term review state tables (CEA) | E16: Publication | F16: R11-16 | G16: Medium
... A25: 21 | B25: Measured network latency | C25: Latency uses straight-line distance × 1.4 | D25: RIPE Atlas; operators | E25: Measurement | F25: R10-10 | G25: Low

Sheet Sources
A1: Sources
A2: Links captured by the research runs. Reports 1–11 named many sources without links; those are listed without one.
A4: # | B4: Source | C4: Used in | D4: Link
A5: 1 | B5: LBNL 2024 US Data Center Energy Usage Report | C5: Report 12 (Verified) | D5: https://eta-publications.lbl.gov/sites/default/files/2024-12/lbnl-2024-united-states-data-center-energy-usage-report_1.pdf
A6: 2 | B6: Uptime Institute Global Data Center Survey 2025 | C6: Report 12 (Verified); Key numbers | D6: https://datacenter.uptimeinstitute.com/rs/711-RIA-145/images/2025.Annual.Survey.Report.pdf?version=0
A7: 3 | B7: Google: Measuring the environmental impact of delivering AI (arXiv 2508.15734) | C7: Reports 2, 6, 12 | D7: https://arxiv.org/pdf/2508.15734
A8: 4 | B8: Google data-centre efficiency | C8: Report 12 | D8: https://datacenters.google/efficiency/
A9: 5 | B9: Microsoft datacenter efficiency | C9: Report 12 | D9: https://datacenters.microsoft.com/sustainability/efficiency/
A10: 6 | B10: Microsoft: zero-water cooling blog (Dec 2024) | C10: Reports 3, 12 | D10: https://www.microsoft.com/en-us/microsoft-cloud/blog/2024/12/09/sustainable-by-design-next-generation-datacenters-consume-zero-water-for-cooling/
A11: 7 | B11: Li, Yang, Islam & Ren, Making AI Less "Thirsty" (ACM) | C11: Reports 6, 12 | D11: https://dl.acm.org/doi/10.1145/3724499
A12: 8 | B12: NTT DATA ESG environment data | C12: Report 12 | D12: https://www.nttdata.com/global/en/about-us/sustainability/esg-data/environment-data
A13: 9 | B13: Down To Earth: India's digital thirst | C13: Reports 4, 6, 12 | D13: https://www.downtoearth.org.in/science-technology/indias-digital-thirst-what-data-centre-giants-arent-saying-about-their-water-use
A14: 10 | B14: CEEW & Systemiq, Scaling India's Data Centre Ecosystem (Feb 2026) | C14: Reports 9, 11, 12 | D14: https://www.ceew.in/sites/default/files/ceew-data-centre-study-web-ready-final.pdf
A15: 11 | B15: Karnataka DC Policy 2026–31 (The News Minute) | C15: Reports 4, 9, 12 | D15: https://www.thenewsminute.com/karnataka/karnatakas-new-data-centre-policy-puts-water-energy-in-focus-what-does-it-say
A16: 12 | B16: MoEFCC S.O. 3305(E) thermal plant norms (CPCB) | C16: Reports 5, 12 | D16: https://cpcb.nic.in/uploads/Thermal_Power_Plant_overview.pdf
... A58: 54 | B58: WELL Labs; KSPCB; Karnataka IT department (Bengaluru DC water) | C58: Report 4 | D58: (no link captured)
