Workbook

Sheet Index
A1: India data centres: all report tables in one place
A2: 259 tables from Reports 1–12, the simulator and the key-numbers sheet. Click a title to jump to it. Tabs R1–R12 hold every table copied from the full research reports. The "Atlas R1-R9" tab keeps extra tables built from the atlas charts and calculators for Reports 1–9 (chart data, capex build-ups, state scores), and the Simulator and Key numbers tabs hold the atlas model inputs.
A4: # | B4: Report | C4: Table ID | D4: Title (click to open) | E4: Rows | F4: Columns | G4: Source | H4: Sheet | I4: Data basis | J4: How it is used in the atlas | K4: What it is used to derive
A5: 1 | B5: Report 1 · Types of data centre | C5: R1-T01 | D5: Data-centre types by ownership and business model | E5: 6 | F5: 7 | G5: Report 1 (full research report) · 1. Types of Data Centre › 1.1 Deep analysis of the types: what exists, what dominates globally, and why | H5: R1 | I5: Mixed: sourced figures plus estimates | J5: Ch 1 "Type explorer" cards (how it works, cost, strengths, users) and the Type finder rules. | K5: Which business model fits a project size and workload.
A6: 2 | B6: Report 1 · Types of data centre | C6: R1-T02 | D6: Uptime Tiers: redundancy, availability and downtime | E6: 4 | F6: 7 | G6: Report 1 (full research report) · 1. Types of Data Centre › 1.1 Deep analysis of the types: what exists, what dominates globally, and why | H6: R1 | I6: Source-derived (reported, not re-verified) | J6: Ch 1 "What a Tier buys you" downtime clock. | K6: Downtime hours a year = (1 − availability) × 8,760 per Tier.
A7: 3 | B7: Report 1 · Types of data centre | C7: R1-T03 | D7: Cooling approaches: density, efficiency and water | E7: 5 | F7: 6 | G7: Report 1 (full research report) · 1. Types of Data Centre › 1.1 Deep analysis of the types: what exists, what dominates globally, and why | H7: R1 | I7: Mixed: sourced figures plus estimates | J7: Ch 3 cooling comparison text; density limits used in the Rack inspector bands. | K7: Practical rack-density ceiling per cooling method.
A8: 4 | B8: Report 1 · Types of data centre | C8: R1-T04 | D8: Global market share and installed capacity by type (2024–2026) | E8: 11 | F8: 3 | G8: Report 1 (full research report) · 1. Types of Data Centre › 1.1 Deep analysis of the types: what exists, what dominates globally, and why | H8: R1 | I8: Source-derived (reported, not re-verified) | J8: Ch 1 headline numbers and "Who owns the world's capacity" chart; Key numbers. | K8: Global growth and hyperscale share trend to set India in context.
A9: 5 | B9: Report 1 · Types of data centre | C9: R1-T05 | D9: India vs global capacity | E9: 7 | F9: 4 | G9: Report 1 (full research report) · 1. Types of Data Centre › 1.2 Indian perspective: which types to build, why, and how | H9: R1 | I9: Source-derived (reported, not re-verified) | J9: Ch 1 and Overview context; Key numbers (India operational capacity, pipeline). | K9: India's share of global capacity; range of Indian capacity estimates.
A10: 6 | B10: Report 1 · Types of data centre | C10: R1-T06 | D10: Key Indian hubs (Cushman & Wakefield, H1 2026) | E10: 8 | F10: 4 | G10: Report 1 (full research report) · 1. Types of Data Centre › 1.2 Indian perspective: which types to build, why, and how | H10: R1 | I10: Source-derived (reported, not re-verified) | J10: Ch 1 "India by city" chart; Ch 9 map (live and pipeline MW); Ch 10 demand scores; Ch 11 starting point. | K10: City shares, pipeline-to-stock ratios, forecast anchor (1,789 MW).
A11: 7 | B11: Report 1 · Types of data centre | C11: R1-T07 | D11: State policies: key terms | E11: 7 | F11: 4 | G11: Report 1 (full research report) · 1. Types of Data Centre › 1.2 Indian perspective: which types to build, why, and how | H11: R1 | I11: Source-derived (reported, not re-verified) | J11: Superseded by Report 9 tables; feeds Ch 9 policy register. | K11: Early comparison of state incentives.
A12: 8 | B12: Report 2 · AI vs conventional | C12: R2-T01 | D12: Electricity split by subsystem and facility class | E12: 4 | F12: 5 | G12: Report 2 (full research report) · Section 1: Anatomy of Data Centre Consumption › 1.1 Electricity breakdown by subsystem | H12: R2 | I12: Illustrative / framework / author judgement | J12: Ch 2 "Where the power goes, by facility class" chart. | K12: Overhead share of energy by facility class; PUE build-up.
A13: 9 | B13: Report 2 · AI vs conventional | C13: R2-T02 | D13: Server power split: conventional CPU vs AI accelerated | E13: 5 | F13: 3 | G13: Report 2 (full research report) · Section 1: Anatomy of Data Centre Consumption › 1.2 Inside the IT load: CPUs, GPUs, memory, storage and networking | H13: R2 | I13: Illustrative / framework / author judgement | J13: Ch 2 text on IT-load anatomy (reference). | K13: Share of rack power going to accelerators.
A14: 10 | B14: Report 2 · AI vs conventional | C14: R2-T03 | D14: Efficiency metrics: PUE, WUE, CUE and ERE | E14: 4 | F14: 3 | G14: Report 2 (full research report) · Section 1: Anatomy of Data Centre Consumption › 1.3 Efficiency metrics: PUE, WUE, CUE and ERE | H14: R2 | I14: Source-derived (reported, not re-verified) | J14: Ch 2 and Ch 8 metric definitions; Key numbers (PUE 1.54, Google 1.09, MeitY <1.35). | K14: PUE and WUE benchmarks for calculators.
A15: 11 | B15: Report 2 · AI vs conventional | C15: R2-T04 | D15: Water per AI query: a contested range | E15: 4 | F15: 3 | G15: Report 2 (full research report) · Section 1: Anatomy of Data Centre Consumption › 1.4 Water consumption: direct and indirect | H15: R2 | I15: Source-derived (reported, not re-verified) | J15: Ch 6 and Ch 12 "Water per AI prompt" charts. | K15: Water per prompt with different boundaries.
A16: 12 | B16: Report 2 · AI vs conventional | C16: R2-T05 | D16: US data-centre electricity (LBNL 2024) | E16: 4 | F16: 3 | G16: Report 2 (full research report) · Section 1: Anatomy of Data Centre Consumption › 1.6 Global and regional electricity consumption | H16: R2 | I16: Source-derived (reported, not re-verified) | J16: Ch 2 context text (reference only). | K16: US growth path as a comparison for India.
... A263: 259 | B263: Key numbers (all reports) | C263: KEY-T01 | D263: Key numbers cheat sheet | E263: 42 | F263: 3 | G263: Atlas Key numbers (all reports) | H263: Key numbers | I263: Mixed: sourced figures plus estimates | J263: Key numbers cheat sheet (searchable list) at the end of the atlas. | K263: Quick reference for the most-used figures; each row names its source.
A265: Tables per report
B266: Report 1 · Types of data centre | C266: =COUNTIF($B$5:$B$263,B266) -> 7
B267: Report 2 · AI vs conventional | C267: =COUNTIF($B$5:$B$263,B267) -> 9
B268: Report 3 · Cooling | C268: =COUNTIF($B$5:$B$263,B268) -> 15
B269: Report 4 · Bengaluru water and power | C269: =COUNTIF($B$5:$B$263,B269) -> 8
B270: Report 5 · Carbon | C270: =COUNTIF($B$5:$B$263,B270) -> 8
B271: Report 6 · Water impact | C271: =COUNTIF($B$5:$B$263,B271) -> 22
B272: Report 7 · Unit economics | C272: =COUNTIF($B$5:$B$263,B272) -> 24
B273: Report 8 · Green data centres | C273: =COUNTIF($B$5:$B$263,B273) -> 12
B274: Report 9 · State policies | C274: =COUNTIF($B$5:$B$263,B274) -> 4
B275: Report 10 · Where to build | C275: =COUNTIF($B$5:$B$263,B275) -> 22
B276: Report 11 · Forecast to 2035 | C276: =COUNTIF($B$5:$B$263,B276) -> 28
B277: Report 12 · Water and energy | C277: =COUNTIF($B$5:$B$263,B277) -> 28
... B280: Key numbers (all reports) | C280: =COUNTIF($B$5:$B$263,B280) -> 1
B281: Total | C281: =SUM(C266:C280) -> 259

Sheet How to read
A1: How these tables feed the atlas
A2: Every table carries three lines under its title: data basis, how it is used in the atlas, and what it is used to derive. The Index repeats them as filterable columns.
A4: Data basis
A5: Category | B5: Meaning | C5: How to treat it
A6: Source-derived, verified | B6: Figures checked against the primary document during the research (Report 12 labelled these one by one). | C6: Safe to cite; still note the date.
A7: Source-derived (reported, not re-verified) | B7: Figures taken from a named source (consultancy, regulator, company, IEA, etc.) as cited in the report, without a check against the original. | C7: Cite with the source; confirm against the original before decisions.
A8: Mixed: sourced figures plus estimates | B8: A table combining reported numbers with analyst estimates or ranges (for example EHV distances or design temperatures alongside tariffs). | C8: Use the sourced columns as data and the estimated ones as placeholders.
A9: Proxy / estimate | B9: Engineering ranges, analogues, typical values or assumptions standing in for missing Indian data. | C9: Indicative only; replace with measured or official data when available.
A10: Illustrative / framework / author judgement | B10: Scorecards, indices, weights, maturity levels, thresholds and recommendations created by the research series. | C10: A method, not data; change the weights or scores to suit your view.
A11: Calculated (model output) | B11: Results of the series' formulas (worked examples, capex stacks, LCOD, forecasts, rankings, water balances). | C11: Only as good as the inputs; rerun when inputs change.
A13: Count of tables by report and basis (live)
A14: Report | B14: Source-derived, verified | C14: Source-derived (reported, not re-verified) | D14: Mixed: sourced figures plus estimates | E14: Proxy / estimate | F14: Illustrative / framework / author judgement | G14: Calculated (model output) | H14: Total
A15: Report 1 · Types of data centre | B15: =COUNTIFS(Index!$B$5:$B$263,$A15,Index!$I$5:$I$263,B$14) -> 0 | C15: =COUNTIFS(Index!$B$5:$B$263,$A15,Index!$I$5:$I$263,C$14) -> 5 | D15: =COUNTIFS(Index!$B$5:$B$263,$A15,Index!$I$5:$I$263,D$14) -> 2 | E15: =COUNTIFS(Index!$B$5:$B$263,$A15,Index!$I$5:$I$263,E$14) -> 0 | F15: =COUNTIFS(Index!$B$5:$B$263,$A15,Index!$I$5:$I$263,F$14) -> 0 | G15: =COUNTIFS(Index!$B$5:$B$263,$A15,Index!$I$5:$I$263,G$14) -> 0 | H15: =SUM(B15:G15) -> 7
A16: Report 2 · AI vs conventional | B16: =COUNTIFS(Index!$B$5:$B$263,$A16,Index!$I$5:$I$263,B$14) -> 0 | C16: =COUNTIFS(Index!$B$5:$B$263,$A16,Index!$I$5:$I$263,C$14) -> 4 | D16: =COUNTIFS(Index!$B$5:$B$263,$A16,Index!$I$5:$I$263,D$14) -> 2 | E16: =COUNTIFS(Index!$B$5:$B$263,$A16,Index!$I$5:$I$263,E$14) -> 0 | F16: =COUNTIFS(Index!$B$5:$B$263,$A16,Index!$I$5:$I$263,F$14) -> 3 | G16: =COUNTIFS(Index!$B$5:$B$263,$A16,Index!$I$5:$I$263,G$14) -> 0 | H16: =SUM(B16:G16) -> 9
A17: Report 3 · Cooling | B17: =COUNTIFS(Index!$B$5:$B$263,$A17,Index!$I$5:$I$263,B$14) -> 0 | C17: =COUNTIFS(Index!$B$5:$B$263,$A17,Index!$I$5:$I$263,C$14) -> 6 | D17: =COUNTIFS(Index!$B$5:$B$263,$A17,Index!$I$5:$I$263,D$14) -> 6 | E17: =COUNTIFS(Index!$B$5:$B$263,$A17,Index!$I$5:$I$263,E$14) -> 2 | F17: =COUNTIFS(Index!$B$5:$B$263,$A17,Index!$I$5:$I$263,F$14) -> 1 | G17: =COUNTIFS(Index!$B$5:$B$263,$A17,Index!$I$5:$I$263,G$14) -> 0 | H17: =SUM(B17:G17) -> 15
A18: Report 4 · Bengaluru water and power | B18: =COUNTIFS(Index!$B$5:$B$263,$A18,Index!$I$5:$I$263,B$14) -> 0 | C18: =COUNTIFS(Index!$B$5:$B$263,$A18,Index!$I$5:$I$263,C$14) -> 1 | D18: =COUNTIFS(Index!$B$5:$B$263,$A18,Index!$I$5:$I$263,D$14) -> 1 | E18: =COUNTIFS(Index!$B$5:$B$263,$A18,Index!$I$5:$I$263,E$14) -> 1 | F18: =COUNTIFS(Index!$B$5:$B$263,$A18,Index!$I$5:$I$263,F$14) -> 1 | G18: =COUNTIFS(Index!$B$5:$B$263,$A18,Index!$I$5:$I$263,G$14) -> 4 | H18: =SUM(B18:G18) -> 8
A19: Report 5 · Carbon | B19: =COUNTIFS(Index!$B$5:$B$263,$A19,Index!$I$5:$I$263,B$14) -> 0 | C19: =COUNTIFS(Index!$B$5:$B$263,$A19,Index!$I$5:$I$263,C$14) -> 2 | D19: =COUNTIFS(Index!$B$5:$B$263,$A19,Index!$I$5:$I$263,D$14) -> 4 | E19: =COUNTIFS(Index!$B$5:$B$263,$A19,Index!$I$5:$I$263,E$14) -> 0 | F19: =COUNTIFS(Index!$B$5:$B$263,$A19,Index!$I$5:$I$263,F$14) -> 1 | G19: =COUNTIFS(Index!$B$5:$B$263,$A19,Index!$I$5:$I$263,G$14) -> 1 | H19: =SUM(B19:G19) -> 8
A20: Report 6 · Water impact | B20: =COUNTIFS(Index!$B$5:$B$263,$A20,Index!$I$5:$I$263,B$14) -> 0 | C20: =COUNTIFS(Index!$B$5:$B$263,$A20,Index!$I$5:$I$263,C$14) -> 5 | D20: =COUNTIFS(Index!$B$5:$B$263,$A20,Index!$I$5:$I$263,D$14) -> 3 | E20: =COUNTIFS(Index!$B$5:$B$263,$A20,Index!$I$5:$I$263,E$14) -> 1 | F20: =COUNTIFS(Index!$B$5:$B$263,$A20,Index!$I$5:$I$263,F$14) -> 5 | G20: =COUNTIFS(Index!$B$5:$B$263,$A20,Index!$I$5:$I$263,G$14) -> 8 | H20: =SUM(B20:G20) -> 22
A21: Report 7 · Unit economics | B21: =COUNTIFS(Index!$B$5:$B$263,$A21,Index!$I$5:$I$263,B$14) -> 0 | C21: =COUNTIFS(Index!$B$5:$B$263,$A21,Index!$I$5:$I$263,C$14) -> 6 | D21: =COUNTIFS(Index!$B$5:$B$263,$A21,Index!$I$5:$I$263,D$14) -> 3 | E21: =COUNTIFS(Index!$B$5:$B$263,$A21,Index!$I$5:$I$263,E$14) -> 1 | F21: =COUNTIFS(Index!$B$5:$B$263,$A21,Index!$I$5:$I$263,F$14) -> 0 | G21: =COUNTIFS(Index!$B$5:$B$263,$A21,Index!$I$5:$I$263,G$14) -> 14 | H21: =SUM(B21:G21) -> 24
A22: Report 8 · Green data centres | B22: =COUNTIFS(Index!$B$5:$B$263,$A22,Index!$I$5:$I$263,B$14) -> 0 | C22: =COUNTIFS(Index!$B$5:$B$263,$A22,Index!$I$5:$I$263,C$14) -> 5 | D22: =COUNTIFS(Index!$B$5:$B$263,$A22,Index!$I$5:$I$263,D$14) -> 1 | E22: =COUNTIFS(Index!$B$5:$B$263,$A22,Index!$I$5:$I$263,E$14) -> 2 | F22: =COUNTIFS(Index!$B$5:$B$263,$A22,Index!$I$5:$I$263,F$14) -> 3 | G22: =COUNTIFS(Index!$B$5:$B$263,$A22,Index!$I$5:$I$263,G$14) -> 1 | H22: =SUM(B22:G22) -> 12
A23: Report 9 · State policies | B23: =COUNTIFS(Index!$B$5:$B$263,$A23,Index!$I$5:$I$263,B$14) -> 0 | C23: =COUNTIFS(Index!$B$5:$B$263,$A23,Index!$I$5:$I$263,C$14) -> 3 | D23: =COUNTIFS(Index!$B$5:$B$263,$A23,Index!$I$5:$I$263,D$14) -> 0 | E23: =COUNTIFS(Index!$B$5:$B$263,$A23,Index!$I$5:$I$263,E$14) -> 0 | F23: =COUNTIFS(Index!$B$5:$B$263,$A23,Index!$I$5:$I$263,F$14) -> 1 | G23: =COUNTIFS(Index!$B$5:$B$263,$A23,Index!$I$5:$I$263,G$14) -> 0 | H23: =SUM(B23:G23) -> 4
A24: Report 10 · Where to build | B24: =COUNTIFS(Index!$B$5:$B$263,$A24,Index!$I$5:$I$263,B$14) -> 0 | C24: =COUNTIFS(Index!$B$5:$B$263,$A24,Index!$I$5:$I$263,C$14) -> 1 | D24: =COUNTIFS(Index!$B$5:$B$263,$A24,Index!$I$5:$I$263,D$14) -> 16 | E24: =COUNTIFS(Index!$B$5:$B$263,$A24,Index!$I$5:$I$263,E$14) -> 0 | F24: =COUNTIFS(Index!$B$5:$B$263,$A24,Index!$I$5:$I$263,F$14) -> 1 | G24: =COUNTIFS(Index!$B$5:$B$263,$A24,Index!$I$5:$I$263,G$14) -> 4 | H24: =SUM(B24:G24) -> 22
A25: Report 11 · Forecast to 2035 | B25: =COUNTIFS(Index!$B$5:$B$263,$A25,Index!$I$5:$I$263,B$14) -> 0 | C25: =COUNTIFS(Index!$B$5:$B$263,$A25,Index!$I$5:$I$263,C$14) -> 5 | D25: =COUNTIFS(Index!$B$5:$B$263,$A25,Index!$I$5:$I$263,D$14) -> 3 | E25: =COUNTIFS(Index!$B$5:$B$263,$A25,Index!$I$5:$I$263,E$14) -> 5 | F25: =COUNTIFS(Index!$B$5:$B$263,$A25,Index!$I$5:$I$263,F$14) -> 1 | G25: =COUNTIFS(Index!$B$5:$B$263,$A25,Index!$I$5:$I$263,G$14) -> 14 | H25: =SUM(B25:G25) -> 28
A26: Report 12 · Water and energy | B26: =COUNTIFS(Index!$B$5:$B$263,$A26,Index!$I$5:$I$263,B$14) -> 4 | C26: =COUNTIFS(Index!$B$5:$B$263,$A26,Index!$I$5:$I$263,C$14) -> 0 | D26: =COUNTIFS(Index!$B$5:$B$263,$A26,Index!$I$5:$I$263,D$14) -> 6 | E26: =COUNTIFS(Index!$B$5:$B$263,$A26,Index!$I$5:$I$263,E$14) -> 5 | F26: =COUNTIFS(Index!$B$5:$B$263,$A26,Index!$I$5:$I$263,F$14) -> 1 | G26: =COUNTIFS(Index!$B$5:$B$263,$A26,Index!$I$5:$I$263,G$14) -> 12 | H26: =SUM(B26:G26) -> 28
... A29: Key numbers (all reports) | B29: =COUNTIFS(Index!$B$5:$B$263,$A29,Index!$I$5:$I$263,B$14) -> 0 | C29: =COUNTIFS(Index!$B$5:$B$263,$A29,Index!$I$5:$I$263,C$14) -> 0 | D29: =COUNTIFS(Index!$B$5:$B$263,$A29,Index!$I$5:$I$263,D$14) -> 1 | E29: =COUNTIFS(Index!$B$5:$B$263,$A29,Index!$I$5:$I$263,E$14) -> 0 | F29: =COUNTIFS(Index!$B$5:$B$263,$A29,Index!$I$5:$I$263,F$14) -> 0 | G29: =COUNTIFS(Index!$B$5:$B$263,$A29,Index!$I$5:$I$263,G$14) -> 0 | H29: =SUM(B29:G29) -> 1
A30: Total | B30: =SUM(B15:B29) -> 4 | C30: =SUM(C15:C29) -> 74 | D30: =SUM(D15:D29) -> 52 | E30: =SUM(E15:E29) -> 22 | F30: =SUM(F15:F29) -> 28 | G30: =SUM(G15:G29) -> 79 | H30: =SUM(H15:H29) -> 259
A32: Report → atlas chapter → what the atlas derives
A33: Report | B33: Atlas chapter and tools | C33: Main things the atlas derives from it
A34: Report 1 · Types | B34: Ch 1: type explorer, type finder, Tier clock, capacity-share and India-by-city charts | C34: Which type to build; downtime per Tier; India in global context
A35: Report 2 · AI vs conventional | B35: Ch 2: energy split chart, rack inspector, density chart, workload table, comparison tables | C35: Rack power consequences; AI vs conventional design differences
A36: Report 3 · Cooling | B36: Ch 3: cooling chain, warm-water explorer, cooling selector, heat-rejection and liquid tables; simulator PUE/WUE functions | C36: Cooling design per city and density; PUE and WUE inputs
A37: Report 4 · Bengaluru | B37: Ch 4: campus calculator, water comparisons, 1 GW scaling, 24-hour day | C37: Energy, MVA, water and share of Karnataka resources per campus
A38: Report 5 · Carbon | B38: Ch 5: TWh-seven-ways chart, Karnataka hourly curve, load-shift calculator, five-factor scorecard | C38: Carbon and water per TWh by source, time and place
A39: Report 6 · Water impact | B39: Ch 6: tower water balance, seasonal chart, scarcity footprint, impact scorecard, water you can picture | C39: Withdrawal vs consumption; scarcity-weighted impact; thresholds
A40: Report 7 · Unit economics | B40: Ch 7: build-cost chart, capex stacks, LCOD calculator, tornado, GPU-hour calculator; simulator costs | C40: Capex/MW, LCOD, break-even rent, GPU-hour cost, returns
A41: Report 8 · Green | B41: Ch 8: twelve dimensions, green upgrade calculator, abatement chart, PUE thresholds, maturity radar | C41: Payback and abatement cost of going green
A42: Report 9 · State policies | B42: Ch 9: policy table, India map, attractiveness index, validity and incentive charts; simulator incentives | C42: State ranking and incentive value
A43: Report 10 · Where to build | B43: Ch 10: ranking engine (filters, min–max, weights, Monte Carlo), map and city table; worked-example workbook | C43: City scores, tiers and stability by use case
A44: Report 11 · Forecast | B44: Ch 11: forecast engine (CAGR, S-curve, pipeline), electricity, carbon, cost, GPU, water and city outputs | C44: Capacity and impacts to 2035 with uncertainty band
A45: Report 12 · Water & energy | B45: Ch 12: power-vs-water chart, hourly day, 8,760-hour histogram, grid water, cost-vs-water, peaks, tower and site calculators | C45: Direct vs indirect water, peaks, landed power cost by procurement route

Sheet R1
A1: Report 1 · Types of data centre
A2: 7 tables. Source line under each title; "Note" gives the context sentence from the report.
A4: R1-T01 Data-centre types by ownership and business model
A5: Source: Report 1 (full research report) · 1. Types of Data Centre › 1.1 Deep analysis of the types: what exists, what dominates globally, and why
A6: Data basis: Mixed: sourced figures plus estimates
A7: Used in atlas: Ch 1 "Type explorer" cards (how it works, cost, strengths, users) and the Type finder rules.
A8: Used to derive: Which business model fits a project size and workload.
A9: Type | B9: How it works | C9: Typical scale / density | D9: Cost structure | E9: Advantages | F9: Disadvantages | G9: Typical users
A10: Enterprise / on-premises | B10: Organisation owns and runs its own facility (server room up to a corporate campus) | C10: Under 1 MW to about 20 MW; modal rack about 7.5 kW (Uptime 2025) | D10: All capex borne by the owner; opex for power, staff and maintenance; low utilisation is common | E10: Full control, data sovereignty, custom compliance | F10: Poor economies of scale, older and less efficient plant, hard to upgrade for AI density | G10: Banks, government, defence, large manufacturers, hospitals
A11: Retail colocation | B11: Operator leases racks, cages or suites with power, cooling and security; tenant brings servers | C11: Facilities of 5–50 MW; customers take 1 rack to under 1 MW | D11: Tenant pays monthly rent per rack/kW plus interconnection; operator carries building capex | E11: Converts capex to opex, carrier-neutral interconnection, fast deployment | F11: Higher per-kW price, less control, contract lock-in | G11: Enterprises, BFSI, network operators, SaaS firms
A12: Wholesale colocation / build-to-suit | B12: Operator leases whole halls or buildings, often to a single hyperscaler on long leases | C12: 10–100+ MW per building, campuses of hundreds of MW to GW | D12: Operator funds the build (often project-financed against an anchor lease); tenant often pays power at cost plus rent | E12: Speed to market for hyperscalers, bankable long-term cash flows | F12: Concentrated tenant risk, thin margins, power-procurement exposure | G12: AWS, Microsoft, Google, Meta, Oracle, AI labs, neoclouds
A13: Hyperscale (self-built) | B13: Cloud/internet giants design, own and operate their own campuses | C13: Single buildings of 30–100+ MW; campuses of 1 GW+; AI halls at 50–130+ kW/rack | D13: Huge capex funded from balance sheet; lowest unit cost thanks to scale | E13: Lowest cost per MW, custom hardware, best PUE (larger sites average about 1.44, per Uptime 2025) | F13: Very concentrated power and water demand, local opposition, long grid queues | G13: AWS, Microsoft, Google, Meta, Alibaba, Tencent, Oracle
A14: Managed services / cloud | B14: Provider runs the infrastructure and sells compute or storage "as a service" (IaaS/PaaS, managed hosting, GPU-as-a-Service) | C14: Sits on top of hyperscale or colocation capacity | D14: Customer pays per use; provider absorbs capex | E14: Elastic, no hardware ownership, fast access to GPUs | F14: Egress costs, vendor lock-in, data-residency questions | G14: Start-ups, digital natives, enterprises moving to hybrid
A15: Edge / micro | B15: Small facilities close to users or devices (telecom central offices, towers, factory floors, cities) | C15: 50 kW to about 5 MW; micro/containerised units at single-rack scale | D15: Low capex per site but high cost per kW; many sites to manage | E15: Low latency, data reduction, local resilience | F15: Hard to operate at scale, uneven demand, limited GPU density | G15: Telcos (5G/MEC), CDNs/OTT, retail, payments, industrial IoT
A18: R1-T02 Uptime Tiers: redundancy, availability and downtime
A19: Source: Report 1 (full research report) · 1. Types of Data Centre › 1.1 Deep analysis of the types: what exists, what dominates globally, and why
A20: Data basis: Source-derived (reported, not re-verified)
A21: Used in atlas: Ch 1 "What a Tier buys you" downtime clock.
A22: Used to derive: Downtime hours a year = (1 − availability) × 8,760 per Tier.
A23: Uptime Tier | B23: Redundancy | C23: Concurrently maintainable? | D23: Fault tolerant? | E23: Design-intent availability | F23: Approx. annual downtime | G23: Typical use
A24: Tier I – Basic capacity | B24: N, single path | C24: No | D24: No | E24: 99.671% | F24: ~28.8 hours | G24: Small business, dev/test
A25: Tier II – Redundant components | B25: N+1 components, single path | C25: No | D25: No | E25: 99.741% | F25: ~22 hours | G25: Non-critical enterprise
A26: Tier III – Concurrently maintainable | B26: N+1, multiple paths (one active) | C26: Yes | D26: No | E26: 99.982% | F26: ~1.6 hours | G26: Colocation baseline, cloud, BFSI production
A27: Tier IV – Fault tolerant | B27: 2N / 2(N+1), multiple active paths | C27: Yes | D27: Yes | E27: 99.995% | F27: ~26 minutes | G27: Trading, critical health, national systems
A30: R1-T03 Cooling approaches: density, efficiency and water
A31: Source: Report 1 (full research report) · 1. Types of Data Centre › 1.1 Deep analysis of the types: what exists, what dominates globally, and why
A32: Data basis: Mixed: sourced figures plus estimates
A33: Used in atlas: Ch 3 cooling comparison text; density limits used in the Rack inspector bands.
A34: Used to derive: Practical rack-density ceiling per cooling method.
A35: Cooling approach | B35: How it works | C35: Practical rack density | D35: Efficiency | E35: Water use | F35: Status
A36: Air (CRAC/CRAH, hot/cold aisle, economisers) | B36: Chilled or outside air moved through racks | C36: Up to about 15–20 kW/rack (SBI notes air nears its limits beyond about 15 kW) | D36: Fleet average PUE 1.54 (Uptime 2025); new sites about 1.48 | E36: High if evaporative towers are used; low with dry coolers | F36: Still most of the installed base: about 75% use perimeter air (Uptime 2025)
A37: Rear-door heat exchangers / hybrid | B37: Liquid-cooled coil on the rack door removes heat from the exhaust air | C37: About 20–50 kW | D37: Better than room air | E37: Moderate | F37: Most common "first step" into liquid
A38: Direct-to-chip (DLC) | B38: Cold plates on CPUs/GPUs; coolant loop to a CDU; residual air cooling | C38: 30–130+ kW | D38: PUE about 1.1–1.25 achievable | E38: Low with closed loops and dry coolers | F38: Becoming the standard for AI; about 22% of operators used direct liquid cooling in 2025 (Uptime)
A39: Single-phase immersion | B39: Servers submerged in a dielectric fluid | C39: 50–150+ kW | D39: Very low cooling overhead | E39: Very low | F39: Niche; suits edge, crypto and HPC
A40: Two-phase immersion | B40: Fluid boils at the chip and condenses | C40: 100–250+ kW | D40: Lowest overhead | E40: Very low | F40: Early stage; fluid cost and environmental concerns
A43: R1-T04 Global market share and installed capacity by type (2024–2026)
A44: Source: Report 1 (full research report) · 1. Types of Data Centre › 1.1 Deep analysis of the types: what exists, what dominates globally, and why
A45: Data basis: Source-derived (reported, not re-verified)
A46: Used in atlas: Ch 1 headline numbers and "Who owns the world's capacity" chart; Key numbers.
A47: Used to derive: Global growth and hyperscale share trend to set India in context.
...

Sheet R2
A1: Report 2 · AI vs conventional
A2: 9 tables. Source line under each title; "Note" gives the context sentence from the report.
A4: R2-T01 Electricity split by subsystem and facility class
A5: Source: Report 2 (full research report) · Section 1: Anatomy of Data Centre Consumption › 1.1 Electricity breakdown by subsystem
A6: Note: Typical percentage splits by facility class. These are the author's synthesis, derived from PUE ranges and the IEA component shares. They are indicative, not measured.
A7: Data basis: Illustrative / framework / author judgement
A8: Used in atlas: Ch 2 "Where the power goes, by facility class" chart.
A9: Used to derive: Overhead share of energy by facility class; PUE build-up.
A10: Subsystem | B10: Legacy/small enterprise (PUE about 1.8–2.0) | C10: Typical enterprise/colo (PUE about 1.5–1.6) | D10: Hyperscale cloud (PUE about 1.1–1.2) | E10: AI liquid-cooled (PUE about 1.1–1.3)
A11: IT load (servers, storage, network) | B11: 50–55% | C11: 62–67% | D11: 83–91% | E11: 77–90%
A12: Cooling (chillers, CRAH/CRAC, pumps, towers, fans) | B12: 30–40% | C12: 25–30% | D12: 5–10% | E12: 7–15% (CDUs, pumps, dry coolers, residual air)
A13: Power conversion and distribution losses (UPS, transformers, PDUs) | B13: 8–12% | C13: 6–8% | D13: 2–5% | E13: 3–6%
A14: Lighting and other (security, offices, humidification) | B14: 2–5% | C14: 1–3% | D14: about 1% | E14: about 1%
A17: R2-T02 Server power split: conventional CPU vs AI accelerated
A18: Source: Report 2 (full research report) · Section 1: Anatomy of Data Centre Consumption › 1.2 Inside the IT load: CPUs, GPUs, memory, storage and networking
A19: Note: Applying the IEA shares to IT load alone, a typical facility's IT power splits about 85% servers, about 7% storage and about 7% networking. Within a server, the split depends on the class:
A20: Data basis: Illustrative / framework / author judgement
A21: Used in atlas: Ch 2 text on IT-load anatomy (reference).
A22: Used to derive: Share of rack power going to accelerators.
A23: Component | B23: Conventional CPU server (indicative) | C23: AI accelerated server/rack
A24: CPUs | B24: about 40–55% of server power | C24: about 10–15% (host CPUs, e.g. Grace)
A25: GPUs/accelerators | B25: 0% (or a small inference card) | C25: about 60–75% (e.g. 72 × B200 at about 1.0–1.2 kW = about 72–86 kW of a 120 kW NVL72 rack)
A26: Memory (DRAM/HBM) | B26: about 15–25% | C26: HBM is counted in the GPU package; host DRAM is a few %
A27: Local storage (SSD/HDD) | B27: about 5–10% | C27: a few %
A28: Fans, PSU losses, NICs | B28: about 10–20% | C28: Switch trays (NVLink), NICs/DPUs and PSU losses about 10–15%; fans are minimal with liquid cooling
A31: R2-T03 Efficiency metrics: PUE, WUE, CUE and ERE
A32: Source: Report 2 (full research report) · Section 1: Anatomy of Data Centre Consumption › 1.3 Efficiency metrics: PUE, WUE, CUE and ERE
A33: Data basis: Source-derived (reported, not re-verified)
A34: Used in atlas: Ch 2 and Ch 8 metric definitions; Key numbers (PUE 1.54, Google 1.09, MeitY <1.35).
A35: Used to derive: PUE and WUE benchmarks for calculators.
A36: Metric | B36: Definition | C36: Benchmarks
A37: PUE (Power Usage Effectiveness) | B37: Total facility energy ÷ IT energy | C37: Uptime 2025 global weighted average 1.54 (1.58 in 2023, 1.56 in 2024). Facilities built in the last five years: 1.48. Sites over 20 MW: about 1.44. Many new high-latitude sites: 1.3 or better. Google fleet: 1.09 (2025). MeitY AI-cloud tenders in India require below 1.35.
A38: WUE (Water Usage Effectiveness) | B38: Site water (L) ÷ IT energy (kWh) | C38: Microsoft FY24: 0.30 L/kWh, down 39% from 0.49 in 2021. Microsoft's regional values range from about 1.52 (Arizona) to 0.02 (Singapore), as reported secondhand.
A39: CUE (Carbon Usage Effectiveness) | B39: kgCO₂e ÷ IT kWh | C39: Determined mainly by the grid mix and whether emissions are counted location-based or market-based
A40: ERE (Energy Reuse Effectiveness) | B40: (Total energy − reused energy) ÷ IT energy | C40: Can fall below 1.0 with district-heat export, which matters for liquid-cooled AI halls producing 40–60 °C return water
A43: R2-T04 Water per AI query: a contested range
A44: Source: Report 2 (full research report) · Section 1: Anatomy of Data Centre Consumption › 1.4 Water consumption: direct and indirect
A45: Note: Per-AI-query water: a contested range.
A46: Data basis: Source-derived (reported, not re-verified)
A47: Used in atlas: Ch 6 and Ch 12 "Water per AI prompt" charts.
...

Sheet R3
A1: Report 3 · Cooling
A2: 15 tables. Source line under each title; "Note" gives the context sentence from the report.
A4: R3-T01 Accelerator power trend per GPU
A5: Source: Report 3 (full research report) · 1. Fundamentals › 1.1 Why cooling is needed
A6: Note: Accelerator power trend (per GPU):
A7: Data basis: Mixed: sourced figures plus estimates
A8: Used in atlas: Ch 3 cooling chain and GPU power figures.
A9: Used to derive: Why air cooling stops working as GPUs pass ~1 kW.
A10: GPU | B10: Year | C10: Max TDP | D10: Cooling implication
A11: Nvidia H100 SXM | B11: 2022–23 | C11: 700 W | D11: Air-coolable (HGX); DLC optional
A12: Nvidia B200 | B12: 2024–25 | C12: 1,000 W (up to ~1,200 W in GB200 configurations) | D12: Air HGX options exist; GB200 NVL72 rack is liquid
A13: Nvidia B300 (Blackwell Ultra) | B13: H2 2025 | C13: 1,400 W (liquid bin); 1,100 W air bin | D13: GB300 NVL72 requires DLC; DGX B300 has an air-cooled 14.5 kW variant
A14: Nvidia Rubin (Vera Rubin NVL72/NVL144) | B14: H2 2026 | C14: ~1,800–2,300 W (industry estimates; not formally confirmed) | D14: 100% liquid; 45°C inlet water
A15: Rubin Ultra (Kyber NVL576) | B15: H2 2027 | C15: — | D15: ~600 kW per rack, 100% liquid, no fans, 800 VDC
A16: Leading GPUs (Dell'Oro projection) | B16: 2029 | C16: >4,000 W | D16: Two-phase or embedded cooling likely needed
A19: R3-T02 Heat transfer properties of cooling fluids
A20: Source: Report 3 (full research report) · 1. Fundamentals › 1.2 Heat transfer properties: why liquid wins
A21: Note: Heat removed is Q = ṁ·cp·ΔT. What matters is how much heat a given volume of fluid can carry per degree of temperature rise. The values below are standard engineering values at about 25°C.
A22: Data basis: Source-derived (reported, not re-verified)
A23: Used in atlas: Ch 3 "Why liquid wins" chart.
A24: Used to derive: Flow needed to move heat with air vs water.
A25: Fluid | B25: Specific heat (kJ/kg·K) | C25: Density (kg/m³) | D25: Volumetric heat capacity (kJ/m³·K) | E25: Relative to air | F25: Notes
A26: Air | B26: ~1.0 | C26: ~1.2 | D26: ~1.2 | E26: 1× | F26: Low thermal conductivity (~0.026 W/m·K)
A27: Water | B27: ~4.18 | C27: ~1,000 | D27: ~4,180 | E27: ~3,500× | F27: Conductivity ~0.6 W/m·K; conductive and corrosive, so loops must be sealed and treated
A28: PG25 (25% propylene glycol) | B28: ~3.9 | C28: ~1,020 | D28: ~4,000 | E28: ~3,300× | F28: Standard technology cooling system (TCS) fluid for cold plates; biocide and freeze protection
A29: Synthetic or hydrocarbon dielectric oil (single-phase immersion) | B29: ~1.9–2.3 | C29: ~800–850 | D29: ~1,600–1,900 | E29: ~1,400× | F29: Higher viscosity means slower convection
A30: Fluorocarbon or HFO dielectric (two-phase) | B30: ~1.1–1.3 | C30: ~1,400–1,700 | D30: ~1,700–2,000 (sensible) | E30: — | F30: Boiling absorbs latent heat (~90–140 kJ/kg); heat transfer coefficient 5–10× single-phase
A33: R3-T03 ASHRAE air-cooled classes (IT inlet air)
A34: Source: Report 3 (full research report) · 1. Fundamentals › 1.3 ASHRAE TC 9.9 thermal guidelines (5th edition, 2021)
A35: Note: Air-cooled classes (IT inlet air):
A36: Data basis: Source-derived (reported, not re-verified)
A37: Used in atlas: Ch 3 reference (ASHRAE classes).
A38: Used to derive: Allowable inlet temperatures; economiser hours.
A39: Class | B39: Recommended | C39: Allowable dry-bulb | D39: Typical use
A40: A1 | B40: 18–27°C | C40: 15–32°C | D40: Enterprise and mission-critical
A41: A2 | B41: 18–27°C | C41: 10–35°C | D41: Volume servers
A42: A3 | B42: 18–27°C | C42: 5–40°C | D42: Extended-range, chillerless designs
A43: A4 | B43: 18–27°C | C43: 5–45°C | D43: Extreme economisation
A44: H1 (high-density) | B44: 18–22°C | C44: 15–25°C | D44: Tightly integrated, high-power air-cooled systems that cannot meet A2
A47: R3-T04 ASHRAE liquid-cooling W classes
...

Sheet R4
A1: Report 4 · Bengaluru water and power
A2: 8 tables. Source line under each title; "Note" gives the context sentence from the report.
A4: R4-T01 Assumptions for the three Bengaluru cases
A5: Source: Report 4 (full research report) · 1. Assumptions
A6: Data basis: Proxy / estimate
A7: Used in atlas: Ch 4 campus calculator presets; simulator defaults.
A8: Used to derive: Input assumptions for the three Bengaluru cases.
A9: Parameter | B9: Case A: Colo/enterprise | C9: Case B: Hyperscale/cloud | D9: Case C: AI campus
A10: Design IT load | B10: 20 MW | C10: 50 MW | D10: 100 MW
A11: Cooling | B11: Water-cooled chillers + cooling towers (with water-side economiser) | C11: B1: chillers + cooling towers; B2: adiabatic/hybrid dry coolers | D11: DLC (~80% to liquid) + dry coolers with adiabatic assist
A12: Annual PUE (central / range) | B12: 1.45 / 1.30–1.60 | C12: 1.35 / 1.25–1.45 | D12: 1.20 / 1.15–1.25
A13: Average utilisation of design IT | B13: 70% / 60–85% | C13: 75% / 65–85% | D13: 80% / 70–90%
A14: Design-day PUE (for contract demand) | B14: 1.6 | C14: 1.5 | D14: 1.3
A15: On-site WUE (L/kWh IT) | B15: 1.8 / 1.5–2.0 | C15: B1: 1.6; B2: 0.4 | D15: Dry 0.05; adiabatic 0.2; (evaporative alt. 1.6)
A16: Staff on site | B16: ~150 | C16: ~300 | D16: ~300
A17: Grid water intensity | B17: 1.5 L/kWh (range 1.0–2.5) | C17: same | D17: same
A20: R4-T02 Power calculations by case
A21: Source: Report 4 (full research report) · 2. Power calculations
A22: Note: Contract demand (MVA) ≈ Design IT × design-day PUE ÷ power factor (0.95), plus ~3–5% for offices and losses
A23: Data basis: Calculated (model output)
A24: Used in atlas: Ch 4 calculator outputs (MU, MVA, homes, % of state demand); Key numbers (841 MU, 140 MVA).
A25: Used to derive: Energy, contract demand and share of Karnataka demand per case.
B26: Case A (20 MW) | C26: Case B (50 MW) | D26: Case C (100 MW)
A27: IT energy | B27: 20×0.70×8,760 = 122.6 GWh | C27: 50×0.75×8,760 = 328.5 GWh | D27: 100×0.80×8,760 = 700.8 GWh
A28: Facility energy (central) | B28: 122.6×1.45 = 177.8 MU | C28: 328.5×1.35 = 443.5 MU | D28: 700.8×1.20 = 841.0 MU
A29: Sensitivity range | B29: 136.7–238.3 MU | C29: 355.9–539.8 MU | D29: 705.2–985.5 MU
A30: Average draw | B30: 20.3 MW | C30: 50.6 MW | D30: 96.0 MW
A31: Design peak | B31: 32 MW | C31: 75 MW | D31: 130 MW
A32: Contract demand | B32: ~34–35 MVA | C32: ~80 MVA | D32: ~140 MVA
A33: Supply voltage (KERC norms) | B33: 110 kV | C33: 220 kV | D33: 220 kV, dedicated substation, dual feed
A34: Installed transformer capacity (2N) | B34: ~70 MVA | C34: ~160 MVA | D34: ~280 MVA
A35: Bengaluru household equivalent (1,800 kWh/yr) | B35: ~98,800 | C35: ~246,400 | D35: ~467,200
A36: Share of Karnataka energy (92,550 MU, FY25) | B36: 0.19% | C36: 0.48% | D36: 0.91%
A37: Share of BESCOM sales (~37,000 MU, est.) | B37: 0.48% | C37: 1.2% | D37: 2.3%
A38: Share of state household use (16,089 MU) | B38: 1.1% | C38: 2.8% | D38: 5.2%
... A40: Energy bill at HT-2a (Rs 6.70/kWh + Rs 365/kVA/month) | B40: ~Rs 134 cr/yr | C40: ~Rs 332 cr/yr | D40: ~Rs 625 cr/yr
A43: R4-T03 On-site water by case
A44: Source: Report 4 (full research report) · 3. Water calculations › 3.2 On-site water by case
A45: Note: Formula: annual on-site water (L) = IT energy (kWh) × WUE + staff × 45 L × 365 + landscaping. MLD = annual ML ÷ 365. Population equivalent = MLD × 10⁶ ÷ 135.
A46: Data basis: Calculated (model output)
...

Sheet R5
A1: Report 5 · Carbon
A2: 8 tables. Source line under each title; "Note" gives the context sentence from the report.
A4: R5-T01 Lifecycle carbon intensity by technology
A5: Source: Report 5 (full research report) · 1. SOURCE — What Generates the Electron › 1.1 Lifecycle carbon intensity by technology
A6: Data basis: Source-derived (reported, not re-verified)
A7: Used in atlas: Ch 5 "Lifecycle carbon by source" bars.
A8: Used to derive: Carbon of procurement options.
A9: Source | B9: IPCC AR5 lifecycle median (min–max), gCO₂e/kWh | C9: UNECE 2021 range, gCO₂e/kWh | D9: Direct (combustion) share | E9: India-specific note
A10: Coal (pulverised) | B10: 820 (740–910) | C10: 751 (IGCC, US) – 1,095 (PC, China) | D10: Direct 760 (670–870) | E10: Indian subcritical units on high-ash coal: about 0.9–1.1 tCO₂/MWh at the busbar; UNECE notes a plant-by-plant global study at about 1,130 g
A11: Oil | B11: ~720 (secondary compilations) | C11: — | D11: Mostly direct | E11: Negligible in Indian grid
A12: Gas CCGT | B12: 490 (410–650) | C12: 403–513 (92–220 with CCS) | D12: Direct 370 (350–490) | E12: Indian gas fleet runs at low PLF; mostly peaking/balancing
A13: Biomass (dedicated) | B13: 230 (130–420) | C13: — | D13: Biogenic accounting contested | E13: Bagasse co-gen in Karnataka/Maharashtra
A14: Solar PV (utility) | B14: 48 (18–180) | C14: 8–83 | D14: 0 direct | E14: Upstream manufacturing mostly on coal-heavy Chinese grid
A15: CSP | B15: 27 (AR5) | C15: 27–122 | D15: 0 | E15: Marginal in India
A16: Geothermal | B16: 38 (6–79) | C16: — | D16: Some CO₂ from geofluid | E16: Not deployed
A17: Hydropower | B17: 24 (1–2,200) | C17: 6–147 | D17: 0 | E17: Tropical reservoirs can emit large biogenic CH₄; upper tail is real for shallow, warm reservoirs
A18: Wind onshore / offshore | B18: 11 / 12 | C18: 7.8–16 / 12–23 | D18: 0 | E18: Karnataka and Tamil Nadu are major onshore wind states
A19: Nuclear | B19: 12 (3.7–110) | C19: 5.1–6.4 | D19: 0 | E19: NPCIL fleet incl. Kaiga (Karnataka)
A22: R5-T02 Water withdrawal vs consumption by generation source
A23: Source: Report 5 (full research report) · 1. SOURCE — What Generates the Electron › 1.2 Water: withdrawal vs consumption by source
A24: Note: Once-through cooling withdraws a great deal but consumes relatively little. Cooling towers withdraw less but evaporate more.
A25: Data basis: Mixed: sourced figures plus estimates
A26: Used in atlas: Ch 5 "Water consumed by source" bars; grid water in calculators.
A27: Used to derive: Indirect water per kWh by source.
A28: Technology / cooling | B28: Consumption, L/MWh (approx., NREL Macknick et al. 2012 medians, converted from gal/MWh) | C28: Withdrawal, L/MWh | D28: Comment
A29: Coal, cooling tower | B29: ~1,800–2,600 (US); 2,800–4,000+ actual in India | C29: ~2,500–4,000 (US); ~4,000 India | D29: NREL notes tower-cooled plants sit near the ~1,000 gal/MWh (~3,800 L) upper bound
A30: Coal, once-through | B30: ~400–1,000 | C30: 70,000–200,000 (CSE, India) | D30: High thermal-pollution and intake impacts
A31: Coal/gas, dry cooling | B31: ~0–450 (India dry-cooled coal: 450–650 L/MWh) | C31: Low | D31: Efficiency penalty (higher CO₂/MWh)
A32: Nuclear, cooling tower | B32: ~2,500–2,700 | C32: ~4,000–5,000 | D32: Lowest carbon, among highest water
A33: Nuclear, once-through / seawater | B33: ~1,000 (largely seawater) | C33: ~100,000–170,000 | D33: Coastal sites (Kudankulam, Tarapur) avoid freshwater stress
A34: Gas CCGT, cooling tower | B34: ~700–1,000 | C34: ~1,000 | D34: Only the steam cycle (about one-third of output) needs cooling
A35: Gas CCGT, dry | B35: ~10 | C35: ~10
A36: Solar PV | B36: ~20–100 (panel cleaning; higher in dusty Indian conditions) | C36: same | D36: Robotic dry cleaning cuts this further
A37: Wind | B37: ~0–5 | C37: ~0
A38: CSP (trough, wet tower) | B38: ~3,000–3,500 | C38: ~3,500 | D38: Wettest renewable
A39: Biopower (steam, tower) | B39: ~2,000 (operations; crop irrigation can add orders of magnitude) | C39: —
A40: Hydro (reservoir evaporation) | B40: ~13,000 (China avg) to ~245,000 (Mekonnen & Hoekstra 35-plant avg); global mean ~79,000 | C40: Not meaningful | D40: Highly contested (see below)
A43: R5-T03 Country grid carbon intensity
A44: Source: Report 5 (full research report) · 3. LOCATION — Which Grid, Which Margin, Which Basin › 3.1 Country grids (operational, annual average)
A45: Data basis: Mixed: sourced figures plus estimates
...

Sheet R6
A1: Report 6 · Water impact
A2: 22 tables. Source line under each title; "Note" gives the context sentence from the report.
A4: R6-T01 Withdrawal vs consumption: definitions by framework
A5: Source: Report 6 (full research report) · 1. How much water? › 1.1 Withdrawal vs consumption: definitions and why both matter
A6: Data basis: Source-derived (reported, not re-verified)
A7: Used in atlas: Ch 6 framing (reference).
A8: Used to derive: Separate withdrawal, consumption, discharge.
A9: Framework | B9: Withdrawal | C9: Consumption | D9: Other key terms
A10: USGS | B10: Water removed from ground or surface sources | C10: Water evaporated, transpired, incorporated into products or otherwise removed from the immediate water environment | D10: Return flow
A11: GRI 303 (2018) | B11: 303-3: all water drawn from all sources, split freshwater (≤1,000 mg/L TDS) and "other" | C11: 303-5: withdrawal − discharge (± storage change) | D11: 303-4 discharge by destination and treatment; all broken out for water-stressed areas
A12: ISO 14046 (2014) | B12: Water use | C12: Water not returned to the drainage basin (evaporated, integrated, transferred) | D12: Water scarcity footprint
A13: Water Footprint Network | B13: — | C13: Blue: surface or groundwater consumed. Green: soil rainwater. Grey: virtual dilution volume for pollutants | D13: —
A16: R6-T02 Cooling water by system
A17: Source: Report 6 (full research report) · 1. How much water? › 1.2 Cooling water
A18: Data basis: Mixed: sourced figures plus estimates
A19: Used in atlas: Ch 6 water balance and simulator WUE values.
A20: Used to derive: Site WUE by cooling system.
A21: System | B21: Mechanism | C21: Site water (L/kWh of IT energy) | D21: Notes
A22: Open cooling towers + water-cooled chillers | B22: Latent heat (about 2,400 kJ/kg → about 1.5 L per kWh of heat) | C22: 1.4–2.5 withdrawal; 1.1–1.8 consumption | D22: Bengaluru's moderate wet-bulb suits towers; lowest PUE
A23: Direct / indirect evaporative air handlers | B23: Evaporation into air | C23: 0.3–1.5 | D23: Seasonal
A24: Adiabatic hybrid dry coolers | B24: Dry coils; sprays above about 28–32°C | C24: 0.05–0.4 | D24: Low average, high peaks
A25: Air-cooled chillers / dry coolers | B25: Sensible heat only | C25: ≈0–0.05 | D25: PUE higher by about 0.1–0.2
A26: Closed-loop DLC + dry coolers | B26: Warm water (35–45°C) to cold plates | C26: 0.01–0.15 | D26: One-time fill about 1.5–3 L/kW (often 25% propylene glycol)
A27: Chilled-water make-up | B27: Closed-loop losses | C27: <0.01 | D27: Quality matters more than volume
A30: R6-T03 Non-cooling water uses (50 MW campus)
A31: Source: Report 6 (full research report) · 1. How much water? › 1.3 Non-cooling water
A32: Data basis: Proxy / estimate
A33: Used in atlas: Ch 6 water balance (non-cooling 14.6 ML/yr).
A34: Used to derive: Non-cooling water allowance.
A35: Use | B35: 50 MW campus magnitude | C35: Comment
A36: Domestic / staff (about 300 people at the 45 L per head per day office norm) | B36: ≈13.5 m³/day | C36: About 80% returns as sewage; on-site STP reuse
A37: Cleaning, housekeeping | B37: 3–10 m³/day | C37: —
A38: Humidification | B38: 0–20 m³/day, seasonal | C38: Dry months (January–March, relative humidity 25–40%) need humidification; the monsoon needs dehumidification, which yields recoverable condensate
A39: Landscaping | B39: 5–20 m³/day | C39: Should use STP or rainwater
A40: Fire suppression | B40: Hundreds of m³ stored; 1–5 m³/week testing | C40: Storage, not consumption
A41: Diesel generator cooling | B41: Closed radiator loops; negligible | C41: —
A42: RO reject | B42: 20–35% of RO feed | C42: Raises withdrawal and discharge, not consumption
A43: Construction | B43: Tens of thousands of m³ over 18–36 months (estimate) | C43: Meta reports construction water separately; Yotta's Greater Noida site had a 50 KLD STP-water connection for construction (DTE)
A46: R6-T04 Freshwater vs recycled water sources (Bengaluru)
A47: Source: Report 6 (full research report) · 1. How much water? › 1.4 Freshwater vs recycled water
...

Sheet R7
A1: Report 7 · Unit economics
A2: 24 tables. Source line under each title; "Note" gives the context sentence from the report.
A4: R7-T01 Construction cost index by market (Turner & Townsend)
A5: Source: Report 7 (full research report) · 1. CAPEX (₹) › 1.1 Global and Indian benchmarks
A6: Note: Turner & Townsend Data Centre Construction Cost Index 2025–26 (52 markets, traditional air-cooled cloud data centre, US$ per watt; construction only):
A7: Data basis: Source-derived (reported, not re-verified)
A8: Used in atlas: Ch 7 "Build cost around the world" chart; Key numbers.
A9: Used to derive: Mumbai cost advantage; forecast base cost.
A10: Market | B10: US$/W | C10: ₹ crore/MW (at ₹90/$) | D10: Comment
A11: Tokyo | B11: 15.2 | C11: 137 | D11: Most expensive
A12: Singapore | B12: 14.5 | C12: 131 | D12: 2nd
A13: Zurich | B13: 14.2 | C13: 128 | D13: 3rd
A14: Silicon Valley | B14: 13.3 | C14: 120 | D14: Largest US premium
A15: New Jersey | B15: 12.9 | C15: 116
A16: Oslo | B16: 12.4 | C16: 112 | D16: 7th
A17: London | B17: 12 | C17: 108
A18: Frankfurt | B18: 11.6 | C18: 104
A19: Atlanta | B19: 9.9 | C19: 89
A20: Phoenix / Columbus | B20: 9.8 | C20: 88
A21: Charlotte | B21: 9.5 | C21: 86
A22: Mumbai | B22: 6.64 | C22: 60 | D22: 51st of 52
A25: R7-T02 Land prices in Indian data-centre hubs
A26: Source: Report 7 (full research report) · 1. CAPEX (₹) › 1.2 Land and buildings
A27: Note: Land prices per acre in Indian data centre hubs. Transaction-based figures are labelled. The rest are estimates or come from low-quality sources.
A28: Data basis: Mixed: sourced figures plus estimates
A29: Used in atlas: Ch 7 "Land and power" table; simulator land prices.
A30: Used to derive: Land share of capex by hub.
A31: Hub | B31: ₹ crore/acre | C31: Evidence
A32: Navi Mumbai (TTC MIDC, Airoli, Mahape, Ghansoli) | B32: 15–40 greenfield; up to ~80 for in-fill with structures | C32: STT GDC paid ₹282 crore for 14,093 m² (~3.5 acres) with an existing 6,828 m² building (May 2026), ≈₹81 crore/acre. Brookfield paid ₹600 crore for 30 acres in Ghansoli (2021), ≈₹20 crore/acre.
A33: Thane / Palava (MMR periphery) | B33: 12–35 | C33: AWS: ~40–45 acres at Palava for ₹500–600 crore (≈₹12–14 crore/acre). Amazon: 54 acres in Thane for ₹1,870 crore (≈₹35 crore/acre).
A34: Chennai (Ambattur, Oragadam, Siruseri) | B34: 8–15 Ambattur; 3–8 Oragadam (estimate) | C34: A secondary blog source gives ₹8–15 crore/acre; treat as indicative.
A35: Hyderabad | B35: 2–6 | C35: Microsoft bought 48 acres for ₹267 crore (2024), ≈₹5.6 crore/acre.
A36: Noida / Greater Noida | B36: 3–10 (estimate, not verified) | C36: Authority allotment rates vary; check YEIDA and GNIDA schedules.
A37: Bengaluru Whitefield | B37: 10–25 (estimate, not verified)
A38: Bengaluru Devanahalli / Hoskote | B38: 4–10 (estimate, not verified)
A39: Pune (Hinjewadi, Chakan, Talegaon) | B39: 5–15 (estimate, not verified)
A42: R7-T03 Servers, storage and GPU prices
A43: Source: Report 7 (full research report) · 1. CAPEX (₹) › 1.3 Servers, storage and GPUs (IT capex)
A44: Data basis: Mixed: sourced figures plus estimates
A45: Used in atlas: Ch 7 GPU calculator (HGX prices); simulator GPU capex.
...

Sheet R8
A1: Report 8 · Green data centres
A2: 12 tables. Source line under each title; "Note" gives the context sentence from the report.
A4: R8-T01 Twelve dimensions of a green data centre
A5: Source: Report 8 (full research report) · 1. What is a "green data centre"? › 1.2 The twelve dimensions
A6: Data basis: Illustrative / framework / author judgement
A7: Used in atlas: Ch 8 "Twelve dimensions" grid.
A8: Used to derive: Definition of green for India.
A9: # | B9: Dimension | C9: Core metric(s) | D9: What "green" looks like (India-tailored) | E9: Why it matters
A10: 1 | B10: Energy efficiency | C10: PUE (ISO/IEC 30134-2) | D10: ≤1.30 annualised (air); ≤1.20 (liquid-cooled AI) | E10: Overhead energy is pure waste
A11: 2 | B11: Carbon-free energy | C11: REF, hourly CFE score, CUE | D11: ≥70–80% hourly-matched CFE; CUE ≤0.3 kgCO₂/IT-kWh | E11: India's grid factor 0.710 tCO₂/MWh makes power the dominant footprint
A12: 3 | B12: Water | C12: WUE (site), source WUE | D12: ≤0.2 L/kWh freshwater; treated wastewater for any evaporative trim | E12: Bengaluru water stress
A13: 4 | B13: Embodied carbon (building) | C13: kgCO₂e/m² or /MW (EN 15978-style LCA) | D13: 30–40% below baseline via low-clinker concrete, recycled steel, hybrid timber | E13: Grows in share as grids decarbonise
A14: 5 | B14: IT hardware Scope 3 | C14: kgCO₂e per server/GPU, lifecycle | D14: Supplier EPDs/PCFs; extended refresh cycles | E14: Now the largest share for hyperscalers
A15: 6 | B15: Circularity | C15: % IT assets reused/refurbished; e-waste diversion | D15: ≥90% assets reused or recycled through authorised E-Waste (Management) Rules 2022 channels | E15: Avoids manufacturing emissions and hazardous waste
A16: 7 | B16: Heat reuse | C16: ERF (ISO/IEC 30134-6), ERE | D16: "Heat-reuse ready" design; absorption cooling or process heat where offtake exists | E16: Turns waste into a product
A17: 8 | B17: Refrigerants | C17: GWP of charge, leakage rate | D17: Low-GWP (HFO, natural refrigerants); chiller-less where possible | E17: HFC leakage is a hidden Scope 1 source
A18: 9 | B18: Land and biodiversity | C18: Footprint, green cover, heat-island | D18: Brownfield/industrial-park siting; native landscaping | E18: Social licence, local heat
A19: 10 | B19: Backup power | C19: Diesel litres/yr, run-hours | D19: HVO-ready gensets, BESS for short events, fuel cells long term | E19: Diesel is local pollution and Scope 1
A20: 11 | B20: Grid-friendliness | C20: Demand response, flexibility MW | D20: BESS/UPS grid services; schedulable AI training | E20: Helps integrate renewables
A21: 12 | B21: Social licence | C21: Disclosure, local water/power impact, jobs | D21: Public site-level dashboards; community water commitments | E21: Without it, moratoria follow (Amsterdam, Dublin, Singapore 2019)
A24: R8-T02 Green vs greenwashing: a quick test
A25: Source: Report 8 (full research report) · 1. What is a "green data centre"? › 1.3 Green vs greenwashing: a quick test
A26: Data basis: Illustrative / framework / author judgement
A27: Used in atlas: Ch 8 "Spotting greenwashing" table.
A28: Used to derive: Credibility test for claims.
A29: Claim | B29: Credible if… | C29: Greenwashing red flag
A30: "100% renewable" | B30: Hourly or at least monthly matching, same grid region, additional (new) capacity, location-based Scope 2 also disclosed | C30: Annual matching with unbundled RECs/I-RECs from old hydro elsewhere
A31: "Carbon neutral" | B31: Deep reductions first; removals (not avoidance offsets) for residuals | C31: Cheap avoidance offsets netted against growing emissions
A32: "PUE 1.2" | B32: Annualised, measured at the utility meter boundary (ISO/IEC 30134-2 Category 2/3), at real load | C32: Design PUE at 100% load, or a single cool-season month
A33: "Water positive" | B33: Site-level WUE disclosed; replenishment in the *same* basin | C33: Global replenishment credits while a Bengaluru site draws borewells
A34: "Green certified" | B34: Operational certification with measured data | C34: Design-stage label only, never re-verified
A37: R8-T03 Core green metrics and formulas
A38: Source: Report 8 (full research report) · 2. Metrics and standards › 2.1 Core metrics and formulas
A39: Data basis: Source-derived (reported, not re-verified)
A40: Used in atlas: Ch 8 metric definitions (reference).
A41: Used to derive: CUE, ERF, CFE formulas.
A42: Metric | B42: Formula | C42: Standard | D42: Notes
A43: PUE | B43: Total facility energy ÷ IT equipment energy | C43: ISO/IEC 30134-2 (The Green Grid, 2007) | D43: Ideal 1.0; global weighted average 1.54 (Uptime 2025)
A44: WUE | B44: Annual site water (L) ÷ IT energy (kWh) | C44: ISO/IEC 30134-9 | D44: Karnataka policy uses this definition; the EU uses freshwater input
A45: CUE | B45: Total CO₂ from facility energy ÷ IT energy = grid EF × PUE (for grid-only supply) | C45: ISO/IEC 30134-8 | D45: Bengaluru grid-only at PUE 1.5: 0.710 × 1.5 = 1.07 kgCO₂/IT-kWh
...

Sheet R9
A1: Report 9 · State policies
A2: 4 tables. Source line under each title; "Note" gives the context sentence from the report.
A4: R9-T01 Central framework instruments
A5: Source: Report 9 (full research report) · Part A — Central Framework
A6: Data basis: Source-derived (reported, not re-verified)
A7: Used in atlas: Ch 9 "The central framework" table.
A8: Used to derive: National levers vs state levers.
A9: Instrument | B9: Status (Oct 2026) | C9: What it does / implication
A10: Draft National Data Centre Policy (MeitY) | B10: Released 5 Nov 2020 for comments (deadline extended to 30 Nov 2020); never notified. MeitY has resumed industry consultations; one market-research release describes a "finalised draft" with up to 20-year conditional tax exemptions, but this is unverified. | C10: Proposed four Data Centre Economic Zones (DCEZs), single-window clearance, infrastructure status, and support for indigenous servers, storage, networking and cooling. Lacked enforceable mandates. Treat "imminent" claims sceptically: it has been pending for nearly six years.
A11: Infrastructure status | B11: In the Harmonised Master List of Infrastructure sub-sectors since 11 Oct 2022 | C11: Applies to data centres of at least 5 MW IT load. Eases long-tenor bank and ECB financing. The Finance Act 2026 tax-holiday definition does not use the 5 MW threshold, so a facility can qualify under one and not the other.
A12: Union Budget 2026–27 (1 Feb 2026) | B12: Enacted in the Finance Act; subordinate notifications on qualifying criteria still pending (Norton Rose Fulbright) | C12: Tax holiday until 31 March 2047 for foreign companies that provide cloud services globally using India-based data-centre services. Indian customers must be served through an Indian reseller. A 15% cost-plus safe harbour applies to related Indian data-centre service providers, and IT services generally move to a 15.5% safe harbour. This is the most important central incentive, but it benefits foreign cloud firms and Indian colocation operators indirectly and has no green conditions.
A13: DPDP Act 2023 / DPDP Rules 2025 | B13: Rules notified 14 Nov 2025 | C13: "Soft localisation": cross-border transfers are allowed unless the government blacklists a country. Demand for local hosting comes more from sector rules — RBI payment-data localisation (all payment data stored in India) and the SEBI Cloud Framework 2023 (data and logs on Indian servers) — than from the DPDP regime itself.
A14: MeitY cloud empanelment (GI Cloud / MeghRaj) | B14: Ongoing | C14: Government workloads must use MeitY-empanelled cloud service providers hosted in audited Indian data centres. This creates steady sovereign demand, especially for Tier III facilities. *(Not re-verified in this research.)*
A15: IndiaAI Mission | B15: Ongoing | C15: Subsidised GPU compute procured from private data-centre operators. It shapes demand for high-density, liquid-cooled capacity. *(Not re-verified in this research.)*
A16: Green Energy Open Access Rules 2022 (MoP) | B16: In force | C16: Lowered the open-access threshold to 100 kW and capped additional surcharges, enabling corporate renewable procurement. CEEW stakeholders still name high cross-subsidy surcharge (CSS) and additional surcharge, inconsistent banking rules and sudden withdrawal of waivers as the main barriers.
A17: ISTS charges waiver | B17: Being phased down for projects commissioned after mid-2025 *(general knowledge, not re-verified)* | C17: Makes inter-state renewable PPAs dearer over time, so state-level wheeling and banking concessions matter more.
A18: TRAI recommendations on data centres, CDNs and interconnect exchanges | B18: Issued Nov 2022 (often cited as 2023); not implemented by statute | C18: Recommended a legal framework, a single-window system, a data-centre-specific building-code category and incentives. Industry still asks for a National Building Code category for data centres.
A19: CEA/MoP draft guidance on power for data centres | B19: *Not verified in this research.* | C19: Flagged as a gap: no publicly verified central power-supply standard for data centres was found.
A20: SEZ route | B20: Available | C20: Data centres can be set up in IT/ITeS SEZs, for example the 2.7 ha SEZ portion of RackBank's Nava Raipur park. The Budget's IFSC tax-holiday extension (20 of 25 years) helps GIFT City-type locations.
A21: GST | B21: Standard rate on data-centre/colocation services *(not re-verified)* | C21: States compete through SGST reimbursement, which is the reason "net SGST reimbursement" appears in almost every policy.
A24: R9-T02 Telangana named projects
A25: Source: Report 9 (full research report) · Part B — State-by-State Deep Dive › 4. Telangana — the inland AI challenger
A26: Note: Implementation: According to Knight Frank India's "India Data Centre Market Update 2025", Hyderabad live capacity rose from 60.9 MW (2022) to 151.4 MW (end-2025), with a 1.9 GW committed pipeline, second only to Mumbai. AWS, which runs three availability zones in the city, holds 46% of live IT capacity. Named projects:
A27: Data basis: Source-derived (reported, not re-verified)
A28: Used in atlas: Ch 9 Telangana detail; Ch 10 demand context.
A29: Used to derive: Hyderabad pipeline evidence.
A30: Project | B30: Size / investment | C30: Details
A31: AWS | B31: ₹60,000 crore | C31: Foundation stone July 2026
A32: TCS HyperVault | B32: Up to 1 GW, up to ₹70,000 crore | C32: 264 acres, Future City; announced September 2026
A33: CtrlS | B33: 400 MW, ₹10,000 crore | C33: MoU 2025
A34: NTT DATA–Neysa | B34: 400 MW, ₹10,500 crore | C34: MoU 2025
A35: Microsoft India South Central region | B35: — | C35: Launched 2026
A38: R9-T03 Master comparison of state policies
A39: Source: Report 9 (full research report) · Part C — Master Comparison Table
A40: Data basis: Source-derived (reported, not re-verified)
A41: Used in atlas: Ch 9 policy register table, map detail panel and validity chart; simulator incentives.
