Workbook

Sheet README
A1: India data-centre site ranking: worked example (Mysuru) with live formulas
A3: What this is: the exact model behind Chapter 10 of the India Data Centre Atlas, laid out in cells so every number can be traced.
A5: Sheets
A6: Settings: hub coordinates, hard-filter limits, weights (blue = inputs you can change).
A7: Model: all 50 candidate cities. Columns run left to right through Steps A, latency, B, C and tiering.
A8: Walkthrough: pick any city in cell B2 (default Mysuru) and read its calculation line by line.
A9: MonteCarlo: Step E results from the 1,000-run seeded simulation (values, not formulas; see note on that sheet).
A11: Colour code: blue text = input; black = formula; yellow = the site's headline results.
A12: Evidence: factor scores, substation distances and seismic zones are Report 10 rubric values and estimates; latency is computed from coordinates.
A13: Excel 2019 or later (or LibreOffice) is needed for MINIFS / MAXIFS.

Sheet Settings
A1: Settings and weights
A3: Hub | B3: Lat | C3: Lon
A4: Mumbai | B4: 19.076 | C4: 72.878
A5: Delhi | B5: 28.614 | C5: 77.209
A6: Chennai | B6: 13.083 | C6: 80.27
A7: Bengaluru | B7: 12.972 | C7: 77.594
A9: Earth radius R (km) | B9: 6371
A10: Latency factor (ms per km) | B10: 0.014 | C10: =2 × 1.4 route factor ÷ 200 km/ms -> #N/A
A12: Hard filters (Step A)
A13: Max distance to 220 kV+ substation (km) | B13: 25
A14: Exclude seismic zone V (1 = yes) | B14: 1
A15: Allow over-exploited groundwater with treated-water contract (1 = yes) | B15: 1
A16: Exclude very-high cyclone / flood sites (1 = yes) | B16: 0
A18: Weights (Step C)
B19: Power | C19: Connectivity | D19: Latency | E19: Water | F19: Climate | G19: Hazards | H19: Land | I19: Policy | J19: Demand & talent | K19: Sum
A20: Raw weight | B20: 25 | C20: 15 | D20: 10 | E20: 15 | F20: 5 | G20: 10 | H20: 5 | I20: 10 | J20: 5 | K20: =SUM(B20:J20) -> 100
A21: Normalised weight (÷ sum) | B21: =B20/SUM($B$20:$J$20) -> 0.25 | C21: =C20/SUM($B$20:$J$20) -> 0.15 | D21: =D20/SUM($B$20:$J$20) -> 0.1 | E21: =E20/SUM($B$20:$J$20) -> 0.15 | F21: =F20/SUM($B$20:$J$20) -> 0.05 | G21: =G20/SUM($B$20:$J$20) -> 0.1 | H21: =H20/SUM($B$20:$J$20) -> 0.05 | I21: =I20/SUM($B$20:$J$20) -> 0.1 | J21: =J20/SUM($B$20:$J$20) -> 0.05
A23: Presets to paste into row 20 (order as above)
A24: Balanced | B24: 25 | C24: 15 | D24: 10 | E24: 15 | F24: 5 | G24: 10 | H24: 5 | I24: 10 | J24: 5
A25: AI training campus | B25: 40 | C25: 5 | D25: 5 | E25: 15 | F25: 5 | G25: 10 | H25: 10 | I25: 7 | J25: 3
A26: Interconnection colo | B26: 15 | C26: 30 | D26: 20 | E26: 5 | F26: 0 | G26: 10 | H26: 2 | I26: 5 | J26: 13
A27: Sustainability-first | B27: 20 | C27: 5 | D27: 5 | E27: 30 | F27: 15 | G27: 10 | H27: 5 | I27: 5 | J27: 5
A29: Tier cut-offs
A30: Share of passing cities in Tier A | B30: 0.3
A31: Cumulative share in Tiers A+B | B31: 0.7

Sheet Model
A1: Model: Steps A to C for every candidate city
A2: Row 3 and 4 hold the min and max of each raw factor over the cities that pass the filters (Step B).
S3: Min | T3: =_xlfn.MINIFS(T$6:T$55,$S$6:$S$55,1) -> 3 | U3: =_xlfn.MINIFS(U$6:U$55,$S$6:$S$55,1) -> 2 | V3: =_xlfn.MINIFS(V$6:V$55,$S$6:$S$55,1) -> 9.7272974 | W3: =_xlfn.MINIFS(W$6:W$55,$S$6:$S$55,1) -> 1 | X3: =_xlfn.MINIFS(X$6:X$55,$S$6:$S$55,1) -> 1 | Y3: =_xlfn.MINIFS(Y$6:Y$55,$S$6:$S$55,1) -> 3 | Z3: =_xlfn.MINIFS(Z$6:Z$55,$S$6:$S$55,1) -> 1 | AA3: =_xlfn.MINIFS(AA$6:AA$55,$S$6:$S$55,1) -> 3 | AB3: =_xlfn.MINIFS(AB$6:AB$55,$S$6:$S$55,1) -> 1
S4: Max | T4: =_xlfn.MAXIFS(T$6:T$55,$S$6:$S$55,1) -> 9 | U4: =_xlfn.MAXIFS(U$6:U$55,$S$6:$S$55,1) -> 10 | V4: =_xlfn.MAXIFS(V$6:V$55,$S$6:$S$55,1) -> 20.566511 | W4: =_xlfn.MAXIFS(W$6:W$55,$S$6:$S$55,1) -> 7 | X4: =_xlfn.MAXIFS(X$6:X$55,$S$6:$S$55,1) -> 8 | Y4: =_xlfn.MAXIFS(Y$6:Y$55,$S$6:$S$55,1) -> 9 | Z4: =_xlfn.MAXIFS(Z$6:Z$55,$S$6:$S$55,1) -> 10 | AA4: =_xlfn.MAXIFS(AA$6:AA$55,$S$6:$S$55,1) -> 9 | AB4: =_xlfn.MAXIFS(AB$6:AB$55,$S$6:$S$55,1) -> 10
A5: id | B5: City | C5: State | D5: Lat | E5: Lon | F5: Seismic zone | G5: Nearest 220kV+ (km) | H5: Water cond. (1=yes) | I5: Flood/cyclone flag (1=yes) | J5: km to Mumbai | K5: km to Delhi | L5: km to Chennai | M5: km to Bengaluru | N5: ms to Mumbai | O5: ms to Delhi | P5: ms to Chennai | Q5: ms to Bengaluru | R5: Mean RTT (ms) | S5: Passes filters (1/0) | T5: Power | U5: Connectivity | V5: Latency (ms) | W5: Water | X5: Climate | Y5: Hazards | Z5: Land | AA5: Policy | AB5: Demand & talent | AC5: s·Power | AD5: s·Connectivity | AE5: s·Latency | AF5: s·Water | AG5: s·Climate | AH5: s·Hazards | AI5: s·Land | AJ5: s·Policy | AK5: s·Demand & talent | AL5: Score: weighted sum | AM5: Score: geometric | AN5: Rank (of passers) | AO5: Tier
A6: nmb | B6: Navi Mumbai | C6: Maharashtra | D6: 19.03 | E6: 73.03 | F6: 3 | G6: 10 | H6: 0 | I6: 0 | J6: =2*Settings!$B$9*ASIN(SQRT(SIN(RADIANS(Settings!$B$4-$D6)/2)^2+COS(RADIANS($D6))*COS(RADIANS(Settings!$B$4))*SIN(RADIANS(Settings!$C$4-$E6)/2)^2)) -> 16.774566 | K6: =2*Settings!$B$9*ASIN(SQRT(SIN(RADIANS(Settings!$B$5-$D6)/2)^2+COS(RADIANS($D6))*COS(RADIANS(Settings!$B$5))*SIN(RADIANS(Settings!$C$5-$E6)/2)^2)) -> 1147.05 | L6: =2*Settings!$B$9*ASIN(SQRT(SIN(RADIANS(Settings!$B$6-$D6)/2)^2+COS(RADIANS($D6))*COS(RADIANS(Settings!$B$6))*SIN(RADIANS(Settings!$C$6-$E6)/2)^2)) -> 1017.3896 | M6: =2*Settings!$B$9*ASIN(SQRT(SIN(RADIANS(Settings!$B$7-$D6)/2)^2+COS(RADIANS($D6))*COS(RADIANS(Settings!$B$7))*SIN(RADIANS(Settings!$C$7-$E6)/2)^2)) -> 831.5384 | N6: =J6*Settings!$B$10 -> 0.23484393 | O6: =K6*Settings!$B$10 -> 16.0587 | P6: =L6*Settings!$B$10 -> 14.243455 | Q6: =M6*Settings!$B$10 -> 11.641538 | R6: =AVERAGE(N6:Q6) -> 10.544634 | S6: =IF(AND(OR(Settings!$B$14=0,F6<5),G6<=Settings!$B$13,OR(H6=0,Settings!$B$15=1),OR(Settings!$B$16=0,I6=0)),1,0) -> 1 | T6: 4.5 | U6: 10 | V6: =R6 -> 10.544634 | W6: 7 | X6: 2 | Y6: 5 | Z6: 2 | AA6: 8 | AB6: 10 | AC6: =IF($S6=1,IF(T$4=T$3,5,10*(T6-T$3)/(T$4-T$3)),"") -> 2.5 | AD6: =IF($S6=1,IF(U$4=U$3,5,10*(U6-U$3)/(U$4-U$3)),"") -> 10 | AE6: =IF($S6=1,IF(V$4=V$3,5,10*(V$4-V6)/(V$4-V$3)),"") -> 9.2459447 | AF6: =IF($S6=1,IF(W$4=W$3,5,10*(W6-W$3)/(W$4-W$3)),"") -> 10 | AG6: =IF($S6=1,IF(X$4=X$3,5,10*(X6-X$3)/(X$4-X$3)),"") -> 1.4285714 | AH6: =IF($S6=1,IF(Y$4=Y$3,5,10*(Y6-Y$3)/(Y$4-Y$3)),"") -> 3.3333333 | AI6: =IF($S6=1,IF(Z$4=Z$3,5,10*(Z6-Z$3)/(Z$4-Z$3)),"") -> 1.1111111 | AJ6: =IF($S6=1,IF(AA$4=AA$3,5,10*(AA6-AA$3)/(AA$4-AA$3)),"") -> 8.3333333 | AK6: =IF($S6=1,IF(AB$4=AB$3,5,10*(AB6-AB$3)/(AB$4-AB$3)),"") -> 10 | AL6: =IF($S6=1,SUMPRODUCT(AC6:AK6,Settings!$B$21:$J$21),"") -> 6.3432453 | AM6: =IF($S6=1,EXP(Settings!$B$21*LN(MAX(AC6,0.5))+Settings!$C$21*LN(MAX(AD6,0.5))+Settings!$D$21*LN(MAX(AE6,0.5))+Settings!$E$21*LN(MAX(AF6,0.5))+Settings!$F$21*LN(MAX(AG6,0.5))+Settings!$G$21*LN(MAX(AH6,0.5))+Settings!$H$21*LN(MAX(AI6,0.5))+Settings!$I$21*LN(MAX(AJ6,0.5))+Settings!$J$21*LN(MAX(AK6,0.5))),"") -> 5.0174477 | AN6: =IF($S6=1,COUNTIFS($S$6:$S$55,1,$AL$6:$AL$55,">"&AL6)+1,"") -> 6 | AO6: =IF($S6=1,IF(AN6<=CEILING(SUM($S$6:$S$55)*Settings!$B$30,1),"A",IF(AN6<=CEILING(SUM($S$6:$S$55)*Settings!$B$31,1),"B","C")),"Excluded") -> A
A7: pun | B7: Pune | C7: Maharashtra | D7: 18.52 | E7: 73.86 | F7: 3 | G7: 15 | H7: 0 | I7: 0 | J7: =2*Settings!$B$9*ASIN(SQRT(SIN(RADIANS(Settings!$B$4-$D7)/2)^2+COS(RADIANS($D7))*COS(RADIANS(Settings!$B$4))*SIN(RADIANS(Settings!$C$4-$E7)/2)^2)) -> 120.44619 | K7: =2*Settings!$B$9*ASIN(SQRT(SIN(RADIANS(Settings!$B$5-$D7)/2)^2+COS(RADIANS($D7))*COS(RADIANS(Settings!$B$5))*SIN(RADIANS(Settings!$C$5-$E7)/2)^2)) -> 1172.9507 | L7: =2*Settings!$B$9*ASIN(SQRT(SIN(RADIANS(Settings!$B$6-$D7)/2)^2+COS(RADIANS($D7))*COS(RADIANS(Settings!$B$6))*SIN(RADIANS(Settings!$C$6-$E7)/2)^2)) -> 913.99258 | M7: =2*Settings!$B$9*ASIN(SQRT(SIN(RADIANS(Settings!$B$7-$D7)/2)^2+COS(RADIANS($D7))*COS(RADIANS(Settings!$B$7))*SIN(RADIANS(Settings!$C$7-$E7)/2)^2)) -> 734.92551 | N7: =J7*Settings!$B$10 -> 1.6862466 | O7: =K7*Settings!$B$10 -> 16.42131 | P7: =L7*Settings!$B$10 -> 12.795896 | Q7: =M7*Settings!$B$10 -> 10.288957 | R7: =AVERAGE(N7:Q7) -> 10.298103 | S7: =IF(AND(OR(Settings!$B$14=0,F7<5),G7<=Settings!$B$13,OR(H7=0,Settings!$B$15=1),OR(Settings!$B$16=0,I7=0)),1,0) -> 1 | T7: 4 | U7: 7 | V7: =R7 -> 10.298103 | W7: 6 | X7: 5 | Y7: 7 | Z7: 5 | AA7: 8 | AB7: 8 | AC7: =IF($S7=1,IF(T$4=T$3,5,10*(T7-T$3)/(T$4-T$3)),"") -> 1.6666667 | AD7: =IF($S7=1,IF(U$4=U$3,5,10*(U7-U$3)/(U$4-U$3)),"") -> 6.25 | AE7: =IF($S7=1,IF(V$4=V$3,5,10*(V$4-V7)/(V$4-V$3)),"") -> 9.4733888 | AF7: =IF($S7=1,IF(W$4=W$3,5,10*(W7-W$3)/(W$4-W$3)),"") -> 8.3333333 | AG7: =IF($S7=1,IF(X$4=X$3,5,10*(X7-X$3)/(X$4-X$3)),"") -> 5.7142857 | AH7: =IF($S7=1,IF(Y$4=Y$3,5,10*(Y7-Y$3)/(Y$4-Y$3)),"") -> 6.6666667 | AI7: =IF($S7=1,IF(Z$4=Z$3,5,10*(Z7-Z$3)/(Z$4-Z$3)),"") -> 4.4444444 | AJ7: =IF($S7=1,IF(AA$4=AA$3,5,10*(AA7-AA$3)/(AA$4-AA$3)),"") -> 8.3333333 | AK7: =IF($S7=1,IF(AB$4=AB$3,5,10*(AB7-AB$3)/(AB$4-AB$3)),"") -> 7.7777778 | AL7: =IF($S7=1,SUMPRODUCT(AC7:AK7,Settings!$B$21:$J$21),"") -> 5.9483309 | AM7: =IF($S7=1,EXP(Settings!$B$21*LN(MAX(AC7,0.5))+Settings!$C$21*LN(MAX(AD7,0.5))+Settings!$D$21*LN(MAX(AE7,0.5))+Settings!$E$21*LN(MAX(AF7,0.5))+Settings!$F$21*LN(MAX(AG7,0.5))+Settings!$G$21*LN(MAX(AH7,0.5))+Settings!$H$21*LN(MAX(AI7,0.5))+Settings!$I$21*LN(MAX(AJ7,0.5))+Settings!$J$21*LN(MAX(AK7,0.5))),"") -> 5.0103958 | AN7: =IF($S7=1,COUNTIFS($S$6:$S$55,1,$AL$6:$AL$55,">"&AL7)+1,"") -> 17 | AO7: =IF($S7=1,IF(AN7<=CEILING(SUM($S$6:$S$55)*Settings!$B$30,1),"A",IF(AN7<=CEILING(SUM($S$6:$S$55)*Settings!$B$31,1),"B","C")),"Excluded") -> B
A8: ngp | B8: Nagpur | C8: Maharashtra | D8: 21.15 | E8: 79.09 | F8: 2 | G8: 8 | H8: 0 | I8: 0 | J8: =2*Settings!$B$9*ASIN(SQRT(SIN(RADIANS(Settings!$B$4-$D8)/2)^2+COS(RADIANS($D8))*COS(RADIANS(Settings!$B$4))*SIN(RADIANS(Settings!$C$4-$E8)/2)^2)) -> 688.31527 | K8: =2*Settings!$B$9*ASIN(SQRT(SIN(RADIANS(Settings!$B$5-$D8)/2)^2+COS(RADIANS($D8))*COS(RADIANS(Settings!$B$5))*SIN(RADIANS(Settings!$C$5-$E8)/2)^2)) -> 851.32237 | L8: =2*Settings!$B$9*ASIN(SQRT(SIN(RADIANS(Settings!$B$6-$D8)/2)^2+COS(RADIANS($D8))*COS(RADIANS(Settings!$B$6))*SIN(RADIANS(Settings!$C$6-$E8)/2)^2)) -> 905.71372 | M8: =2*Settings!$B$9*ASIN(SQRT(SIN(RADIANS(Settings!$B$7-$D8)/2)^2+COS(RADIANS($D8))*COS(RADIANS(Settings!$B$7))*SIN(RADIANS(Settings!$C$7-$E8)/2)^2)) -> 923.12278 | N8: =J8*Settings!$B$10 -> 9.6364138 | O8: =K8*Settings!$B$10 -> 11.918513 | P8: =L8*Settings!$B$10 -> 12.679992 | Q8: =M8*Settings!$B$10 -> 12.923719 | R8: =AVERAGE(N8:Q8) -> 11.789659 | S8: =IF(AND(OR(Settings!$B$14=0,F8<5),G8<=Settings!$B$13,OR(H8=0,Settings!$B$15=1),OR(Settings!$B$16=0,I8=0)),1,0) -> 1 | T8: 4 | U8: 5 | V8: =R8 -> 11.789659 | W8: 7 | X8: 5 | Y8: 9 | Z8: 8 | AA8: 8 | AB8: 4 | AC8: =IF($S8=1,IF(T$4=T$3,5,10*(T8-T$3)/(T$4-T$3)),"") -> 1.6666667 | AD8: =IF($S8=1,IF(U$4=U$3,5,10*(U8-U$3)/(U$4-U$3)),"") -> 3.75 | AE8: =IF($S8=1,IF(V$4=V$3,5,10*(V$4-V8)/(V$4-V$3)),"") -> 8.0973139 | AF8: =IF($S8=1,IF(W$4=W$3,5,10*(W8-W$3)/(W$4-W$3)),"") -> 10 | AG8: =IF($S8=1,IF(X$4=X$3,5,10*(X8-X$3)/(X$4-X$3)),"") -> 5.7142857 | AH8: =IF($S8=1,IF(Y$4=Y$3,5,10*(Y8-Y$3)/(Y$4-Y$3)),"") -> 10 | AI8: =IF($S8=1,IF(Z$4=Z$3,5,10*(Z8-Z$3)/(Z$4-Z$3)),"") -> 7.7777778 | AJ8: =IF($S8=1,IF(AA$4=AA$3,5,10*(AA8-AA$3)/(AA$4-AA$3)),"") -> 8.3333333 | AK8: =IF($S8=1,IF(AB$4=AB$3,5,10*(AB8-AB$3)/(AB$4-AB$3)),"") -> 3.3333333 | AL8: =IF($S8=1,SUMPRODUCT(AC8:AK8,Settings!$B$21:$J$21),"") -> 5.9635012 | AM8: =IF($S8=1,EXP(Settings!$B$21*LN(MAX(AC8,0.5))+Settings!$C$21*LN(MAX(AD8,0.5))+Settings!$D$21*LN(MAX(AE8,0.5))+Settings!$E$21*LN(MAX(AF8,0.5))+Settings!$F$21*LN(MAX(AG8,0.5))+Settings!$G$21*LN(MAX(AH8,0.5))+Settings!$H$21*LN(MAX(AI8,0.5))+Settings!$I$21*LN(MAX(AJ8,0.5))+Settings!$J$21*LN(MAX(AK8,0.5))),"") -> 4.819674 | AN8: =IF($S8=1,COUNTIFS($S$6:$S$55,1,$AL$6:$AL$55,">"&AL8)+1,"") -> 16 | AO8: =IF($S8=1,IF(AN8<=CEILING(SUM($S$6:$S$55)*Settings!$B$30,1),"A",IF(AN8<=CEILING(SUM($S$6:$S$55)*Settings!$B$31,1),"B","C")),"Excluded") -> B
A9: nsk | B9: Nashik | C9: Maharashtra | D9: 20 | E9: 73.79 | F9: 3 | G9: 15 | H9: 0 | I9: 0 | J9: =2*Settings!$B$9*ASIN(SQRT(SIN(RADIANS(Settings!$B$4-$D9)/2)^2+COS(RADIANS($D9))*COS(RADIANS(Settings!$B$4))*SIN(RADIANS(Settings!$C$4-$E9)/2)^2)) -> 140.32033 | K9: =2*Settings!$B$9*ASIN(SQRT(SIN(RADIANS(Settings!$B$5-$D9)/2)^2+COS(RADIANS($D9))*COS(RADIANS(Settings!$B$5))*SIN(RADIANS(Settings!$C$5-$E9)/2)^2)) -> 1018.3897 | L9: =2*Settings!$B$9*ASIN(SQRT(SIN(RADIANS(Settings!$B$6-$D9)/2)^2+COS(RADIANS($D9))*COS(RADIANS(Settings!$B$6))*SIN(RADIANS(Settings!$C$6-$E9)/2)^2)) -> 1033.3887 | M9: =2*Settings!$B$9*ASIN(SQRT(SIN(RADIANS(Settings!$B$7-$D9)/2)^2+COS(RADIANS($D9))*COS(RADIANS(Settings!$B$7))*SIN(RADIANS(Settings!$C$7-$E9)/2)^2)) -> 880.31277 | N9: =J9*Settings!$B$10 -> 1.9644846 | O9: =K9*Settings!$B$10 -> 14.257456 | P9: =L9*Settings!$B$10 -> 14.467442 | Q9: =M9*Settings!$B$10 -> 12.324379 | R9: =AVERAGE(N9:Q9) -> 10.75344 | S9: =IF(AND(OR(Settings!$B$14=0,F9<5),G9<=Settings!$B$13,OR(H9=0,Settings!$B$15=1),OR(Settings!$B$16=0,I9=0)),1,0) -> 1 | T9: 3 | U9: 5 | V9: =R9 -> 10.75344 | W9: 7 | X9: 6 | Y9: 7 | Z9: 7 | AA9: 8 | AB9: 3 | AC9: =IF($S9=1,IF(T$4=T$3,5,10*(T9-T$3)/(T$4-T$3)),"") -> 0 | AD9: =IF($S9=1,IF(U$4=U$3,5,10*(U9-U$3)/(U$4-U$3)),"") -> 3.75 | AE9: =IF($S9=1,IF(V$4=V$3,5,10*(V$4-V9)/(V$4-V$3)),"") -> 9.0533051 | AF9: =IF($S9=1,IF(W$4=W$3,5,10*(W9-W$3)/(W$4-W$3)),"") -> 10 | AG9: =IF($S9=1,IF(X$4=X$3,5,10*(X9-X$3)/(X$4-X$3)),"") -> 7.1428571 | AH9: =IF($S9=1,IF(Y$4=Y$3,5,10*(Y9-Y$3)/(Y$4-Y$3)),"") -> 6.6666667 | AI9: =IF($S9=1,IF(Z$4=Z$3,5,10*(Z9-Z$3)/(Z$4-Z$3)),"") -> 6.6666667 | AJ9: =IF($S9=1,IF(AA$4=AA$3,5,10*(AA9-AA$3)/(AA$4-AA$3)),"") -> 8.3333333 | AK9: =IF($S9=1,IF(AB$4=AB$3,5,10*(AB9-AB$3)/(AB$4-AB$3)),"") -> 2.2222222 | AL9: =IF($S9=1,SUMPRODUCT(AC9:AK9,Settings!$B$21:$J$21),"") -> 5.2694178 | AM9: =IF($S9=1,EXP(Settings!$B$21*LN(MAX(AC9,0.5))+Settings!$C$21*LN(MAX(AD9,0.5))+Settings!$D$21*LN(MAX(AE9,0.5))+Settings!$E$21*LN(MAX(AF9,0.5))+Settings!$F$21*LN(MAX(AG9,0.5))+Settings!$G$21*LN(MAX(AH9,0.5))+Settings!$H$21*LN(MAX(AI9,0.5))+Settings!$I$21*LN(MAX(AJ9,0.5))+Settings!$J$21*LN(MAX(AK9,0.5))),"") -> 3.4058778 | AN9: =IF($S9=1,COUNTIFS($S$6:$S$55,1,$AL$6:$AL$55,">"&AL9)+1,"") -> 25 | AO9: =IF($S9=1,IF(AN9<=CEILING(SUM($S$6:$S$55)*Settings!$B$30,1),"A",IF(AN9<=CEILING(SUM($S$6:$S$55)*Settings!$B$31,1),"B","C")),"Excluded") -> B
A10: hos | B10: Hosur | C10: Tamil Nadu | D10: 12.74 | E10: 77.83 | F10: 2 | G10: 10 | H10: 0 | I10: 0 | J10: =2*Settings!$B$9*ASIN(SQRT(SIN(RADIANS(Settings!$B$4-$D10)/2)^2+COS(RADIANS($D10))*COS(RADIANS(Settings!$B$4))*SIN(RADIANS(Settings!$C$4-$E10)/2)^2)) -> 881.14585 | K10: =2*Settings!$B$9*ASIN(SQRT(SIN(RADIANS(Settings!$B$5-$D10)/2)^2+COS(RADIANS($D10))*COS(RADIANS(Settings!$B$5))*SIN(RADIANS(Settings!$C$5-$E10)/2)^2)) -> 1766.2793 | L10: =2*Settings!$B$9*ASIN(SQRT(SIN(RADIANS(Settings!$B$6-$D10)/2)^2+COS(RADIANS($D10))*COS(RADIANS(Settings!$B$6))*SIN(RADIANS(Settings!$C$6-$E10)/2)^2)) -> 267.19045 | M10: =2*Settings!$B$9*ASIN(SQRT(SIN(RADIANS(Settings!$B$7-$D10)/2)^2+COS(RADIANS($D10))*COS(RADIANS(Settings!$B$7))*SIN(RADIANS(Settings!$C$7-$E10)/2)^2)) -> 36.332434 | N10: =J10*Settings!$B$10 -> 12.336042 | O10: =K10*Settings!$B$10 -> 24.727911 | P10: =L10*Settings!$B$10 -> 3.7406663 | Q10: =M10*Settings!$B$10 -> 0.50865408 | R10: =AVERAGE(N10:Q10) -> 10.328318 | S10: =IF(AND(OR(Settings!$B$14=0,F10<5),G10<=Settings!$B$13,OR(H10=0,Settings!$B$15=1),OR(Settings!$B$16=0,I10=0)),1,0) -> 1 | T10: 3.8 | U10: 6 | V10: =R10 -> 10.328318 | W10: 4 | X10: 6 | Y10: 9 | Z10: 7 | AA10: 4 | AB10: 6 | AC10: =IF($S10=1,IF(T$4=T$3,5,10*(T10-T$3)/(T$4-T$3)),"") -> 1.3333333 | AD10: =IF($S10=1,IF(U$4=U$3,5,10*(U10-U$3)/(U$4-U$3)),"") -> 5 | AE10: =IF($S10=1,IF(V$4=V$3,5,10*(V$4-V10)/(V$4-V$3)),"") -> 9.4455125 | AF10: =IF($S10=1,IF(W$4=W$3,5,10*(W10-W$3)/(W$4-W$3)),"") -> 5 | AG10: =IF($S10=1,IF(X$4=X$3,5,10*(X10-X$3)/(X$4-X$3)),"") -> 7.1428571 | AH10: =IF($S10=1,IF(Y$4=Y$3,5,10*(Y10-Y$3)/(Y$4-Y$3)),"") -> 10 | AI10: =IF($S10=1,IF(Z$4=Z$3,5,10*(Z10-Z$3)/(Z$4-Z$3)),"") -> 6.6666667 | AJ10: =IF($S10=1,IF(AA$4=AA$3,5,10*(AA10-AA$3)/(AA$4-AA$3)),"") -> 1.6666667 | AK10: =IF($S10=1,IF(AB$4=AB$3,5,10*(AB10-AB$3)/(AB$4-AB$3)),"") -> 5.5555556 | AL10: =IF($S10=1,SUMPRODUCT(AC10:AK10,Settings!$B$21:$J$21),"") -> 4.9128052 | AM10: =IF($S10=1,EXP(Settings!$B$21*LN(MAX(AC10,0.5))+Settings!$C$21*LN(MAX(AD10,0.5))+Settings!$D$21*LN(MAX(AE10,0.5))+Settings!$E$21*LN(MAX(AF10,0.5))+Settings!$F$21*LN(MAX(AG10,0.5))+Settings!$G$21*LN(MAX(AH10,0.5))+Settings!$H$21*LN(MAX(AI10,0.5))+Settings!$I$21*LN(MAX(AJ10,0.5))+Settings!$J$21*LN(MAX(AK10,0.5))),"") -> 3.8173196 | AN10: =IF($S10=1,COUNTIFS($S$6:$S$55,1,$AL$6:$AL$55,">"&AL10)+1,"") -> 27 | AO10: =IF($S10=1,IF(AN10<=CEILING(SUM($S$6:$S$55)*Settings!$B$30,1),"A",IF(AN10<=CEILING(SUM($S$6:$S$55)*Settings!$B$31,1),"B","C")),"Excluded") -> B
A11: che | B11: Chennai | C11: Tamil Nadu | D11: 13.08 | E11: 80.27 | F11: 3 | G11: 12 | H11: 1 | I11: 1 | J11: =2*Settings!$B$9*ASIN(SQRT(SIN(RADIANS(Settings!$B$4-$D11)/2)^2+COS(RADIANS($D11))*COS(RADIANS(Settings!$B$4))*SIN(RADIANS(Settings!$C$4-$E11)/2)^2)) -> 1033.2144 | K11: =2*Settings!$B$9*ASIN(SQRT(SIN(RADIANS(Settings!$B$5-$D11)/2)^2+COS(RADIANS($D11))*COS(RADIANS(Settings!$B$5))*SIN(RADIANS(Settings!$C$5-$E11)/2)^2)) -> 1756.091 | L11: =2*Settings!$B$9*ASIN(SQRT(SIN(RADIANS(Settings!$B$6-$D11)/2)^2+COS(RADIANS($D11))*COS(RADIANS(Settings!$B$6))*SIN(RADIANS(Settings!$C$6-$E11)/2)^2)) -> 0.33358478 | M11: =2*Settings!$B$9*ASIN(SQRT(SIN(RADIANS(Settings!$B$7-$D11)/2)^2+COS(RADIANS($D11))*COS(RADIANS(Settings!$B$7))*SIN(RADIANS(Settings!$C$7-$E11)/2)^2)) -> 290.14808 | N11: =J11*Settings!$B$10 -> 14.465002 | O11: =K11*Settings!$B$10 -> 24.585273 | P11: =L11*Settings!$B$10 -> 0.0046701869 | Q11: =M11*Settings!$B$10 -> 4.0620731 | R11: =AVERAGE(N11:Q11) -> 10.779255 | S11: =IF(AND(OR(Settings!$B$14=0,F11<5),G11<=Settings!$B$13,OR(H11=0,Settings!$B$15=1),OR(Settings!$B$16=0,I11=0)),1,0) -> 1 | T11: 4.3 | U11: 10 | V11: =R11 -> 10.779255 | W11: 3 | X11: 1 | Y11: 4 | Z11: 4 | AA11: 4 | AB11: 9 | AC11: =IF($S11=1,IF(T$4=T$3,5,10*(T11-T$3)/(T$4-T$3)),"") -> 2.1666667 | AD11: =IF($S11=1,IF(U$4=U$3,5,10*(U11-U$3)/(U$4-U$3)),"") -> 10 | AE11: =IF($S11=1,IF(V$4=V$3,5,10*(V$4-V11)/(V$4-V$3)),"") -> 9.0294893 | AF11: =IF($S11=1,IF(W$4=W$3,5,10*(W11-W$3)/(W$4-W$3)),"") -> 3.3333333 | AG11: =IF($S11=1,IF(X$4=X$3,5,10*(X11-X$3)/(X$4-X$3)),"") -> 0 | AH11: =IF($S11=1,IF(Y$4=Y$3,5,10*(Y11-Y$3)/(Y$4-Y$3)),"") -> 1.6666667 | AI11: =IF($S11=1,IF(Z$4=Z$3,5,10*(Z11-Z$3)/(Z$4-Z$3)),"") -> 3.3333333 | AJ11: =IF($S11=1,IF(AA$4=AA$3,5,10*(AA11-AA$3)/(AA$4-AA$3)),"") -> 1.6666667 | AK11: =IF($S11=1,IF(AB$4=AB$3,5,10*(AB11-AB$3)/(AB$4-AB$3)),"") -> 8.8888889 | AL11: =IF($S11=1,SUMPRODUCT(AC11:AK11,Settings!$B$21:$J$21),"") -> 4.38906 | AM11: =IF($S11=1,EXP(Settings!$B$21*LN(MAX(AC11,0.5))+Settings!$C$21*LN(MAX(AD11,0.5))+Settings!$D$21*LN(MAX(AE11,0.5))+Settings!$E$21*LN(MAX(AF11,0.5))+Settings!$F$21*LN(MAX(AG11,0.5))+Settings!$G$21*LN(MAX(AH11,0.5))+Settings!$H$21*LN(MAX(AI11,0.5))+Settings!$I$21*LN(MAX(AJ11,0.5))+Settings!$J$21*LN(MAX(AK11,0.5))),"") -> 3.2422815 | AN11: =IF($S11=1,COUNTIFS($S$6:$S$55,1,$AL$6:$AL$55,">"&AL11)+1,"") -> 38 | AO11: =IF($S11=1,IF(AN11<=CEILING(SUM($S$6:$S$55)*Settings!$B$30,1),"A",IF(AN11<=CEILING(SUM($S$6:$S$55)*Settings!$B$31,1),"B","C")),"Excluded") -> C
A12: cbe | B12: Coimbatore | C12: Tamil Nadu | D12: 11.02 | E12: 76.96 | F12: 3 | G12: 20 | H12: 0 | I12: 0 | J12: =2*Settings!$B$9*ASIN(SQRT(SIN(RADIANS(Settings!$B$4-$D12)/2)^2+COS(RADIANS($D12))*COS(RADIANS(Settings!$B$4))*SIN(RADIANS(Settings!$C$4-$E12)/2)^2)) -> 997.08475 | K12: =2*Settings!$B$9*ASIN(SQRT(SIN(RADIANS(Settings!$B$5-$D12)/2)^2+COS(RADIANS($D12))*COS(RADIANS(Settings!$B$5))*SIN(RADIANS(Settings!$C$5-$E12)/2)^2)) -> 1956.535 | L12: =2*Settings!$B$9*ASIN(SQRT(SIN(RADIANS(Settings!$B$6-$D12)/2)^2+COS(RADIANS($D12))*COS(RADIANS(Settings!$B$6))*SIN(RADIANS(Settings!$C$6-$E12)/2)^2)) -> 426.80662 | M12: =2*Settings!$B$9*ASIN(SQRT(SIN(RADIANS(Settings!$B$7-$D12)/2)^2+COS(RADIANS($D12))*COS(RADIANS(Settings!$B$7))*SIN(RADIANS(Settings!$C$7-$E12)/2)^2)) -> 227.74213 | N12: =J12*Settings!$B$10 -> 13.959186 | O12: =K12*Settings!$B$10 -> 27.391491 | P12: =L12*Settings!$B$10 -> 5.9752926 | Q12: =M12*Settings!$B$10 -> 3.1883898 | R12: =AVERAGE(N12:Q12) -> 12.62859 | S12: =IF(AND(OR(Settings!$B$14=0,F12<5),G12<=Settings!$B$13,OR(H12=0,Settings!$B$15=1),OR(Settings!$B$16=0,I12=0)),1,0) -> 1 | T12: 4.3 | U12: 5 | V12: =R12 -> 12.62859 | W12: 5 | X12: 5 | Y12: 7 | Z12: 7 | AA12: 4 | AB12: 6 | AC12: =IF($S12=1,IF(T$4=T$3,5,10*(T12-T$3)/(T$4-T$3)),"") -> 2.1666667 | AD12: =IF($S12=1,IF(U$4=U$3,5,10*(U12-U$3)/(U$4-U$3)),"") -> 3.75 | AE12: =IF($S12=1,IF(V$4=V$3,5,10*(V$4-V12)/(V$4-V$3)),"") -> 7.3233367 | AF12: =IF($S12=1,IF(W$4=W$3,5,10*(W12-W$3)/(W$4-W$3)),"") -> 6.6666667 | AG12: =IF($S12=1,IF(X$4=X$3,5,10*(X12-X$3)/(X$4-X$3)),"") -> 5.7142857 | AH12: =IF($S12=1,IF(Y$4=Y$3,5,10*(Y12-Y$3)/(Y$4-Y$3)),"") -> 6.6666667 | AI12: =IF($S12=1,IF(Z$4=Z$3,5,10*(Z12-Z$3)/(Z$4-Z$3)),"") -> 6.6666667 | AJ12: =IF($S12=1,IF(AA$4=AA$3,5,10*(AA12-AA$3)/(AA$4-AA$3)),"") -> 1.6666667 | AK12: =IF($S12=1,IF(AB$4=AB$3,5,10*(AB12-AB$3)/(AB$4-AB$3)),"") -> 5.5555556 | AL12: =IF($S12=1,SUMPRODUCT(AC12:AK12,Settings!$B$21:$J$21),"") -> 4.5666591 | AM12: =IF($S12=1,EXP(Settings!$B$21*LN(MAX(AC12,0.5))+Settings!$C$21*LN(MAX(AD12,0.5))+Settings!$D$21*LN(MAX(AE12,0.5))+Settings!$E$21*LN(MAX(AF12,0.5))+Settings!$F$21*LN(MAX(AG12,0.5))+Settings!$G$21*LN(MAX(AH12,0.5))+Settings!$H$21*LN(MAX(AI12,0.5))+Settings!$I$21*LN(MAX(AJ12,0.5))+Settings!$J$21*LN(MAX(AK12,0.5))),"") -> 3.9899328 | AN12: =IF($S12=1,COUNTIFS($S$6:$S$55,1,$AL$6:$AL$55,">"&AL12)+1,"") -> 32 | AO12: =IF($S12=1,IF(AN12<=CEILING(SUM($S$6:$S$55)*Settings!$B$30,1),"A",IF(AN12<=CEILING(SUM($S$6:$S$55)*Settings!$B$31,1),"B","C")),"Excluded") -> B
A13: tut | B13: Thoothukudi | C13: Tamil Nadu | D13: 8.76 | E13: 78.13 | F13: 2 | G13: 20 | H13: 0 | I13: 0 | J13: =2*Settings!$B$9*ASIN(SQRT(SIN(RADIANS(Settings!$B$4-$D13)/2)^2+COS(RADIANS($D13))*COS(RADIANS(Settings!$B$4))*SIN(RADIANS(Settings!$C$4-$E13)/2)^2)) -> 1279.0955 | K13: =2*Settings!$B$9*ASIN(SQRT(SIN(RADIANS(Settings!$B$5-$D13)/2)^2+COS(RADIANS($D13))*COS(RADIANS(Settings!$B$5))*SIN(RADIANS(Settings!$C$5-$E13)/2)^2)) -> 2209.7658 | L13: =2*Settings!$B$9*ASIN(SQRT(SIN(RADIANS(Settings!$B$6-$D13)/2)^2+COS(RADIANS($D13))*COS(RADIANS(Settings!$B$6))*SIN(RADIANS(Settings!$C$6-$E13)/2)^2)) -> 534.44393 | M13: =2*Settings!$B$9*ASIN(SQRT(SIN(RADIANS(Settings!$B$7-$D13)/2)^2+COS(RADIANS($D13))*COS(RADIANS(Settings!$B$7))*SIN(RADIANS(Settings!$C$7-$E13)/2)^2)) -> 471.99452 | N13: =J13*Settings!$B$10 -> 17.907337 | O13: =K13*Settings!$B$10 -> 30.936721 | P13: =L13*Settings!$B$10 -> 7.482215 | Q13: =M13*Settings!$B$10 -> 6.6079233 | R13: =AVERAGE(N13:Q13) -> 15.733549 | S13: =IF(AND(OR(Settings!$B$14=0,F13<5),G13<=Settings!$B$13,OR(H13=0,Settings!$B$15=1),OR(Settings!$B$16=0,I13=0)),1,0) -> 1 | T13: 4.8 | U13: 7 | V13: =R13 -> 15.733549 | W13: 5 | X13: 1 | Y13: 6 | Z13: 8 | AA13: 4 | AB13: 2 | AC13: =IF($S13=1,IF(T$4=T$3,5,10*(T13-T$3)/(T$4-T$3)),"") -> 3 | AD13: =IF($S13=1,IF(U$4=U$3,5,10*(U13-U$3)/(U$4-U$3)),"") -> 6.25 | AE13: =IF($S13=1,IF(V$4=V$3,5,10*(V$4-V13)/(V$4-V$3)),"") -> 4.458775 | AF13: =IF($S13=1,IF(W$4=W$3,5,10*(W13-W$3)/(W$4-W$3)),"") -> 6.6666667 | AG13: =IF($S13=1,IF(X$4=X$3,5,10*(X13-X$3)/(X$4-X$3)),"") -> 0 | AH13: =IF($S13=1,IF(Y$4=Y$3,5,10*(Y13-Y$3)/(Y$4-Y$3)),"") -> 5 | AI13: =IF($S13=1,IF(Z$4=Z$3,5,10*(Z13-Z$3)/(Z$4-Z$3)),"") -> 7.7777778 | AJ13: =IF($S13=1,IF(AA$4=AA$3,5,10*(AA13-AA$3)/(AA$4-AA$3)),"") -> 1.6666667 | AK13: =IF($S13=1,IF(AB$4=AB$3,5,10*(AB13-AB$3)/(AB$4-AB$3)),"") -> 1.1111111 | AL13: =IF($S13=1,SUMPRODUCT(AC13:AK13,Settings!$B$21:$J$21),"") -> 4.2444886 | AM13: =IF($S13=1,EXP(Settings!$B$21*LN(MAX(AC13,0.5))+Settings!$C$21*LN(MAX(AD13,0.5))+Settings!$D$21*LN(MAX(AE13,0.5))+Settings!$E$21*LN(MAX(AF13,0.5))+Settings!$F$21*LN(MAX(AG13,0.5))+Settings!$G$21*LN(MAX(AH13,0.5))+Settings!$H$21*LN(MAX(AI13,0.5))+Settings!$I$21*LN(MAX(AJ13,0.5))+Settings!$J$21*LN(MAX(AK13,0.5))),"") -> 3.5565688 | AN13: =IF($S13=1,COUNTIFS($S$6:$S$55,1,$AL$6:$AL$55,">"&AL13)+1,"") -> 39 | AO13: =IF($S13=1,IF(AN13<=CEILING(SUM($S$6:$S$55)*Settings!$B$30,1),"A",IF(AN13<=CEILING(SUM($S$6:$S$55)*Settings!$B$31,1),"B","C")),"Excluded") -> C
A14: mys | B14: Mysuru | C14: Karnataka | D14: 12.3 | E14: 76.64 | F14: 2 | G14: 15 | H14: 0 | I14: 0 | J14: =2*Settings!$B$9*ASIN(SQRT(SIN(RADIANS(Settings!$B$4-$D14)/2)^2+COS(RADIANS($D14))*COS(RADIANS(Settings!$B$4))*SIN(RADIANS(Settings!$C$4-$E14)/2)^2)) -> 854.19694 | K14: =2*Settings!$B$9*ASIN(SQRT(SIN(RADIANS(Settings!$B$5-$D14)/2)^2+COS(RADIANS($D14))*COS(RADIANS(Settings!$B$5))*SIN(RADIANS(Settings!$C$5-$E14)/2)^2)) -> 1814.9931 | L14: =2*Settings!$B$9*ASIN(SQRT(SIN(RADIANS(Settings!$B$6-$D14)/2)^2+COS(RADIANS($D14))*COS(RADIANS(Settings!$B$6))*SIN(RADIANS(Settings!$C$6-$E14)/2)^2)) -> 403.27948 | M14: =2*Settings!$B$9*ASIN(SQRT(SIN(RADIANS(Settings!$B$7-$D14)/2)^2+COS(RADIANS($D14))*COS(RADIANS(Settings!$B$7))*SIN(RADIANS(Settings!$C$7-$E14)/2)^2)) -> 127.66294 | N14: =J14*Settings!$B$10 -> 11.958757 | O14: =K14*Settings!$B$10 -> 25.409903 | P14: =L14*Settings!$B$10 -> 5.6459127 | Q14: =M14*Settings!$B$10 -> 1.7872812 | R14: =AVERAGE(N14:Q14) -> 11.200463 | S14: =IF(AND(OR(Settings!$B$14=0,F14<5),G14<=Settings!$B$13,OR(H14=0,Settings!$B$15=1),OR(Settings!$B$16=0,I14=0)),1,0) -> 1 | T14: 5 | U14: 4 | V14: =R14 -> 11.200463 | W14: 7 | X14: 8 | Y14: 9 | Z14: 7 | AA14: 8 | AB14: 3 | AC14: =IF($S14=1,IF(T$4=T$3,5,10*(T14-T$3)/(T$4-T$3)),"") -> 3.3333333 | AD14: =IF($S14=1,IF(U$4=U$3,5,10*(U14-U$3)/(U$4-U$3)),"") -> 2.5 | AE14: =IF($S14=1,IF(V$4=V$3,5,10*(V$4-V14)/(V$4-V$3)),"") -> 8.6408921 | AF14: =IF($S14=1,IF(W$4=W$3,5,10*(W14-W$3)/(W$4-W$3)),"") -> 10 | AG14: =IF($S14=1,IF(X$4=X$3,5,10*(X14-X$3)/(X$4-X$3)),"") -> 10 | AH14: =IF($S14=1,IF(Y$4=Y$3,5,10*(Y14-Y$3)/(Y$4-Y$3)),"") -> 10 | AI14: =IF($S14=1,IF(Z$4=Z$3,5,10*(Z14-Z$3)/(Z$4-Z$3)),"") -> 6.6666667 | AJ14: =IF($S14=1,IF(AA$4=AA$3,5,10*(AA14-AA$3)/(AA$4-AA$3)),"") -> 8.3333333 | AK14: =IF($S14=1,IF(AB$4=AB$3,5,10*(AB14-AB$3)/(AB$4-AB$3)),"") -> 2.2222222 | AL14: =IF($S14=1,SUMPRODUCT(AC14:AK14,Settings!$B$21:$J$21),"") -> 6.3502003 | AM14: =IF($S14=1,EXP(Settings!$B$21*LN(MAX(AC14,0.5))+Settings!$C$21*LN(MAX(AD14,0.5))+Settings!$D$21*LN(MAX(AE14,0.5))+Settings!$E$21*LN(MAX(AF14,0.5))+Settings!$F$21*LN(MAX(AG14,0.5))+Settings!$G$21*LN(MAX(AH14,0.5))+Settings!$H$21*LN(MAX(AI14,0.5))+Settings!$I$21*LN(MAX(AJ14,0.5))+Settings!$J$21*LN(MAX(AK14,0.5))),"") -> 5.4285424 | AN14: =IF($S14=1,COUNTIFS($S$6:$S$55,1,$AL$6:$AL$55,">"&AL14)+1,"") -> 5 | AO14: =IF($S14=1,IF(AN14<=CEILING(SUM($S$6:$S$55)*Settings!$B$30,1),"A",IF(AN14<=CEILING(SUM($S$6:$S$55)*Settings!$B$31,1),"B","C")),"Excluded") -> A
A15: hsk | B15: Hoskote | C15: Karnataka | D15: 13.07 | E15: 77.8 | F15: 2 | G15: 20 | H15: 1 | I15: 0 | J15: =2*Settings!$B$9*ASIN(SQRT(SIN(RADIANS(Settings!$B$4-$D15)/2)^2+COS(RADIANS($D15))*COS(RADIANS(Settings!$B$4))*SIN(RADIANS(Settings!$C$4-$E15)/2)^2)) -> 849.85576 | K15: =2*Settings!$B$9*ASIN(SQRT(SIN(RADIANS(Settings!$B$5-$D15)/2)^2+COS(RADIANS($D15))*COS(RADIANS(Settings!$B$5))*SIN(RADIANS(Settings!$C$5-$E15)/2)^2)) -> 1729.4951 | L15: =2*Settings!$B$9*ASIN(SQRT(SIN(RADIANS(Settings!$B$6-$D15)/2)^2+COS(RADIANS($D15))*COS(RADIANS(Settings!$B$6))*SIN(RADIANS(Settings!$C$6-$E15)/2)^2)) -> 267.53228 | M15: =2*Settings!$B$9*ASIN(SQRT(SIN(RADIANS(Settings!$B$7-$D15)/2)^2+COS(RADIANS($D15))*COS(RADIANS(Settings!$B$7))*SIN(RADIANS(Settings!$C$7-$E15)/2)^2)) -> 24.835524 | N15: =J15*Settings!$B$10 -> 11.897981 | O15: =K15*Settings!$B$10 -> 24.212932 | P15: =L15*Settings!$B$10 -> 3.745452 | Q15: =M15*Settings!$B$10 -> 0.34769734 | R15: =AVERAGE(N15:Q15) -> 10.051015 | S15: =IF(AND(OR(Settings!$B$14=0,F15<5),G15<=Settings!$B$13,OR(H15=0,Settings!$B$15=1),OR(Settings!$B$16=0,I15=0)),1,0) -> 1 | T15: 5.5 | U15: 6 | V15: =R15 -> 10.051015 | W15: 2 | X15: 8 | Y15: 9 | Z15: 6 | AA15: 8 | AB15: 8 | AC15: =IF($S15=1,IF(T$4=T$3,5,10*(T15-T$3)/(T$4-T$3)),"") -> 4.1666667 | AD15: =IF($S15=1,IF(U$4=U$3,5,10*(U15-U$3)/(U$4-U$3)),"") -> 5 | AE15: =IF($S15=1,IF(V$4=V$3,5,10*(V$4-V15)/(V$4-V$3)),"") -> 9.7013455 | AF15: =IF($S15=1,IF(W$4=W$3,5,10*(W15-W$3)/(W$4-W$3)),"") -> 1.6666667 | AG15: =IF($S15=1,IF(X$4=X$3,5,10*(X15-X$3)/(X$4-X$3)),"") -> 10 | AH15: =IF($S15=1,IF(Y$4=Y$3,5,10*(Y15-Y$3)/(Y$4-Y$3)),"") -> 10 | AI15: =IF($S15=1,IF(Z$4=Z$3,5,10*(Z15-Z$3)/(Z$4-Z$3)),"") -> 5.5555556 | AJ15: =IF($S15=1,IF(AA$4=AA$3,5,10*(AA15-AA$3)/(AA$4-AA$3)),"") -> 8.3333333 | AK15: =IF($S15=1,IF(AB$4=AB$3,5,10*(AB15-AB$3)/(AB$4-AB$3)),"") -> 7.7777778 | AL15: =IF($S15=1,SUMPRODUCT(AC15:AK15,Settings!$B$21:$J$21),"") -> 6.0118012 | AM15: =IF($S15=1,EXP(Settings!$B$21*LN(MAX(AC15,0.5))+Settings!$C$21*LN(MAX(AD15,0.5))+Settings!$D$21*LN(MAX(AE15,0.5))+Settings!$E$21*LN(MAX(AF15,0.5))+Settings!$F$21*LN(MAX(AG15,0.5))+Settings!$G$21*LN(MAX(AH15,0.5))+Settings!$H$21*LN(MAX(AI15,0.5))+Settings!$I$21*LN(MAX(AJ15,0.5))+Settings!$J$21*LN(MAX(AK15,0.5))),"") -> 5.195343 | AN15: =IF($S15=1,COUNTIFS($S$6:$S$55,1,$AL$6:$AL$55,">"&AL15)+1,"") -> 14 | AO15: =IF($S15=1,IF(AN15<=CEILING(SUM($S$6:$S$55)*Settings!$B$30,1),"A",IF(AN15<=CEILING(SUM($S$6:$S$55)*Settings!$B$31,1),"B","C")),"Excluded") -> A
A16: blr | B16: Bengaluru core | C16: Karnataka | D16: 12.97 | E16: 77.59 | F16: 2 | G16: 15 | H16: 1 | I16: 0 | J16: =2*Settings!$B$9*ASIN(SQRT(SIN(RADIANS(Settings!$B$4-$D16)/2)^2+COS(RADIANS($D16))*COS(RADIANS(Settings!$B$4))*SIN(RADIANS(Settings!$C$4-$E16)/2)^2)) -> 845.15061 | K16: =2*Settings!$B$9*ASIN(SQRT(SIN(RADIANS(Settings!$B$5-$D16)/2)^2+COS(RADIANS($D16))*COS(RADIANS(Settings!$B$5))*SIN(RADIANS(Settings!$C$5-$E16)/2)^2)) -> 1739.9802 | L16: =2*Settings!$B$9*ASIN(SQRT(SIN(RADIANS(Settings!$B$6-$D16)/2)^2+COS(RADIANS($D16))*COS(RADIANS(Settings!$B$6))*SIN(RADIANS(Settings!$C$6-$E16)/2)^2)) -> 290.60395 | M16: =2*Settings!$B$9*ASIN(SQRT(SIN(RADIANS(Settings!$B$7-$D16)/2)^2+COS(RADIANS($D16))*COS(RADIANS(Settings!$B$7))*SIN(RADIANS(Settings!$C$7-$E16)/2)^2)) -> 0.48715434 | N16: =J16*Settings!$B$10 -> 11.832109 | O16: =K16*Settings!$B$10 -> 24.359723 | P16: =L16*Settings!$B$10 -> 4.0684554 | Q16: =M16*Settings!$B$10 -> 0.0068201607 | R16: =AVERAGE(N16:Q16) -> 10.066777 | S16: =IF(AND(OR(Settings!$B$14=0,F16<5),G16<=Settings!$B$13,OR(H16=0,Settings!$B$15=1),OR(Settings!$B$16=0,I16=0)),1,0) -> 1 | T16: 5 | U16: 7 | V16: =R16 -> 10.066777 | W16: 1 | X16: 8 | Y16: 8 | Z16: 3 | AA16: 8 | AB16: 10 | AC16: =IF($S16=1,IF(T$4=T$3,5,10*(T16-T$3)/(T$4-T$3)),"") -> 3.3333333 | AD16: =IF($S16=1,IF(U$4=U$3,5,10*(U16-U$3)/(U$4-U$3)),"") -> 6.25 | AE16: =IF($S16=1,IF(V$4=V$3,5,10*(V$4-V16)/(V$4-V$3)),"") -> 9.6868044 | AF16: =IF($S16=1,IF(W$4=W$3,5,10*(W16-W$3)/(W$4-W$3)),"") -> 0 | AG16: =IF($S16=1,IF(X$4=X$3,5,10*(X16-X$3)/(X$4-X$3)),"") -> 10 | AH16: =IF($S16=1,IF(Y$4=Y$3,5,10*(Y16-Y$3)/(Y$4-Y$3)),"") -> 8.3333333 | AI16: =IF($S16=1,IF(Z$4=Z$3,5,10*(Z16-Z$3)/(Z$4-Z$3)),"") -> 2.2222222 | AJ16: =IF($S16=1,IF(AA$4=AA$3,5,10*(AA16-AA$3)/(AA$4-AA$3)),"") -> 8.3333333 | AK16: =IF($S16=1,IF(AB$4=AB$3,5,10*(AB16-AB$3)/(AB$4-AB$3)),"") -> 10 | AL16: =IF($S16=1,SUMPRODUCT(AC16:AK16,Settings!$B$21:$J$21),"") -> 5.5172915 | AM16: =IF($S16=1,EXP(Settings!$B$21*LN(MAX(AC16,0.5))+Settings!$C$21*LN(MAX(AD16,0.5))+Settings!$D$21*LN(MAX(AE16,0.5))+Settings!$E$21*LN(MAX(AF16,0.5))+Settings!$F$21*LN(MAX(AG16,0.5))+Settings!$G$21*LN(MAX(AH16,0.5))+Settings!$H$21*LN(MAX(AI16,0.5))+Settings!$I$21*LN(MAX(AJ16,0.5))+Settings!$J$21*LN(MAX(AK16,0.5))),"") -> 4.0278044 | AN16: =IF($S16=1,COUNTIFS($S$6:$S$55,1,$AL$6:$AL$55,">"&AL16)+1,"") -> 22 | AO16: =IF($S16=1,IF(AN16<=CEILING(SUM($S$6:$S$55)*Settings!$B$30,1),"A",IF(AN16<=CEILING(SUM($S$6:$S$55)*Settings!$B$31,1),"B","C")),"Excluded") -> B
A17: mlr | B17: Mangaluru | C17: Karnataka | D17: 12.91 | E17: 74.86 | F17: 3 | G17: 15 | H17: 0 | I17: 0 | J17: =2*Settings!$B$9*ASIN(SQRT(SIN(RADIANS(Settings!$B$4-$D17)/2)^2+COS(RADIANS($D17))*COS(RADIANS(Settings!$B$4))*SIN(RADIANS(Settings!$C$4-$E17)/2)^2)) -> 717.57594 | K17: =2*Settings!$B$9*ASIN(SQRT(SIN(RADIANS(Settings!$B$5-$D17)/2)^2+COS(RADIANS($D17))*COS(RADIANS(Settings!$B$5))*SIN(RADIANS(Settings!$C$5-$E17)/2)^2)) -> 1763.0502 | L17: =2*Settings!$B$9*ASIN(SQRT(SIN(RADIANS(Settings!$B$6-$D17)/2)^2+COS(RADIANS($D17))*COS(RADIANS(Settings!$B$6))*SIN(RADIANS(Settings!$C$6-$E17)/2)^2)) -> 586.45906 | M17: =2*Settings!$B$9*ASIN(SQRT(SIN(RADIANS(Settings!$B$7-$D17)/2)^2+COS(RADIANS($D17))*COS(RADIANS(Settings!$B$7))*SIN(RADIANS(Settings!$C$7-$E17)/2)^2)) -> 296.36429 | N17: =J17*Settings!$B$10 -> 10.046063 | O17: =K17*Settings!$B$10 -> 24.682703 | P17: =L17*Settings!$B$10 -> 8.2104268 | Q17: =M17*Settings!$B$10 -> 4.1491 | R17: =AVERAGE(N17:Q17) -> 11.772073 | S17: =IF(AND(OR(Settings!$B$14=0,F17<5),G17<=Settings!$B$13,OR(H17=0,Settings!$B$15=1),OR(Settings!$B$16=0,I17=0)),1,0) -> 1 | T17: 5 | U17: 6 | V17: =R17 -> 11.772073 | W17: 7 | X17: 2 | Y17: 6 | Z17: 6 | AA17: 8 | AB17: 3 | AC17: =IF($S17=1,IF(T$4=T$3,5,10*(T17-T$3)/(T$4-T$3)),"") -> 3.3333333 | AD17: =IF($S17=1,IF(U$4=U$3,5,10*(U17-U$3)/(U$4-U$3)),"") -> 5 | AE17: =IF($S17=1,IF(V$4=V$3,5,10*(V$4-V17)/(V$4-V$3)),"") -> 8.1135385 | AF17: =IF($S17=1,IF(W$4=W$3,5,10*(W17-W$3)/(W$4-W$3)),"") -> 10 | AG17: =IF($S17=1,IF(X$4=X$3,5,10*(X17-X$3)/(X$4-X$3)),"") -> 1.4285714 | AH17: =IF($S17=1,IF(Y$4=Y$3,5,10*(Y17-Y$3)/(Y$4-Y$3)),"") -> 5 | AI17: =IF($S17=1,IF(Z$4=Z$3,5,10*(Z17-Z$3)/(Z$4-Z$3)),"") -> 5.5555556 | AJ17: =IF($S17=1,IF(AA$4=AA$3,5,10*(AA17-AA$3)/(AA$4-AA$3)),"") -> 8.3333333 | AK17: =IF($S17=1,IF(AB$4=AB$3,5,10*(AB17-AB$3)/(AB$4-AB$3)),"") -> 2.2222222 | AL17: =IF($S17=1,SUMPRODUCT(AC17:AK17,Settings!$B$21:$J$21),"") -> 5.688338 | AM17: =IF($S17=1,EXP(Settings!$B$21*LN(MAX(AC17,0.5))+Settings!$C$21*LN(MAX(AD17,0.5))+Settings!$D$21*LN(MAX(AE17,0.5))+Settings!$E$21*LN(MAX(AF17,0.5))+Settings!$F$21*LN(MAX(AG17,0.5))+Settings!$G$21*LN(MAX(AH17,0.5))+Settings!$H$21*LN(MAX(AI17,0.5))+Settings!$I$21*LN(MAX(AJ17,0.5))+Settings!$J$21*LN(MAX(AK17,0.5))),"") -> 5.0209505 | AN17: =IF($S17=1,COUNTIFS($S$6:$S$55,1,$AL$6:$AL$55,">"&AL17)+1,"") -> 18 | AO17: =IF($S17=1,IF(AN17<=CEILING(SUM($S$6:$S$55)*Settings!$B$30,1),"A",IF(AN17<=CEILING(SUM($S$6:$S$55)*Settings!$B$31,1),"B","C")),"Excluded") -> B
... A55: guw | B55: Guwahati | C55: Assam | D55: 26.14 | E55: 91.74 | F55: 5 | G55: 15 | H55: 0 | I55: 1 | J55: =2*Settings!$B$9*ASIN(SQRT(SIN(RADIANS(Settings!$B$4-$D55)/2)^2+COS(RADIANS($D55))*COS(RADIANS(Settings!$B$4))*SIN(RADIANS(Settings!$C$4-$E55)/2)^2)) -> 2086.5106 | K55: =2*Settings!$B$9*ASIN(SQRT(SIN(RADIANS(Settings!$B$5-$D55)/2)^2+COS(RADIANS($D55))*COS(RADIANS(Settings!$B$5))*SIN(RADIANS(Settings!$C$5-$E55)/2)^2)) -> 1459.9407 | L55: =2*Settings!$B$9*ASIN(SQRT(SIN(RADIANS(Settings!$B$6-$D55)/2)^2+COS(RADIANS($D55))*COS(RADIANS(Settings!$B$6))*SIN(RADIANS(Settings!$C$6-$E55)/2)^2)) -> 1882.0595 | M55: =2*Settings!$B$9*ASIN(SQRT(SIN(RADIANS(Settings!$B$7-$D55)/2)^2+COS(RADIANS($D55))*COS(RADIANS(Settings!$B$7))*SIN(RADIANS(Settings!$C$7-$E55)/2)^2)) -> 2079.9737 | N55: =J55*Settings!$B$10 -> 29.211148 | O55: =K55*Settings!$B$10 -> 20.43917 | P55: =L55*Settings!$B$10 -> 26.348833 | Q55: =M55*Settings!$B$10 -> 29.119632 | R55: =AVERAGE(N55:Q55) -> 26.279696 | S55: =IF(AND(OR(Settings!$B$14=0,F55<5),G55<=Settings!$B$13,OR(H55=0,Settings!$B$15=1),OR(Settings!$B$16=0,I55=0)),1,0) -> 0 | T55: 4.7 | U55: 4 | V55: =R55 -> 26.279696 | W55: 7 | X55: 4 | Y55: 1 | Z55: 7 | AA55: 4 | AB55: 2 | AC55: =IF($S55=1,IF(T$4=T$3,5,10*(T55-T$3)/(T$4-T$3)),"") | AD55: =IF($S55=1,IF(U$4=U$3,5,10*(U55-U$3)/(U$4-U$3)),"") | AE55: =IF($S55=1,IF(V$4=V$3,5,10*(V$4-V55)/(V$4-V$3)),"") | AF55: =IF($S55=1,IF(W$4=W$3,5,10*(W55-W$3)/(W$4-W$3)),"") | AG55: =IF($S55=1,IF(X$4=X$3,5,10*(X55-X$3)/(X$4-X$3)),"") | AH55: =IF($S55=1,IF(Y$4=Y$3,5,10*(Y55-Y$3)/(Y$4-Y$3)),"") | AI55: =IF($S55=1,IF(Z$4=Z$3,5,10*(Z55-Z$3)/(Z$4-Z$3)),"") | AJ55: =IF($S55=1,IF(AA$4=AA$3,5,10*(AA55-AA$3)/(AA$4-AA$3)),"") | AK55: =IF($S55=1,IF(AB$4=AB$3,5,10*(AB55-AB$3)/(AB$4-AB$3)),"") | AL55: =IF($S55=1,SUMPRODUCT(AC55:AK55,Settings!$B$21:$J$21),"") | AM55: =IF($S55=1,EXP(Settings!$B$21*LN(MAX(AC55,0.5))+Settings!$C$21*LN(MAX(AD55,0.5))+Settings!$D$21*LN(MAX(AE55,0.5))+Settings!$E$21*LN(MAX(AF55,0.5))+Settings!$F$21*LN(MAX(AG55,0.5))+Settings!$G$21*LN(MAX(AH55,0.5))+Settings!$H$21*LN(MAX(AI55,0.5))+Settings!$I$21*LN(MAX(AJ55,0.5))+Settings!$J$21*LN(MAX(AK55,0.5))),"") | AN55: =IF($S55=1,COUNTIFS($S$6:$S$55,1,$AL$6:$AL$55,">"&AL55)+1,"") | AO55: =IF($S55=1,IF(AN55<=CEILING(SUM($S$6:$S$55)*Settings!$B$30,1),"A",IF(AN55<=CEILING(SUM($S$6:$S$55)*Settings!$B$31,1),"B","C")),"Excluded") -> Excluded

Sheet Walkthrough
A1: Worked example: how one site is ranked
A2: Choose a city (blue cell) | B2: Mysuru
A3: Row in Model | B3: =MATCH(B2,Model!$B$6:$B$55,0) -> 9
A5: STEP A: hard filters (all must pass)
A6: Test | B6: Site value | C6: Limit | D6: Pass?
A7: Seismic zone below V | B7: =INDEX(Model!$F$6:$F$55,$B$3) -> 2 | C7: <5 | D7: =IF(OR(Settings!B14=0,B7<5),"pass","FAIL") -> pass
A8: Distance to nearest 220 kV+ substation (km) | B8: =INDEX(Model!$G$6:$G$55,$B$3) -> 15 | C8: =Settings!B13 -> 25 | D8: =IF(B8<=C8,"pass","FAIL") -> pass
A9: Groundwater: over-exploited without treated water? (1 = yes) | B9: =INDEX(Model!$H$6:$H$55,$B$3) -> 0 | C9: =IF(Settings!B15=1,"allowed","not allowed") -> allowed | D9: =IF(OR(B9=0,Settings!B15=1),"pass","FAIL") -> pass
A10: Very-high cyclone / flood site? (1 = yes) | B10: =INDEX(Model!$I$6:$I$55,$B$3) -> 0 | C10: =IF(Settings!B16=1,"excluded","ignored") -> ignored | D10: =IF(OR(Settings!B16=0,B10=0),"pass","FAIL") -> pass
A11: Overall: passes all filters? | B11: =INDEX(Model!$S$6:$S$55,$B$3) -> 1 | C11: 1 = yes
A13: LATENCY: great-circle distance (haversine) to four hubs
A14: a = sin²(Δφ/2) + cos φ1 · cos φ2 · sin²(Δλ/2); d = 2R · asin(√a); ms = 0.014 × d
A15: Hub | B15: Hub lat | C15: Hub lon | D15: Δφ (deg) | E15: Δλ (deg) | F15: a | G15: d (km) | H15: RTT (ms)
A16: =Settings!A4 -> Mumbai | B16: =Settings!B4 -> 19.076 | C16: =Settings!C4 -> 72.878 | D16: =B16-INDEX(Model!$D$6:$D$55,$B$3) -> 6.776 | E16: =C16-INDEX(Model!$E$6:$E$55,$B$3) -> -3.762 | F16: =SIN(RADIANS(D16)/2)^2+COS(RADIANS(INDEX(Model!$D$6:$D$55,$B$3)))*COS(RADIANS(B16))*SIN(RADIANS(E16)/2)^2 -> 0.004487352 | G16: =2*Settings!$B$9*ASIN(SQRT(F16)) -> 854.19694 | H16: =G16*Settings!$B$10 -> 11.958757
A17: =Settings!A5 -> Delhi | B17: =Settings!B5 -> 28.614 | C17: =Settings!C5 -> 77.209 | D17: =B17-INDEX(Model!$D$6:$D$55,$B$3) -> 16.314 | E17: =C17-INDEX(Model!$E$6:$E$55,$B$3) -> 0.569 | F17: =SIN(RADIANS(D17)/2)^2+COS(RADIANS(INDEX(Model!$D$6:$D$55,$B$3)))*COS(RADIANS(B17))*SIN(RADIANS(E17)/2)^2 -> 0.020152806 | G17: =2*Settings!$B$9*ASIN(SQRT(F17)) -> 1814.9931 | H17: =G17*Settings!$B$10 -> 25.409903
A18: =Settings!A6 -> Chennai | B18: =Settings!B6 -> 13.083 | C18: =Settings!C6 -> 80.27 | D18: =B18-INDEX(Model!$D$6:$D$55,$B$3) -> 0.783 | E18: =C18-INDEX(Model!$E$6:$E$55,$B$3) -> 3.63 | F18: =SIN(RADIANS(D18)/2)^2+COS(RADIANS(INDEX(Model!$D$6:$D$55,$B$3)))*COS(RADIANS(B18))*SIN(RADIANS(E18)/2)^2 -> 0.0010013641 | G18: =2*Settings!$B$9*ASIN(SQRT(F18)) -> 403.27948 | H18: =G18*Settings!$B$10 -> 5.6459127
A19: =Settings!A7 -> Bengaluru | B19: =Settings!B7 -> 12.972 | C19: =Settings!C7 -> 77.594 | D19: =B19-INDEX(Model!$D$6:$D$55,$B$3) -> 0.672 | E19: =C19-INDEX(Model!$E$6:$E$55,$B$3) -> 0.954 | F19: =SIN(RADIANS(D19)/2)^2+COS(RADIANS(INDEX(Model!$D$6:$D$55,$B$3)))*COS(RADIANS(B19))*SIN(RADIANS(E19)/2)^2 -> 0.00010037833 | G19: =2*Settings!$B$9*ASIN(SQRT(F19)) -> 127.66294 | H19: =G19*Settings!$B$10 -> 1.7872812
A20: Mean RTT (ms): the Latency raw value | H20: =AVERAGE(H16:H19) -> 11.200463
A22: STEP B: min–max normalisation to 0–10 (over cities that pass the filters)
A23: s = 10 × (x − min) ÷ (max − min); Latency flipped: s = 10 × (max − x) ÷ (max − min)
A24: Factor | B24: Raw x | C24: Min | D24: Max | E24: Score s
A25: Power | B25: =INDEX(Model!$T$6:$T$55,$B$3) -> 5 | C25: =Model!T$3 -> 3 | D25: =Model!T$4 -> 9 | E25: =IF(D25=C25,5,10*(B25-C25)/(D25-C25)) -> 3.3333333
A26: Connectivity | B26: =INDEX(Model!$U$6:$U$55,$B$3) -> 4 | C26: =Model!U$3 -> 2 | D26: =Model!U$4 -> 10 | E26: =IF(D26=C26,5,10*(B26-C26)/(D26-C26)) -> 2.5
A27: Latency | B27: =INDEX(Model!$V$6:$V$55,$B$3) -> 11.200463 | C27: =Model!V$3 -> 9.7272974 | D27: =Model!V$4 -> 20.566511 | E27: =IF(D27=C27,5,10*(D27-B27)/(D27-C27)) -> 8.6408921
A28: Water | B28: =INDEX(Model!$W$6:$W$55,$B$3) -> 7 | C28: =Model!W$3 -> 1 | D28: =Model!W$4 -> 7 | E28: =IF(D28=C28,5,10*(B28-C28)/(D28-C28)) -> 10
A29: Climate | B29: =INDEX(Model!$X$6:$X$55,$B$3) -> 8 | C29: =Model!X$3 -> 1 | D29: =Model!X$4 -> 8 | E29: =IF(D29=C29,5,10*(B29-C29)/(D29-C29)) -> 10
A30: Hazards | B30: =INDEX(Model!$Y$6:$Y$55,$B$3) -> 9 | C30: =Model!Y$3 -> 3 | D30: =Model!Y$4 -> 9 | E30: =IF(D30=C30,5,10*(B30-C30)/(D30-C30)) -> 10
A31: Land | B31: =INDEX(Model!$Z$6:$Z$55,$B$3) -> 7 | C31: =Model!Z$3 -> 1 | D31: =Model!Z$4 -> 10 | E31: =IF(D31=C31,5,10*(B31-C31)/(D31-C31)) -> 6.6666667
A32: Policy | B32: =INDEX(Model!$AA$6:$AA$55,$B$3) -> 8 | C32: =Model!AA$3 -> 3 | D32: =Model!AA$4 -> 9 | E32: =IF(D32=C32,5,10*(B32-C32)/(D32-C32)) -> 8.3333333
A33: Demand & talent | B33: =INDEX(Model!$AB$6:$AB$55,$B$3) -> 3 | C33: =Model!AB$3 -> 1 | D33: =Model!AB$4 -> 10 | E33: =IF(D33=C33,5,10*(B33-C33)/(D33-C33)) -> 2.2222222
A35: STEP C: weights and the two ways of combining
A36: Factor | B36: Score s | C36: Raw weight | D36: Weight w (÷ sum) | E36: Contribution w·s | F36: LN(max(s,0.5)) | G36: w·LN(…)
A37: Power | B37: =E25 -> 3.3333333 | C37: =Settings!B20 -> 25 | D37: =Settings!B21 -> 0.25 | E37: =B37*D37 -> 0.83333333 | F37: =LN(MAX(B37,0.5)) -> 1.2039728 | G37: =D37*F37 -> 0.3009932
A38: Connectivity | B38: =E26 -> 2.5 | C38: =Settings!C20 -> 15 | D38: =Settings!C21 -> 0.15 | E38: =B38*D38 -> 0.375 | F38: =LN(MAX(B38,0.5)) -> 0.91629073 | G38: =D38*F38 -> 0.13744361
A39: Latency | B39: =E27 -> 8.6408921 | C39: =Settings!D20 -> 10 | D39: =Settings!D21 -> 0.1 | E39: =B39*D39 -> 0.86408921 | F39: =LN(MAX(B39,0.5)) -> 2.1565058 | G39: =D39*F39 -> 0.21565058
A40: Water | B40: =E28 -> 10 | C40: =Settings!E20 -> 15 | D40: =Settings!E21 -> 0.15 | E40: =B40*D40 -> 1.5 | F40: =LN(MAX(B40,0.5)) -> 2.3025851 | G40: =D40*F40 -> 0.34538776
A41: Climate | B41: =E29 -> 10 | C41: =Settings!F20 -> 5 | D41: =Settings!F21 -> 0.05 | E41: =B41*D41 -> 0.5 | F41: =LN(MAX(B41,0.5)) -> 2.3025851 | G41: =D41*F41 -> 0.11512925
A42: Hazards | B42: =E30 -> 10 | C42: =Settings!G20 -> 10 | D42: =Settings!G21 -> 0.1 | E42: =B42*D42 -> 1 | F42: =LN(MAX(B42,0.5)) -> 2.3025851 | G42: =D42*F42 -> 0.23025851
A43: Land | B43: =E31 -> 6.6666667 | C43: =Settings!H20 -> 5 | D43: =Settings!H21 -> 0.05 | E43: =B43*D43 -> 0.33333333 | F43: =LN(MAX(B43,0.5)) -> 1.89712 | G43: =D43*F43 -> 0.094855999
A44: Policy | B44: =E32 -> 8.3333333 | C44: =Settings!I20 -> 10 | D44: =Settings!I21 -> 0.1 | E44: =B44*D44 -> 0.83333333 | F44: =LN(MAX(B44,0.5)) -> 2.1202635 | G44: =D44*F44 -> 0.21202635
...

Sheet MonteCarlo
A1: Step E: Monte Carlo stability (1,000 runs, balanced weights, weighted sum)
A2: Values copied from the atlas run with seed 20261007 (mulberry32 generator). Excel cannot reproduce that generator; the method is shown in the Walkthrough document. Cities excluded by the filters have no result.
A4: id | B4: City | C4: State | D4: State top-3 (%) | E4: India top-10 (%)
A5: nmb | B5: Navi Mumbai | C5: Maharashtra | D5: 99.8 | E5: 70.7
A6: pun | B6: Pune | C6: Maharashtra | D6: 99.3 | E6: 35.6
A7: ngp | B7: Nagpur | C7: Maharashtra | D7: 98.6 | E7: 21.6
A8: nsk | B8: Nashik | C8: Maharashtra | D8: 2.3 | E8: 0
A9: hos | B9: Hosur | C9: Tamil Nadu | D9: 99.8 | E9: 0
A10: che | B10: Chennai | C10: Tamil Nadu | D10: 60.1 | E10: 0
A11: cbe | B11: Coimbatore | C11: Tamil Nadu | D11: 92.3 | E11: 0
A12: tut | B12: Thoothukudi | C12: Tamil Nadu | D12: 47.8 | E12: 0
A13: mys | B13: Mysuru | C13: Karnataka | D13: 99.8 | E13: 76.1
A14: hsk | B14: Hoskote | C14: Karnataka | D14: 96.7 | E14: 30.6
A15: blr | B15: Bengaluru core | C15: Karnataka | D15: 33.8 | E15: 1.4
A16: mlr | B16: Mangaluru | C16: Karnataka | D16: 69.7 | E16: 4.3
... A37: kol | B37: Kolkata | C37: West Bengal | D37: 100 | E37: 0
A38: dig | B38: Digha | C38: West Bengal
A39: koc | B39: Kochi | C39: Kerala | D39: 100 | E39: 40.3
A40: tvm | B40: Thiruvananthapuram | C40: Kerala | D40: 100 | E40: 3.4
A41: jsg | B41: Jharsuguda | C41: Odisha | D41: 100 | E41: 68.4
A42: bbs | B42: Bhubaneswar | C42: Odisha | D42: 100 | E42: 33.3
A43: jai | B43: Jaipur | C43: Rajasthan | D43: 100 | E43: 0
A44: jod | B44: Jodhpur | C44: Rajasthan | D44: 100 | E44: 0
A45: bho | B45: Bhopal | C45: Madhya Pradesh | D45: 100 | E45: 0
A46: ind | B46: Indore | C46: Madhya Pradesh | D46: 100 | E46: 0
A47: nvr | B47: Nava Raipur | C47: Chhattisgarh | D47: 100 | E47: 63.7
A48: rnc | B48: Ranchi | C48: Jharkhand | D48: 100 | E48: 0
A49: goa | B49: Goa (Verna) | C49: Goa | D49: 100 | E49: 0
A50: ddn | B50: Dehradun | C50: Uttarakhand | D50: 100 | E50: 0
... A53: pat | B53: Patna | C53: Bihar | D53: 100 | E53: 0
A54: guw | B54: Guwahati | C54: Assam
